Workbook
Name EditableMiddle: 人物卡!$BX$3:$CX$11,人物卡!$BN$14,人物卡!$BN$17,人物卡!$BI$27
Name 主卡技能选项: OFFSET(规则数据!$Z$20,0,0,MAX(1,规则数据!$Z$19),1)
Name 额外第1项: OFFSET(规则数据!$AA$20,0,0,MAX(1,规则数据!$AA$19),1)
Name 额外第2项: OFFSET(规则数据!$AC$20,0,0,MAX(1,规则数据!$AC$19),1)
Name 额外第3项: OFFSET(规则数据!$AE$20,0,0,MAX(1,规则数据!$AE$19),1)
Name 额外第4项: OFFSET(规则数据!$AG$20,0,0,MAX(1,规则数据!$AG$19),1)
Name 额外第5项: OFFSET(规则数据!$AI$20,0,0,MAX(1,规则数据!$AI$19),1)
Name 额外第6项: OFFSET(规则数据!$AK$20,0,0,MAX(1,规则数据!$AK$19),1)
Name 额外第7项: OFFSET(规则数据!$AM$20,0,0,MAX(1,规则数据!$AM$19),1)
Name 额外第8项: OFFSET(规则数据!$AO$20,0,0,MAX(1,规则数据!$AO$19),1)
Name 非自然心理疾病: '精神疾病'!$B$9:$B$16
Name 武器下拉列表: 规则数据!$A$500:$A$553
Name 护甲下拉列表: 规则数据!$A$560:$A$565
Name 特训对应项: 规则数据!$A$580:$A$644
Name 任选勾选值: '职业选项'!$AA$2:$AA$3
Name 空白选项: '职业选项'!$AA$4
Name 特训范例: '参考选项'!$B$20:$B$33
Name 关系称谓: '参考选项'!$B$35:$B$46
Name 模组编号: '幕间计算'!$W$2:$W$21
Name 幕间事项: '幕间计算'!$U$2:$U$10
Name 变更目标: '幕间计算'!$P$2:INDEX('幕间计算'!$P$2:$P$79,MAX(1,COUNTIF('幕间计算'!$P$2:$P$79,"?*")))
Name 关系编号: '幕间计算'!$X$2:$X$8
Name 失败标记: '人物卡'!$B$14:$C$43,'人物卡'!$AE$14:$AF$43
Name 本次成长记录: '幕间与结算'!$A$10:INDEX('幕间与结算'!$I$10:$I$69,MAX(1,'幕间计算'!$AO$2))
Name 本次骰点: '幕间与结算'!$J$10:$J$69
Name 幕间一记录: '幕间与结算'!$A$80:$I$84
Name 幕间二记录: '幕间与结算'!$A$96:$I$100
Name 装备包选项: '装备选项'!$J$2:$J$8

Sheet 人物卡
CZ1: 物品
B2: ※ 特工信息 v1.10 | AB2: ※ 属性 | AH2: 数值 | AK2: ×5 | AN2: 暂降 | AQ2: 突出值解释 | BI2: 头像 | BX2: ※ 特训 | CP2: 对应技能或属性 | CZ2: ※ 物品 | DH2: 跟随职业
B3: 玩家 | AB3: 力量 | AE3: STR | AH3: ='幕间计算'!BF1199 -> 0 | AK3: =附表!B2*5 -> 0 | CZ3: =IF('装备选项'!L6<>"",'装备选项'!L6,IF(DH2="自定义","",'装备选项'!L5)) | DR3: ='装备选项'!L7 | EI3: =IF(AND(DH2<>"自定义",'装备选项'!L6<>""),'装备选项'!L5,"")
B4: 特工 | AB4: 体质 | AE4: CON | AH4: ='幕间计算'!BG1199 -> 0 | AK4: =附表!B3*5 -> 0
B5: 性别 | N5: 年龄 | AB5: 敏捷 | AE5: DEX | AH5: ='幕间计算'!BH1199 -> 0 | AK5: =附表!B4*5 -> 0
B6: 国籍 | N6: 年代 | AB6: 智力 | AE6: INT | AH6: ='幕间计算'!BI1199 -> 0 | AK6: =附表!B5*5 -> 0
B7: 雇主 | AB7: 意志 | AE7: POW | AH7: ='幕间计算'!BJ1199 -> 0 | AK7: =附表!B6*5 -> 0
B8: 职位 | AB8: 魅力 | AE8: CHA | AH8: ='幕间计算'!BK1199 -> 0 | AK8: =附表!B7*5 -> 0 | EI8: 护甲
R9: 原始合计： | X9: =SUM('幕间与结算'!A5:F5) -> 0 | AB9: 总本职技能点： | AI9: =SUM(V14:V43,AY14:AY43)-SUMIF(V14:V43,">0",S14:S43)-SUMIF(AY14:AY43,">0",AV14:AV43) -> 0 | AL9: （初始重要关系数： | AT9: =IFERROR(MAX(0,IF(AND(AI9>=350,AI9<=500,MOD(AI9,50)=0),(550-AI9)/50,"错误")-IF(DF46="艰苦经历",1,0)),"错误")&"）" -> 错误） | AW9: 总额外技能点： | BD9: =规则数据!S3 -> 0
B10: 体力 | H10: ='幕间计算'!BM1199 -> 0 | K10: =CEILING((附表!B2+附表!B3)/2,1) -> 0 | N10: 毅力 | V10: ='幕间计算'!BN1199 -> 0 | Y10: =附表!B6 -> 0 | AB10: 理智 | AH10: ='幕间计算'!BO1199 -> 0 | AK10: =99-AS39 -> 99 | AN10: 崩溃点 | AU10: ='幕间计算'!BP1199 -> 0 | AX10: 适应暴力 | BD10: =IF(DF46="极端暴力","已适应","☐☐☐") -> ☐☐☐
B11: Hit Points | N11: Willpower Points | AB11: Sanity | AN11: Breaking Point | AX11: 适应无力 | BD11: =IF(DF46="关押或入狱","已适应","☐☐☐") -> ☐☐☐
B13: ※ 技能 | P13: 总计 | S13: 初始 | V13: 职业 | Y13: 额外 | AB13: 成长 | AS13: 总计 | AV13: 初始 | AY13: 职业 | BB13: 额外 | BE13: 成长 | BI13: ※ 背景故事 | CZ13: ※ 武器 | DM13: 技能% | DQ13: 伤害/致死% | DW13: 穿甲 | DZ13: 基础射程 | ED13: 半径 | EI13: 近战伤害加成 | EQ13: =IF(AH3="",0,FLOOR((附表!B2-9)/4,1)) -> -3
B14: ☐ | D14: 会计学 | P14: =MAX(0,MIN(99,IF(V14="",N(S14),N(V14))+N(Y14)+N(AB14))) -> 10 | S14: 10 | V14: =IF(职业选项!V40>0,职业选项!V40,"") | Y14: =规则数据!H20 | AB14: ='幕间计算'!B2+IF(AND('幕间计算'!A2<>"",COUNTIF('幕间计算'!$A$2:A2,'幕间计算'!A2)=1),SUMIF('幕间计算'!$C$200:$C$1199,'幕间计算'!A2,'幕间计算'!$E$200:$E$1199),0) -> 0 | AE14: ☐ | AG14: 法律 | AS14: =MAX(0,MIN(99,IF(AY14="",N(AV14),N(AY14))+N(BB14)+N(BE14))) -> 0 | AV14: 0 | AY14: =IF(职业选项!V41>0,职业选项!V41,"") | BB14: =规则数据!H50 | BE14: ='幕间计算'!B32+IF(AND('幕间计算'!A32<>"",COUNTIF('幕间计算'!$A$2:A32,'幕间计算'!A32)=1),SUMIF('幕间计算'!$C$200:$C$1199,'幕间计算'!A32,'幕间计算'!$E$200:$E$1199),0) -> 0 | BI14: 外貌描述 | DM14: =IFERROR(INDIRECT(INDEX(规则数据!$C$500:$C$553,MATCH(CZ14,规则数据!$A$500:$A$553,0))),"") | DQ14: =IFERROR(IF(INDEX(规则数据!$D$500:$D$553,MATCH(CZ14,规则数据!$A$500:$A$553,0))="","",INDEX(规则数据!$D$500:$D$553,MATCH(CZ14,规则数据!$A$500:$A$553,0))),"") | DW14: =IFERROR(IF(INDEX(规则数据!$E$500:$E$553,MATCH(CZ14,规则数据!$A$500:$A$553,0))="","",INDEX(规则数据!$E$500:$E$553,MATCH(CZ14,规则数据!$A$500:$A$553,0))),"") | DZ14: =IFERROR(IF(INDEX(规则数据!$F$500:$F$553,MATCH(CZ14,规则数据!$A$500:$A$553,0))="","",INDEX(规则数据!$F$500:$F$553,MATCH(CZ14,规则数据!$A$500:$A$553,0))),"") | ED14: =IFERROR(IF(INDEX(规则数据!$G$500:$G$553,MATCH(CZ14,规则数据!$A$500:$A$553,0))="","",INDEX(规则数据!$G$500:$G$553,MATCH(CZ14,规则数据!$A$500:$A$553,0))),"") | EI14: Damage Bonus
B15: ☐ | D15: 警觉 | P15: =MAX(0,MIN(99,IF(V15="",N(S15),N(V15))+N(Y15)+N(AB15))) -> 20 | S15: 20 | V15: =IF(职业选项!V42>0,职业选项!V42,"") | Y15: =规则数据!H21 | AB15: ='幕间计算'!B3+IF(AND('幕间计算'!A3<>"",COUNTIF('幕间计算'!$A$2:A3,'幕间计算'!A3)=1),SUMIF('幕间计算'!$C$200:$C$1199,'幕间计算'!A3,'幕间计算'!$E$200:$E$1199),0) -> 0 | AE15: ☐ | AG15: 医学 | AS15: =MAX(0,MIN(99,IF(AY15="",N(AV15),N(AY15))+N(BB15)+N(BE15))) -> 0 | AV15: 0 | AY15: =IF(职业选项!V43>0,职业选项!V43,"") | BB15: =规则数据!H51 | BE15: ='幕间计算'!B33+IF(AND('幕间计算'!A33<>"",COUNTIF('幕间计算'!$A$2:A33,'幕间计算'!A33)=1),SUMIF('幕间计算'!$C$200:$C$1199,'幕间计算'!A33,'幕间计算'!$E$200:$E$1199),0) -> 0 | DM15: =IFERROR(INDIRECT(INDEX(规则数据!$C$500:$C$553,MATCH(CZ15,规则数据!$A$500:$A$553,0))),"") | DQ15: =IFERROR(IF(INDEX(规则数据!$D$500:$D$553,MATCH(CZ15,规则数据!$A$500:$A$553,0))="","",INDEX(规则数据!$D$500:$D$553,MATCH(CZ15,规则数据!$A$500:$A$553,0))),"") | DW15: =IFERROR(IF(INDEX(规则数据!$E$500:$E$553,MATCH(CZ15,规则数据!$A$500:$A$553,0))="","",INDEX(规则数据!$E$500:$E$553,MATCH(CZ15,规则数据!$A$500:$A$553,0))),"") | DZ15: =IFERROR(IF(INDEX(规则数据!$F$500:$F$553,MATCH(CZ15,规则数据!$A$500:$A$553,0))="","",INDEX(规则数据!$F$500:$F$553,MATCH(CZ15,规则数据!$A$500:$A$553,0))),"") | ED15: =IFERROR(IF(INDEX(规则数据!$G$500:$G$553,MATCH(CZ15,规则数据!$A$500:$A$553,0))="","",INDEX(规则数据!$G$500:$G$553,MATCH(CZ15,规则数据!$A$500:$A$553,0))),"")
B16: ☐ | D16: 人类学 | P16: =MAX(0,MIN(99,IF(V16="",N(S16),N(V16))+N(Y16)+N(AB16))) -> 0 | S16: 0 | V16: =IF(职业选项!V44>0,职业选项!V44,"") | Y16: =规则数据!H22 | AB16: ='幕间计算'!B4+IF(AND('幕间计算'!A4<>"",COUNTIF('幕间计算'!$A$2:A4,'幕间计算'!A4)=1),SUMIF('幕间计算'!$C$200:$C$1199,'幕间计算'!A4,'幕间计算'!$E$200:$E$1199),0) -> 0 | AE16: ☐ | AG16: 近战武器 | AS16: =MAX(0,MIN(99,IF(AY16="",N(AV16),N(AY16))+N(BB16)+N(BE16))) -> 30 | AV16: 30 | AY16: =IF(职业选项!V45>0,职业选项!V45,"") | BB16: =规则数据!H52 | BE16: ='幕间计算'!B34+IF(AND('幕间计算'!A34<>"",COUNTIF('幕间计算'!$A$2:A34,'幕间计算'!A34)=1),SUMIF('幕间计算'!$C$200:$C$1199,'幕间计算'!A34,'幕间计算'!$E$200:$E$1199),0) -> 0 | DM16: =IFERROR(INDIRECT(INDEX(规则数据!$C$500:$C$553,MATCH(CZ16,规则数据!$A$500:$A$553,0))),"") | DQ16: =IFERROR(IF(INDEX(规则数据!$D$500:$D$553,MATCH(CZ16,规则数据!$A$500:$A$553,0))="","",INDEX(规则数据!$D$500:$D$553,MATCH(CZ16,规则数据!$A$500:$A$553,0))),"") | DW16: =IFERROR(IF(INDEX(规则数据!$E$500:$E$553,MATCH(CZ16,规则数据!$A$500:$A$553,0))="","",INDEX(规则数据!$E$500:$E$553,MATCH(CZ16,规则数据!$A$500:$A$553,0))),"") | DZ16: =IFERROR(IF(INDEX(规则数据!$F$500:$F$553,MATCH(CZ16,规则数据!$A$500:$A$553,0))="","",INDEX(规则数据!$F$500:$F$553,MATCH(CZ16,规则数据!$A$500:$A$553,0))),"") | ED16: =IFERROR(IF(INDEX(规则数据!$G$500:$G$553,MATCH(CZ16,规则数据!$A$500:$A$553,0))="","",INDEX(规则数据!$G$500:$G$553,MATCH(CZ16,规则数据!$A$500:$A$553,0))),"") | EI16: ※ 永久伤残、顽疾或成瘾症
B17: ☐ | D17: 考古学 | P17: =MAX(0,MIN(99,IF(V17="",N(S17),N(V17))+N(Y17)+N(AB17))) -> 0 | S17: 0 | V17: =IF(职业选项!V46>0,职业选项!V46,"") | Y17: =规则数据!H23 | AB17: ='幕间计算'!B5+IF(AND('幕间计算'!A5<>"",COUNTIF('幕间计算'!$A$2:A5,'幕间计算'!A5)=1),SUMIF('幕间计算'!$C$200:$C$1199,'幕间计算'!A5,'幕间计算'!$E$200:$E$1199),0) -> 0 | AE17: ☐ | AG17: 军事科学： | AM17: =IF(COUNTIF(职业选项!$I$2:$I$28,"军事科学1")>0,IFERROR(INDEX(职业选项!$F$2:$F$28,MATCH("军事科学1",职业选项!$I$2:$I$28,0)),""),IFERROR(MID(IFERROR(INDEX(规则数据!$C$2:$C$9,SMALL(规则数据!$AU$2:$AU$9,1-COUNTIF(职业选项!$C$2:$C$28,"军事科学"))),""),LEN("军事科学")+2,LEN(IFERROR(INDEX(规则数据!$C$2:$C$9,SMALL(规则数据!$AU$2:$AU$9,1-COUNTIF(职业选项!$C$2:$C$28,"军事科学"))),""))-LEN("军事科学")-2),"")) | AS17: =MAX(0,MIN(99,IF(AY17="",N(AV17),N(AY17))+N(BB17)+N(BE17))) -> 0 | AV17: 0 | AY17: =IF(职业选项!V47>0,职业选项!V47,"") | BB17: =规则数据!H53 | BE17: ='幕间计算'!B35+IF(AND('幕间计算'!A35<>"",COUNTIF('幕间计算'!$A$2:A35,'幕间计算'!A35)=1),SUMIF('幕间计算'!$C$200:$C$1199,'幕间计算'!A35,'幕间计算'!$E$200:$E$1199),0) -> 0 | BI17: 人生动力 及 精神疾病 | BN17: =规则数据!S10&IF(AND(DF46="人类不应知道之事",DR55<>""),IF(规则数据!S10<>"",CHAR(10),"")&"创伤心理疾病："&DR55,"") | DM17: =IFERROR(INDIRECT(INDEX(规则数据!$C$500:$C$553,MATCH(CZ17,规则数据!$A$500:$A$553,0))),"") | DQ17: =IFERROR(IF(INDEX(规则数据!$D$500:$D$553,MATCH(CZ17,规则数据!$A$500:$A$553,0))="","",INDEX(规则数据!$D$500:$D$553,MATCH(CZ17,规则数据!$A$500:$A$553,0))),"") | DW17: =IFERROR(IF(INDEX(规则数据!$E$500:$E$553,MATCH(CZ17,规则数据!$A$500:$A$553,0))="","",INDEX(规则数据!$E$500:$E$553,MATCH(CZ17,规则数据!$A$500:$A$553,0))),"") | DZ17: =IFERROR(IF(INDEX(规则数据!$F$500:$F$553,MATCH(CZ17,规则数据!$A$500:$A$553,0))="","",INDEX(规则数据!$F$500:$F$553,MATCH(CZ17,规则数据!$A$500:$A$553,0))),"") | ED17: =IFERROR(IF(INDEX(规则数据!$G$500:$G$553,MATCH(CZ17,规则数据!$A$500:$A$553,0))="","",INDEX(规则数据!$G$500:$G$553,MATCH(CZ17,规则数据!$A$500:$A$553,0))),"")
B18: ☐ | D18: 艺术： | J18: =IF(COUNTIF(职业选项!$I$2:$I$28,"艺术1")>0,IFERROR(INDEX(职业选项!$F$2:$F$28,MATCH("艺术1",职业选项!$I$2:$I$28,0)),""),IFERROR(MID(IFERROR(INDEX(规则数据!$C$2:$C$9,SMALL(规则数据!$AR$2:$AR$9,1-COUNTIF(职业选项!$C$2:$C$28,"艺术"))),""),LEN("艺术")+2,LEN(IFERROR(INDEX(规则数据!$C$2:$C$9,SMALL(规则数据!$AR$2:$AR$9,1-COUNTIF(职业选项!$C$2:$C$28,"艺术"))),""))-LEN("艺术")-2),"")) | P18: =MAX(0,MIN(99,IF(V18="",N(S18),N(V18))+N(Y18)+N(AB18))) -> 0 | S18: 0 | V18: =IF(职业选项!V48>0,职业选项!V48,"") | Y18: =规则数据!H24 | AB18: ='幕间计算'!B6+IF(AND('幕间计算'!A6<>"",COUNTIF('幕间计算'!$A$2:A6,'幕间计算'!A6)=1),SUMIF('幕间计算'!$C$200:$C$1199,'幕间计算'!A6,'幕间计算'!$E$200:$E$1199),0) -> 0 | AE18: ☐ | AG18: 军事科学： | AM18: =IF(COUNTIF(职业选项!$I$2:$I$28,"军事科学2")>0,IFERROR(INDEX(职业选项!$F$2:$F$28,MATCH("军事科学2",职业选项!$I$2:$I$28,0)),""),IFERROR(MID(IFERROR(INDEX(规则数据!$C$2:$C$9,SMALL(规则数据!$AU$2:$AU$9,2-COUNTIF(职业选项!$C$2:$C$28,"军事科学"))),""),LEN("军事科学")+2,LEN(IFERROR(INDEX(规则数据!$C$2:$C$9,SMALL(规则数据!$AU$2:$AU$9,2-COUNTIF(职业选项!$C$2:$C$28,"军事科学"))),""))-LEN("军事科学")-2),"")) | AS18: =MAX(0,MIN(99,IF(AY18="",N(AV18),N(AY18))+N(BB18)+N(BE18))) -> 0 | AV18: 0 | AY18: =IF(职业选项!V49>0,职业选项!V49,"") | BB18: =规则数据!H54 | BE18: ='幕间计算'!B36+IF(AND('幕间计算'!A36<>"",COUNTIF('幕间计算'!$A$2:A36,'幕间计算'!A36)=1),SUMIF('幕间计算'!$C$200:$C$1199,'幕间计算'!A36,'幕间计算'!$E$200:$E$1199),0) -> 0 | DM18: =IFERROR(INDIRECT(INDEX(规则数据!$C$500:$C$553,MATCH(CZ18,规则数据!$A$500:$A$553,0))),"") | DQ18: =IFERROR(IF(INDEX(规则数据!$D$500:$D$553,MATCH(CZ18,规则数据!$A$500:$A$553,0))="","",INDEX(规则数据!$D$500:$D$553,MATCH(CZ18,规则数据!$A$500:$A$553,0))),"") | DW18: =IFERROR(IF(INDEX(规则数据!$E$500:$E$553,MATCH(CZ18,规则数据!$A$500:$A$553,0))="","",INDEX(规则数据!$E$500:$E$553,MATCH(CZ18,规则数据!$A$500:$A$553,0))),"") | DZ18: =IFERROR(IF(INDEX(规则数据!$F$500:$F$553,MATCH(CZ18,规则数据!$A$500:$A$553,0))="","",INDEX(规则数据!$F$500:$F$553,MATCH(CZ18,规则数据!$A$500:$A$553,0))),"") | ED18: =IFERROR(IF(INDEX(规则数据!$G$500:$G$553,MATCH(CZ18,规则数据!$A$500:$A$553,0))="","",INDEX(规则数据!$G$500:$G$553,MATCH(CZ18,规则数据!$A$500:$A$553,0))),"")
B19: ☐ | D19: 艺术： | J19: =IF(COUNTIF(职业选项!$I$2:$I$28,"艺术2")>0,IFERROR(INDEX(职业选项!$F$2:$F$28,MATCH("艺术2",职业选项!$I$2:$I$28,0)),""),IFERROR(MID(IFERROR(INDEX(规则数据!$C$2:$C$9,SMALL(规则数据!$AR$2:$AR$9,2-COUNTIF(职业选项!$C$2:$C$28,"艺术"))),""),LEN("艺术")+2,LEN(IFERROR(INDEX(规则数据!$C$2:$C$9,SMALL(规则数据!$AR$2:$AR$9,2-COUNTIF(职业选项!$C$2:$C$28,"艺术"))),""))-LEN("艺术")-2),"")) | P19: =MAX(0,MIN(99,IF(V19="",N(S19),N(V19))+N(Y19)+N(AB19))) -> 0 | S19: 0 | V19: =IF(职业选项!V50>0,职业选项!V50,"") | Y19: =规则数据!H25 | AB19: ='幕间计算'!B7+IF(AND('幕间计算'!A7<>"",COUNTIF('幕间计算'!$A$2:A7,'幕间计算'!A7)=1),SUMIF('幕间计算'!$C$200:$C$1199,'幕间计算'!A7,'幕间计算'!$E$200:$E$1199),0) -> 0 | AE19: ☐ | AG19: 军事科学： | AM19: =IF(COUNTIF(职业选项!$I$2:$I$28,"军事科学3")>0,IFERROR(INDEX(职业选项!$F$2:$F$28,MATCH("军事科学3",职业选项!$I$2:$I$28,0)),""),IFERROR(MID(IFERROR(INDEX(规则数据!$C$2:$C$9,SMALL(规则数据!$AU$2:$AU$9,3-COUNTIF(职业选项!$C$2:$C$28,"军事科学"))),""),LEN("军事科学")+2,LEN(IFERROR(INDEX(规则数据!$C$2:$C$9,SMALL(规则数据!$AU$2:$AU$9,3-COUNTIF(职业选项!$C$2:$C$28,"军事科学"))),""))-LEN("军事科学")-2),"")) | AS19: =MAX(0,MIN(99,IF(AY19="",N(AV19),N(AY19))+N(BB19)+N(BE19))) -> 0 | AV19: 0 | AY19: =IF(职业选项!V51>0,职业选项!V51,"") | BB19: =规则数据!H55 | BE19: ='幕间计算'!B37+IF(AND('幕间计算'!A37<>"",COUNTIF('幕间计算'!$A$2:A37,'幕间计算'!A37)=1),SUMIF('幕间计算'!$C$200:$C$1199,'幕间计算'!A37,'幕间计算'!$E$200:$E$1199),0) -> 0 | DM19: =IFERROR(INDIRECT(INDEX(规则数据!$C$500:$C$553,MATCH(CZ19,规则数据!$A$500:$A$553,0))),"") | DQ19: =IFERROR(IF(INDEX(规则数据!$D$500:$D$553,MATCH(CZ19,规则数据!$A$500:$A$553,0))="","",INDEX(规则数据!$D$500:$D$553,MATCH(CZ19,规则数据!$A$500:$A$553,0))),"") | DW19: =IFERROR(IF(INDEX(规则数据!$E$500:$E$553,MATCH(CZ19,规则数据!$A$500:$A$553,0))="","",INDEX(规则数据!$E$500:$E$553,MATCH(CZ19,规则数据!$A$500:$A$553,0))),"") | DZ19: =IFERROR(IF(INDEX(规则数据!$F$500:$F$553,MATCH(CZ19,规则数据!$A$500:$A$553,0))="","",INDEX(规则数据!$F$500:$F$553,MATCH(CZ19,规则数据!$A$500:$A$553,0))),"") | ED19: =IFERROR(IF(INDEX(规则数据!$G$500:$G$553,MATCH(CZ19,规则数据!$A$500:$A$553,0))="","",INDEX(规则数据!$G$500:$G$553,MATCH(CZ19,规则数据!$A$500:$A$553,0))),"")
B20: ☐ | D20: 艺术： | J20: =IF(COUNTIF(职业选项!$I$2:$I$28,"艺术3")>0,IFERROR(INDEX(职业选项!$F$2:$F$28,MATCH("艺术3",职业选项!$I$2:$I$28,0)),""),IFERROR(MID(IFERROR(INDEX(规则数据!$C$2:$C$9,SMALL(规则数据!$AR$2:$AR$9,3-COUNTIF(职业选项!$C$2:$C$28,"艺术"))),""),LEN("艺术")+2,LEN(IFERROR(INDEX(规则数据!$C$2:$C$9,SMALL(规则数据!$AR$2:$AR$9,3-COUNTIF(职业选项!$C$2:$C$28,"艺术"))),""))-LEN("艺术")-2),"")) | P20: =MAX(0,MIN(99,IF(V20="",N(S20),N(V20))+N(Y20)+N(AB20))) -> 0 | S20: 0 | V20: =IF(职业选项!V52>0,职业选项!V52,"") | Y20: =规则数据!H26 | AB20: ='幕间计算'!B8+IF(AND('幕间计算'!A8<>"",COUNTIF('幕间计算'!$A$2:A8,'幕间计算'!A8)=1),SUMIF('幕间计算'!$C$200:$C$1199,'幕间计算'!A8,'幕间计算'!$E$200:$E$1199),0) -> 0 | AE20: ☐ | AG20: 导航 | AS20: =MAX(0,MIN(99,IF(AY20="",N(AV20),N(AY20))+N(BB20)+N(BE20))) -> 10 | AV20: 10 | AY20: =IF(职业选项!V53>0,职业选项!V53,"") | BB20: =规则数据!H56 | BE20: ='幕间计算'!B38+IF(AND('幕间计算'!A38<>"",COUNTIF('幕间计算'!$A$2:A38,'幕间计算'!A38)=1),SUMIF('幕间计算'!$C$200:$C$1199,'幕间计算'!A38,'幕间计算'!$E$200:$E$1199),0) -> 0 | DM20: =IFERROR(INDIRECT(INDEX(规则数据!$C$500:$C$553,MATCH(CZ20,规则数据!$A$500:$A$553,0))),"") | DQ20: =IFERROR(IF(INDEX(规则数据!$D$500:$D$553,MATCH(CZ20,规则数据!$A$500:$A$553,0))="","",INDEX(规则数据!$D$500:$D$553,MATCH(CZ20,规则数据!$A$500:$A$553,0))),"") | DW20: =IFERROR(IF(INDEX(规则数据!$E$500:$E$553,MATCH(CZ20,规则数据!$A$500:$A$553,0))="","",INDEX(规则数据!$E$500:$E$553,MATCH(CZ20,规则数据!$A$500:$A$553,0))),"") | DZ20: =IFERROR(IF(INDEX(规则数据!$F$500:$F$553,MATCH(CZ20,规则数据!$A$500:$A$553,0))="","",INDEX(规则数据!$F$500:$F$553,MATCH(CZ20,规则数据!$A$500:$A$553,0))),"") | ED20: =IFERROR(IF(INDEX(规则数据!$G$500:$G$553,MATCH(CZ20,规则数据!$A$500:$A$553,0))="","",INDEX(规则数据!$G$500:$G$553,MATCH(CZ20,规则数据!$A$500:$A$553,0))),"")
B21: ☐ | D21: 炮术 | P21: =MAX(0,MIN(99,IF(V21="",N(S21),N(V21))+N(Y21)+N(AB21))) -> 0 | S21: 0 | V21: =IF(职业选项!V54>0,职业选项!V54,"") | Y21: =规则数据!H27 | AB21: ='幕间计算'!B9+IF(AND('幕间计算'!A9<>"",COUNTIF('幕间计算'!$A$2:A9,'幕间计算'!A9)=1),SUMIF('幕间计算'!$C$200:$C$1199,'幕间计算'!A9,'幕间计算'!$E$200:$E$1199),0) -> 0 | AE21: ☐ | AG21: 神秘学 | AS21: =MAX(0,MIN(99,IF(AY21="",N(AV21),N(AY21))+N(BB21)+N(BE21))) -> 10 | AV21: 10 | AY21: =IF(职业选项!V55>0,职业选项!V55,"") | BB21: =规则数据!H57 | BE21: ='幕间计算'!B39+IF(AND('幕间计算'!A39<>"",COUNTIF('幕间计算'!$A$2:A39,'幕间计算'!A39)=1),SUMIF('幕间计算'!$C$200:$C$1199,'幕间计算'!A39,'幕间计算'!$E$200:$E$1199),0) -> 0
B22: ☐ | D22: 运动 | P22: =MAX(0,MIN(99,IF(V22="",N(S22),N(V22))+N(Y22)+N(AB22))) -> 30 | S22: 30 | V22: =IF(职业选项!V56>0,职业选项!V56,"") | Y22: =规则数据!H28 | AB22: ='幕间计算'!B10+IF(AND('幕间计算'!A10<>"",COUNTIF('幕间计算'!$A$2:A10,'幕间计算'!A10)=1),SUMIF('幕间计算'!$C$200:$C$1199,'幕间计算'!A10,'幕间计算'!$E$200:$E$1199),0) -> 0 | AE22: ☐ | AG22: 说服 | AS22: =MAX(0,MIN(99,IF(AY22="",N(AV22),N(AY22))+N(BB22)+N(BE22))) -> 20 | AV22: 20 | AY22: =IF(职业选项!V57>0,职业选项!V57,"") | BB22: =规则数据!H58 | BE22: ='幕间计算'!B40+IF(AND('幕间计算'!A40<>"",COUNTIF('幕间计算'!$A$2:A40,'幕间计算'!A40)=1),SUMIF('幕间计算'!$C$200:$C$1199,'幕间计算'!A40,'幕间计算'!$E$200:$E$1199),0) -> 0 | CZ22: ※ 重要关系 | DT22: 关系数： | DX22: =COUNTIF(ED24,">0")+COUNTIF(ED27,">0")+COUNTIF(ED30,">0")+COUNTIF(ED33,">0")+COUNTIF(ED36,">0")+COUNTIF(ED39,">0")+COUNTIF(ED42,">0") -> 0 | EC22: 魅力： | EF22: =附表!B7 -> 0 | EI22: ※ 其他笔记
B23: ☐ | D23: 行政 | P23: =MAX(0,MIN(99,IF(V23="",N(S23),N(V23))+N(Y23)+N(AB23))) -> 10 | S23: 10 | V23: =IF(职业选项!V58>0,职业选项!V58,"") | Y23: =规则数据!H29 | AB23: ='幕间计算'!B11+IF(AND('幕间计算'!A11<>"",COUNTIF('幕间计算'!$A$2:A11,'幕间计算'!A11)=1),SUMIF('幕间计算'!$C$200:$C$1199,'幕间计算'!A11,'幕间计算'!$E$200:$E$1199),0) -> 0 | AE23: ☐ | AG23: 药学 | AS23: =MAX(0,MIN(99,IF(AY23="",N(AV23),N(AY23))+N(BB23)+N(BE23))) -> 0 | AV23: 0 | AY23: =IF(职业选项!V59>0,职业选项!V59,"") | BB23: =规则数据!H59 | BE23: ='幕间计算'!B41+IF(AND('幕间计算'!A41<>"",COUNTIF('幕间计算'!$A$2:A41,'幕间计算'!A41)=1),SUMIF('幕间计算'!$C$200:$C$1199,'幕间计算'!A41,'幕间计算'!$E$200:$E$1199),0) -> 0 | ED23: 值 | EF23: DG
B24: ☐ | D24: 计算机科学 | P24: =MAX(0,MIN(99,IF(V24="",N(S24),N(V24))+N(Y24)+N(AB24))) -> 0 | S24: 0 | V24: =IF(职业选项!V60>0,职业选项!V60,"") | Y24: =规则数据!H30 | AB24: ='幕间计算'!B12+IF(AND('幕间计算'!A12<>"",COUNTIF('幕间计算'!$A$2:A12,'幕间计算'!A12)=1),SUMIF('幕间计算'!$C$200:$C$1199,'幕间计算'!A12,'幕间计算'!$E$200:$E$1199),0) -> 0 | AE24: ☐ | AG24: 特种载具： | AM24: =IF(COUNTIF(职业选项!$I$2:$I$28,"特种载具1")>0,IFERROR(INDEX(职业选项!$F$2:$F$28,MATCH("特种载具1",职业选项!$I$2:$I$28,0)),""),IFERROR(MID(IFERROR(INDEX(规则数据!$C$2:$C$9,SMALL(规则数据!$AV$2:$AV$9,1-COUNTIF(职业选项!$C$2:$C$28,"特种载具"))),""),LEN("特种载具")+2,LEN(IFERROR(INDEX(规则数据!$C$2:$C$9,SMALL(规则数据!$AV$2:$AV$9,1-COUNTIF(职业选项!$C$2:$C$28,"特种载具"))),""))-LEN("特种载具")-2),"")) | AS24: =MAX(0,MIN(99,IF(AY24="",N(AV24),N(AY24))+N(BB24)+N(BE24))) -> 0 | AV24: 0 | AY24: =IF(职业选项!V61>0,职业选项!V61,"") | BB24: =规则数据!H60 | BE24: ='幕间计算'!B42+IF(AND('幕间计算'!A42<>"",COUNTIF('幕间计算'!$A$2:A42,'幕间计算'!A42)=1),SUMIF('幕间计算'!$C$200:$C$1199,'幕间计算'!A42,'幕间计算'!$E$200:$E$1199),0) -> 0 | ED24: =IF(CZ23="","",'幕间计算'!BQ1199) | EF24: ×
B25: ☐ | D25: 工艺： | J25: =IF(COUNTIF(职业选项!$I$2:$I$28,"工艺1")>0,IFERROR(INDEX(职业选项!$F$2:$F$28,MATCH("工艺1",职业选项!$I$2:$I$28,0)),""),IFERROR(MID(IFERROR(INDEX(规则数据!$C$2:$C$9,SMALL(规则数据!$AS$2:$AS$9,1-COUNTIF(职业选项!$C$2:$C$28,"工艺"))),""),LEN("工艺")+2,LEN(IFERROR(INDEX(规则数据!$C$2:$C$9,SMALL(规则数据!$AS$2:$AS$9,1-COUNTIF(职业选项!$C$2:$C$28,"工艺"))),""))-LEN("工艺")-2),"")) | P25: =MAX(0,MIN(99,IF(V25="",N(S25),N(V25))+N(Y25)+N(AB25))) -> 0 | S25: 0 | V25: =IF(职业选项!V62>0,职业选项!V62,"") | Y25: =规则数据!H31 | AB25: ='幕间计算'!B13+IF(AND('幕间计算'!A13<>"",COUNTIF('幕间计算'!$A$2:A13,'幕间计算'!A13)=1),SUMIF('幕间计算'!$C$200:$C$1199,'幕间计算'!A13,'幕间计算'!$E$200:$E$1199),0) -> 0 | AE25: ☐ | AG25: 特种载具： | AM25: =IF(COUNTIF(职业选项!$I$2:$I$28,"特种载具2")>0,IFERROR(INDEX(职业选项!$F$2:$F$28,MATCH("特种载具2",职业选项!$I$2:$I$28,0)),""),IFERROR(MID(IFERROR(INDEX(规则数据!$C$2:$C$9,SMALL(规则数据!$AV$2:$AV$9,2-COUNTIF(职业选项!$C$2:$C$28,"特种载具"))),""),LEN("特种载具")+2,LEN(IFERROR(INDEX(规则数据!$C$2:$C$9,SMALL(规则数据!$AV$2:$AV$9,2-COUNTIF(职业选项!$C$2:$C$28,"特种载具"))),""))-LEN("特种载具")-2),"")) | AS25: =MAX(0,MIN(99,IF(AY25="",N(AV25),N(AY25))+N(BB25)+N(BE25))) -> 0 | AV25: 0 | AY25: =IF(职业选项!V63>0,职业选项!V63,"") | BB25: =规则数据!H61 | BE25: ='幕间计算'!B43+IF(AND('幕间计算'!A43<>"",COUNTIF('幕间计算'!$A$2:A43,'幕间计算'!A43)=1),SUMIF('幕间计算'!$C$200:$C$1199,'幕间计算'!A43,'幕间计算'!$E$200:$E$1199),0) -> 0
B26: ☐ | D26: 工艺： | J26: =IF(COUNTIF(职业选项!$I$2:$I$28,"工艺2")>0,IFERROR(INDEX(职业选项!$F$2:$F$28,MATCH("工艺2",职业选项!$I$2:$I$28,0)),""),IFERROR(MID(IFERROR(INDEX(规则数据!$C$2:$C$9,SMALL(规则数据!$AS$2:$AS$9,2-COUNTIF(职业选项!$C$2:$C$28,"工艺"))),""),LEN("工艺")+2,LEN(IFERROR(INDEX(规则数据!$C$2:$C$9,SMALL(规则数据!$AS$2:$AS$9,2-COUNTIF(职业选项!$C$2:$C$28,"工艺"))),""))-LEN("工艺")-2),"")) | P26: =MAX(0,MIN(99,IF(V26="",N(S26),N(V26))+N(Y26)+N(AB26))) -> 0 | S26: 0 | V26: =IF(职业选项!V64>0,职业选项!V64,"") | Y26: =规则数据!H32 | AB26: ='幕间计算'!B14+IF(AND('幕间计算'!A14<>"",COUNTIF('幕间计算'!$A$2:A14,'幕间计算'!A14)=1),SUMIF('幕间计算'!$C$200:$C$1199,'幕间计算'!A14,'幕间计算'!$E$200:$E$1199),0) -> 0 | AE26: ☐ | AG26: 特种载具： | AM26: =IF(COUNTIF(职业选项!$I$2:$I$28,"特种载具3")>0,IFERROR(INDEX(职业选项!$F$2:$F$28,MATCH("特种载具3",职业选项!$I$2:$I$28,0)),""),IFERROR(MID(IFERROR(INDEX(规则数据!$C$2:$C$9,SMALL(规则数据!$AV$2:$AV$9,3-COUNTIF(职业选项!$C$2:$C$28,"特种载具"))),""),LEN("特种载具")+2,LEN(IFERROR(INDEX(规则数据!$C$2:$C$9,SMALL(规则数据!$AV$2:$AV$9,3-COUNTIF(职业选项!$C$2:$C$28,"特种载具"))),""))-LEN("特种载具")-2),"")) | AS26: =MAX(0,MIN(99,IF(AY26="",N(AV26),N(AY26))+N(BB26)+N(BE26))) -> 0 | AV26: 0 | AY26: =IF(职业选项!V65>0,职业选项!V65,"") | BB26: =规则数据!H62 | BE26: ='幕间计算'!B44+IF(AND('幕间计算'!A44<>"",COUNTIF('幕间计算'!$A$2:A44,'幕间计算'!A44)=1),SUMIF('幕间计算'!$C$200:$C$1199,'幕间计算'!A44,'幕间计算'!$E$200:$E$1199),0) -> 0 | ED26: 值 | EF26: DG
B27: ☐ | D27: 工艺： | J27: =IF(COUNTIF(职业选项!$I$2:$I$28,"工艺3")>0,IFERROR(INDEX(职业选项!$F$2:$F$28,MATCH("工艺3",职业选项!$I$2:$I$28,0)),""),IFERROR(MID(IFERROR(INDEX(规则数据!$C$2:$C$9,SMALL(规则数据!$AS$2:$AS$9,3-COUNTIF(职业选项!$C$2:$C$28,"工艺"))),""),LEN("工艺")+2,LEN(IFERROR(INDEX(规则数据!$C$2:$C$9,SMALL(规则数据!$AS$2:$AS$9,3-COUNTIF(职业选项!$C$2:$C$28,"工艺"))),""))-LEN("工艺")-2),"")) | P27: =MAX(0,MIN(99,IF(V27="",N(S27),N(V27))+N(Y27)+N(AB27))) -> 0 | S27: 0 | V27: =IF(职业选项!V66>0,职业选项!V66,"") | Y27: =规则数据!H33 | AB27: ='幕间计算'!B15+IF(AND('幕间计算'!A15<>"",COUNTIF('幕间计算'!$A$2:A15,'幕间计算'!A15)=1),SUMIF('幕间计算'!$C$200:$C$1199,'幕间计算'!A15,'幕间计算'!$E$200:$E$1199),0) -> 0 | AE27: ☐ | AG27: 精神治疗 | AS27: =MAX(0,MIN(99,IF(AY27="",N(AV27),N(AY27))+N(BB27)+N(BE27))) -> 10 | AV27: 10 | AY27: =IF(职业选项!V67>0,职业选项!V67,"") | BB27: =规则数据!H63 | BE27: ='幕间计算'!B45+IF(AND('幕间计算'!A45<>"",COUNTIF('幕间计算'!$A$2:A45,'幕间计算'!A45)=1),SUMIF('幕间计算'!$C$200:$C$1199,'幕间计算'!A45,'幕间计算'!$E$200:$E$1199),0) -> 0 | ED27: =IF(CZ26="","",'幕间计算'!BR1199) | EF27: ×
B28: ☐ | D28: 工艺： | J28: =IF(COUNTIF(职业选项!$I$2:$I$28,"工艺4")>0,IFERROR(INDEX(职业选项!$F$2:$F$28,MATCH("工艺4",职业选项!$I$2:$I$28,0)),""),IFERROR(MID(IFERROR(INDEX(规则数据!$C$2:$C$9,SMALL(规则数据!$AS$2:$AS$9,4-COUNTIF(职业选项!$C$2:$C$28,"工艺"))),""),LEN("工艺")+2,LEN(IFERROR(INDEX(规则数据!$C$2:$C$9,SMALL(规则数据!$AS$2:$AS$9,4-COUNTIF(职业选项!$C$2:$C$28,"工艺"))),""))-LEN("工艺")-2),"")) | P28: =MAX(0,MIN(99,IF(V28="",N(S28),N(V28))+N(Y28)+N(AB28))) -> 0 | S28: 0 | V28: =IF(职业选项!V68>0,职业选项!V68,"") | Y28: =规则数据!H34 | AB28: ='幕间计算'!B16+IF(AND('幕间计算'!A16<>"",COUNTIF('幕间计算'!$A$2:A16,'幕间计算'!A16)=1),SUMIF('幕间计算'!$C$200:$C$1199,'幕间计算'!A16,'幕间计算'!$E$200:$E$1199),0) -> 0 | AE28: ☐ | AG28: 骑术 | AS28: =MAX(0,MIN(99,IF(AY28="",N(AV28),N(AY28))+N(BB28)+N(BE28))) -> 10 | AV28: 10 | AY28: =IF(职业选项!V69>0,职业选项!V69,"") | BB28: =规则数据!H64 | BE28: ='幕间计算'!B46+IF(AND('幕间计算'!A46<>"",COUNTIF('幕间计算'!$A$2:A46,'幕间计算'!A46)=1),SUMIF('幕间计算'!$C$200:$C$1199,'幕间计算'!A46,'幕间计算'!$E$200:$E$1199),0) -> 0
B29: ☐ | D29: 犯罪学 | P29: =MAX(0,MIN(99,IF(V29="",N(S29),N(V29))+N(Y29)+N(AB29))) -> 10 | S29: 10 | V29: =IF(职业选项!V70>0,职业选项!V70,"") | Y29: =规则数据!H35 | AB29: ='幕间计算'!B17+IF(AND('幕间计算'!A17<>"",COUNTIF('幕间计算'!$A$2:A17,'幕间计算'!A17)=1),SUMIF('幕间计算'!$C$200:$C$1199,'幕间计算'!A17,'幕间计算'!$E$200:$E$1199),0) -> 0 | AE29: ☐ | AG29: 科学： | AM29: =IF(COUNTIF(职业选项!$I$2:$I$28,"科学1")>0,IFERROR(INDEX(职业选项!$F$2:$F$28,MATCH("科学1",职业选项!$I$2:$I$28,0)),""),IFERROR(MID(IFERROR(INDEX(规则数据!$C$2:$C$9,SMALL(规则数据!$AW$2:$AW$9,1-COUNTIF(职业选项!$C$2:$C$28,"科学"))),""),LEN("科学")+2,LEN(IFERROR(INDEX(规则数据!$C$2:$C$9,SMALL(规则数据!$AW$2:$AW$9,1-COUNTIF(职业选项!$C$2:$C$28,"科学"))),""))-LEN("科学")-2),"")) | AS29: =MAX(0,MIN(99,IF(AY29="",N(AV29),N(AY29))+N(BB29)+N(BE29))) -> 0 | AV29: 0 | AY29: =IF(职业选项!V71>0,职业选项!V71,"") | BB29: =规则数据!H65 | BE29: ='幕间计算'!B47+IF(AND('幕间计算'!A47<>"",COUNTIF('幕间计算'!$A$2:A47,'幕间计算'!A47)=1),SUMIF('幕间计算'!$C$200:$C$1199,'幕间计算'!A47,'幕间计算'!$E$200:$E$1199),0) -> 0 | ED29: 值 | EF29: DG
B30: ☐ | D30: 爆破 | P30: =MAX(0,MIN(99,IF(V30="",N(S30),N(V30))+N(Y30)+N(AB30))) -> 0 | S30: 0 | V30: =IF(职业选项!V72>0,职业选项!V72,"") | Y30: =规则数据!H36 | AB30: ='幕间计算'!B18+IF(AND('幕间计算'!A18<>"",COUNTIF('幕间计算'!$A$2:A18,'幕间计算'!A18)=1),SUMIF('幕间计算'!$C$200:$C$1199,'幕间计算'!A18,'幕间计算'!$E$200:$E$1199),0) -> 0 | AE30: ☐ | AG30: 科学： | AM30: =IF(COUNTIF(职业选项!$I$2:$I$28,"科学2")>0,IFERROR(INDEX(职业选项!$F$2:$F$28,MATCH("科学2",职业选项!$I$2:$I$28,0)),""),IFERROR(MID(IFERROR(INDEX(规则数据!$C$2:$C$9,SMALL(规则数据!$AW$2:$AW$9,2-COUNTIF(职业选项!$C$2:$C$28,"科学"))),""),LEN("科学")+2,LEN(IFERROR(INDEX(规则数据!$C$2:$C$9,SMALL(规则数据!$AW$2:$AW$9,2-COUNTIF(职业选项!$C$2:$C$28,"科学"))),""))-LEN("科学")-2),"")) | AS30: =MAX(0,MIN(99,IF(AY30="",N(AV30),N(AY30))+N(BB30)+N(BE30))) -> 0 | AV30: 0 | AY30: =IF(职业选项!V73>0,职业选项!V73,"") | BB30: =规则数据!H66 | BE30: ='幕间计算'!B48+IF(AND('幕间计算'!A48<>"",COUNTIF('幕间计算'!$A$2:A48,'幕间计算'!A48)=1),SUMIF('幕间计算'!$C$200:$C$1199,'幕间计算'!A48,'幕间计算'!$E$200:$E$1199),0) -> 0 | ED30: =IF(CZ29="","",'幕间计算'!BS1199) | EF30: ×
B31: ☐ | D31: 乔装 | P31: =MAX(0,MIN(99,IF(V31="",N(S31),N(V31))+N(Y31)+N(AB31))) -> 10 | S31: 10 | V31: =IF(职业选项!V74>0,职业选项!V74,"") | Y31: =规则数据!H37 | AB31: ='幕间计算'!B19+IF(AND('幕间计算'!A19<>"",COUNTIF('幕间计算'!$A$2:A19,'幕间计算'!A19)=1),SUMIF('幕间计算'!$C$200:$C$1199,'幕间计算'!A19,'幕间计算'!$E$200:$E$1199),0) -> 0 | AE31: ☐ | AG31: 科学： | AM31: =IF(COUNTIF(职业选项!$I$2:$I$28,"科学3")>0,IFERROR(INDEX(职业选项!$F$2:$F$28,MATCH("科学3",职业选项!$I$2:$I$28,0)),""),IFERROR(MID(IFERROR(INDEX(规则数据!$C$2:$C$9,SMALL(规则数据!$AW$2:$AW$9,3-COUNTIF(职业选项!$C$2:$C$28,"科学"))),""),LEN("科学")+2,LEN(IFERROR(INDEX(规则数据!$C$2:$C$9,SMALL(规则数据!$AW$2:$AW$9,3-COUNTIF(职业选项!$C$2:$C$28,"科学"))),""))-LEN("科学")-2),"")) | AS31: =MAX(0,MIN(99,IF(AY31="",N(AV31),N(AY31))+N(BB31)+N(BE31))) -> 0 | AV31: 0 | AY31: =IF(职业选项!V75>0,职业选项!V75,"") | BB31: =规则数据!H67 | BE31: ='幕间计算'!B49+IF(AND('幕间计算'!A49<>"",COUNTIF('幕间计算'!$A$2:A49,'幕间计算'!A49)=1),SUMIF('幕间计算'!$C$200:$C$1199,'幕间计算'!A49,'幕间计算'!$E$200:$E$1199),0) -> 0
B32: ☐ | D32: 闪避 | P32: =MAX(0,MIN(99,IF(V32="",N(S32),N(V32))+N(Y32)+N(AB32))) -> 30 | S32: 30 | V32: =IF(职业选项!V76>0,职业选项!V76,"") | Y32: =规则数据!H38 | AB32: ='幕间计算'!B20+IF(AND('幕间计算'!A20<>"",COUNTIF('幕间计算'!$A$2:A20,'幕间计算'!A20)=1),SUMIF('幕间计算'!$C$200:$C$1199,'幕间计算'!A20,'幕间计算'!$E$200:$E$1199),0) -> 0 | AE32: ☐ | AG32: 搜寻 | AS32: =MAX(0,MIN(99,IF(AY32="",N(AV32),N(AY32))+N(BB32)+N(BE32))) -> 20 | AV32: 20 | AY32: =IF(职业选项!V77>0,职业选项!V77,"") | BB32: =规则数据!H68 | BE32: ='幕间计算'!B50+IF(AND('幕间计算'!A50<>"",COUNTIF('幕间计算'!$A$2:A50,'幕间计算'!A50)=1),SUMIF('幕间计算'!$C$200:$C$1199,'幕间计算'!A50,'幕间计算'!$E$200:$E$1199),0) -> 0 | ED32: 值 | EF32: DG
B33: ☐ | D33: 机动车驾驶 | P33: =MAX(0,MIN(99,IF(V33="",N(S33),N(V33))+N(Y33)+N(AB33))) -> 20 | S33: 20 | V33: =IF(职业选项!V78>0,职业选项!V78,"") | Y33: =规则数据!H39 | AB33: ='幕间计算'!B21+IF(AND('幕间计算'!A21<>"",COUNTIF('幕间计算'!$A$2:A21,'幕间计算'!A21)=1),SUMIF('幕间计算'!$C$200:$C$1199,'幕间计算'!A21,'幕间计算'!$E$200:$E$1199),0) -> 0 | AE33: ☐ | AG33: 信号情报 | AS33: =MAX(0,MIN(99,IF(AY33="",N(AV33),N(AY33))+N(BB33)+N(BE33))) -> 0 | AV33: 0 | AY33: =IF(职业选项!V79>0,职业选项!V79,"") | BB33: =规则数据!H69 | BE33: ='幕间计算'!B51+IF(AND('幕间计算'!A51<>"",COUNTIF('幕间计算'!$A$2:A51,'幕间计算'!A51)=1),SUMIF('幕间计算'!$C$200:$C$1199,'幕间计算'!A51,'幕间计算'!$E$200:$E$1199),0) -> 0 | ED33: =IF(CZ32="","",'幕间计算'!BT1199) | EF33: ×
B34: ☐ | D34: 射击 | P34: =MAX(0,MIN(99,IF(V34="",N(S34),N(V34))+N(Y34)+N(AB34))) -> 20 | S34: 20 | V34: =IF(职业选项!V80>0,职业选项!V80,"") | Y34: =规则数据!H40 | AB34: ='幕间计算'!B22+IF(AND('幕间计算'!A22<>"",COUNTIF('幕间计算'!$A$2:A22,'幕间计算'!A22)=1),SUMIF('幕间计算'!$C$200:$C$1199,'幕间计算'!A22,'幕间计算'!$E$200:$E$1199),0) -> 0 | AE34: ☐ | AG34: 潜藏 | AS34: =MAX(0,MIN(99,IF(AY34="",N(AV34),N(AY34))+N(BB34)+N(BE34))) -> 10 | AV34: 10 | AY34: =IF(职业选项!V81>0,职业选项!V81,"") | BB34: =规则数据!H70 | BE34: ='幕间计算'!B52+IF(AND('幕间计算'!A52<>"",COUNTIF('幕间计算'!$A$2:A52,'幕间计算'!A52)=1),SUMIF('幕间计算'!$C$200:$C$1199,'幕间计算'!A52,'幕间计算'!$E$200:$E$1199),0) -> 0
B35: ☐ | D35: 急救 | P35: =MAX(0,MIN(99,IF(V35="",N(S35),N(V35))+N(Y35)+N(AB35))) -> 10 | S35: 10 | V35: =IF(职业选项!V82>0,职业选项!V82,"") | Y35: =规则数据!H41 | AB35: ='幕间计算'!B23+IF(AND('幕间计算'!A23<>"",COUNTIF('幕间计算'!$A$2:A23,'幕间计算'!A23)=1),SUMIF('幕间计算'!$C$200:$C$1199,'幕间计算'!A23,'幕间计算'!$E$200:$E$1199),0) -> 0 | AE35: ☐ | AG35: 手术 | AS35: =MAX(0,MIN(99,IF(AY35="",N(AV35),N(AY35))+N(BB35)+N(BE35))) -> 0 | AV35: 0 | AY35: =IF(职业选项!V83>0,职业选项!V83,"") | BB35: =规则数据!H71 | BE35: ='幕间计算'!B53+IF(AND('幕间计算'!A53<>"",COUNTIF('幕间计算'!$A$2:A53,'幕间计算'!A53)=1),SUMIF('幕间计算'!$C$200:$C$1199,'幕间计算'!A53,'幕间计算'!$E$200:$E$1199),0) -> 0 | ED35: 值 | EF35: DG
B36: ☐ | D36: 外语： | J36: =IF(COUNTIF(职业选项!$I$2:$I$28,"外语1")>0,IFERROR(INDEX(职业选项!$F$2:$F$28,MATCH("外语1",职业选项!$I$2:$I$28,0)),""),IFERROR(MID(IFERROR(INDEX(规则数据!$C$2:$C$9,SMALL(规则数据!$AT$2:$AT$9,1-COUNTIF(职业选项!$C$2:$C$28,"外语"))),""),LEN("外语")+2,LEN(IFERROR(INDEX(规则数据!$C$2:$C$9,SMALL(规则数据!$AT$2:$AT$9,1-COUNTIF(职业选项!$C$2:$C$28,"外语"))),""))-LEN("外语")-2),"")) | P36: =MAX(0,MIN(99,IF(V36="",N(S36),N(V36))+N(Y36)+N(AB36))) -> 0 | S36: 0 | V36: =IF(职业选项!V84>0,职业选项!V84,"") | Y36: =规则数据!H42 | AB36: ='幕间计算'!B24+IF(AND('幕间计算'!A24<>"",COUNTIF('幕间计算'!$A$2:A24,'幕间计算'!A24)=1),SUMIF('幕间计算'!$C$200:$C$1199,'幕间计算'!A24,'幕间计算'!$E$200:$E$1199),0) -> 0 | AE36: ☐ | AG36: 生存 | AS36: =MAX(0,MIN(99,IF(AY36="",N(AV36),N(AY36))+N(BB36)+N(BE36))) -> 10 | AV36: 10 | AY36: =IF(职业选项!V85>0,职业选项!V85,"") | BB36: =规则数据!H72 | BE36: ='幕间计算'!B54+IF(AND('幕间计算'!A54<>"",COUNTIF('幕间计算'!$A$2:A54,'幕间计算'!A54)=1),SUMIF('幕间计算'!$C$200:$C$1199,'幕间计算'!A54,'幕间计算'!$E$200:$E$1199),0) -> 0 | ED36: =IF(CZ35="","",'幕间计算'!BU1199) | EF36: ×
B37: ☐ | D37: 外语： | J37: =IF(COUNTIF(职业选项!$I$2:$I$28,"外语2")>0,IFERROR(INDEX(职业选项!$F$2:$F$28,MATCH("外语2",职业选项!$I$2:$I$28,0)),""),IFERROR(MID(IFERROR(INDEX(规则数据!$C$2:$C$9,SMALL(规则数据!$AT$2:$AT$9,2-COUNTIF(职业选项!$C$2:$C$28,"外语"))),""),LEN("外语")+2,LEN(IFERROR(INDEX(规则数据!$C$2:$C$9,SMALL(规则数据!$AT$2:$AT$9,2-COUNTIF(职业选项!$C$2:$C$28,"外语"))),""))-LEN("外语")-2),"")) | P37: =MAX(0,MIN(99,IF(V37="",N(S37),N(V37))+N(Y37)+N(AB37))) -> 0 | S37: 0 | V37: =IF(职业选项!V86>0,职业选项!V86,"") | Y37: =规则数据!H43 | AB37: ='幕间计算'!B25+IF(AND('幕间计算'!A25<>"",COUNTIF('幕间计算'!$A$2:A25,'幕间计算'!A25)=1),SUMIF('幕间计算'!$C$200:$C$1199,'幕间计算'!A25,'幕间计算'!$E$200:$E$1199),0) -> 0 | AE37: ☐ | AG37: 游泳 | AS37: =MAX(0,MIN(99,IF(AY37="",N(AV37),N(AY37))+N(BB37)+N(BE37))) -> 20 | AV37: 20 | AY37: =IF(职业选项!V87>0,职业选项!V87,"") | BB37: =规则数据!H73 | BE37: ='幕间计算'!B55+IF(AND('幕间计算'!A55<>"",COUNTIF('幕间计算'!$A$2:A55,'幕间计算'!A55)=1),SUMIF('幕间计算'!$C$200:$C$1199,'幕间计算'!A55,'幕间计算'!$E$200:$E$1199),0) -> 0
B38: ☐ | D38: 外语： | J38: =IF(COUNTIF(职业选项!$I$2:$I$28,"外语3")>0,IFERROR(INDEX(职业选项!$F$2:$F$28,MATCH("外语3",职业选项!$I$2:$I$28,0)),""),IFERROR(MID(IFERROR(INDEX(规则数据!$C$2:$C$9,SMALL(规则数据!$AT$2:$AT$9,3-COUNTIF(职业选项!$C$2:$C$28,"外语"))),""),LEN("外语")+2,LEN(IFERROR(INDEX(规则数据!$C$2:$C$9,SMALL(规则数据!$AT$2:$AT$9,3-COUNTIF(职业选项!$C$2:$C$28,"外语"))),""))-LEN("外语")-2),"")) | P38: =MAX(0,MIN(99,IF(V38="",N(S38),N(V38))+N(Y38)+N(AB38))) -> 0 | S38: 0 | V38: =IF(职业选项!V88>0,职业选项!V88,"") | Y38: =规则数据!H44 | AB38: ='幕间计算'!B26+IF(AND('幕间计算'!A26<>"",COUNTIF('幕间计算'!$A$2:A26,'幕间计算'!A26)=1),SUMIF('幕间计算'!$C$200:$C$1199,'幕间计算'!A26,'幕间计算'!$E$200:$E$1199),0) -> 0 | AE38: ☐ | AG38: 徒手搏斗 | AS38: =MAX(0,MIN(99,IF(AY38="",N(AV38),N(AY38))+N(BB38)+N(BE38))) -> 40 | AV38: 40 | AY38: =IF(职业选项!V89>0,职业选项!V89,"") | BB38: =规则数据!H74 | BE38: ='幕间计算'!B56+IF(AND('幕间计算'!A56<>"",COUNTIF('幕间计算'!$A$2:A56,'幕间计算'!A56)=1),SUMIF('幕间计算'!$C$200:$C$1199,'幕间计算'!A56,'幕间计算'!$E$200:$E$1199),0) -> 0 | ED38: 值 | EF38: DG
B39: ☐ | D39: 法证学 | P39: =MAX(0,MIN(99,IF(V39="",N(S39),N(V39))+N(Y39)+N(AB39))) -> 0 | S39: 0 | V39: =IF(职业选项!V90>0,职业选项!V90,"") | Y39: =规则数据!H45 | AB39: ='幕间计算'!B27+IF(AND('幕间计算'!A27<>"",COUNTIF('幕间计算'!$A$2:A27,'幕间计算'!A27)=1),SUMIF('幕间计算'!$C$200:$C$1199,'幕间计算'!A27,'幕间计算'!$E$200:$E$1199),0) -> 0 | AE39: ☐ | AG39: 非自然知识 | AS39: =MAX(0,MIN(99,N(BB39)+N(BE39))) -> 0 | AV39: 0 | AY39: — | BB39: =IF(DF46="人类不应知道之事",10,0) -> 0 | BE39: ='幕间计算'!B57+IF(AND('幕间计算'!A57<>"",COUNTIF('幕间计算'!$A$2:A57,'幕间计算'!A57)=1),SUMIF('幕间计算'!$C$200:$C$1199,'幕间计算'!A57,'幕间计算'!$E$200:$E$1199),0) -> 0 | ED39: =IF(CZ38="","",'幕间计算'!BV1199) | EF39: ×
B40: ☐ | D40: 重型机械 | P40: =MAX(0,MIN(99,IF(V40="",N(S40),N(V40))+N(Y40)+N(AB40))) -> 10 | S40: 10 | V40: =IF(职业选项!V91>0,职业选项!V91,"") | Y40: =规则数据!H46 | AB40: ='幕间计算'!B28+IF(AND('幕间计算'!A28<>"",COUNTIF('幕间计算'!$A$2:A28,'幕间计算'!A28)=1),SUMIF('幕间计算'!$C$200:$C$1199,'幕间计算'!A28,'幕间计算'!$E$200:$E$1199),0) -> 0 | AE40: ☐ | AG40: =IFERROR(INDEX(规则数据!$C$2:$C$9,SMALL(规则数据!$AX$2:$AX$9,1)),"") | AS40: =MAX(0,MIN(99,IF(AY40="",N(AV40),N(AY40))+N(BB40)+N(BE40))) -> 0 | BB40: =规则数据!H75 | BE40: ='幕间计算'!B58+IF(AND('幕间计算'!A58<>"",COUNTIF('幕间计算'!$A$2:A58,'幕间计算'!A58)=1),SUMIF('幕间计算'!$C$200:$C$1199,'幕间计算'!A58,'幕间计算'!$E$200:$E$1199),0) -> 0
B41: ☐ | D41: 重型武器 | P41: =MAX(0,MIN(99,IF(V41="",N(S41),N(V41))+N(Y41)+N(AB41))) -> 0 | S41: 0 | V41: =IF(职业选项!V92>0,职业选项!V92,"") | Y41: =规则数据!H47 | AB41: ='幕间计算'!B29+IF(AND('幕间计算'!A29<>"",COUNTIF('幕间计算'!$A$2:A29,'幕间计算'!A29)=1),SUMIF('幕间计算'!$C$200:$C$1199,'幕间计算'!A29,'幕间计算'!$E$200:$E$1199),0) -> 0 | AE41: ☐ | AG41: =IFERROR(INDEX(规则数据!$C$2:$C$9,SMALL(规则数据!$AX$2:$AX$9,2)),"") | AS41: =MAX(0,MIN(99,IF(AY41="",N(AV41),N(AY41))+N(BB41)+N(BE41))) -> 0 | BB41: =规则数据!H76 | BE41: ='幕间计算'!B59+IF(AND('幕间计算'!A59<>"",COUNTIF('幕间计算'!$A$2:A59,'幕间计算'!A59)=1),SUMIF('幕间计算'!$C$200:$C$1199,'幕间计算'!A59,'幕间计算'!$E$200:$E$1199),0) -> 0 | ED41: 值 | EF41: DG
...

Sheet 骰子指令
A1: 骰子属性设置指令
A2: 复制方法：（需要Excel 2019或更新版本） 1. 选择右方单元格，复制。 2. 粘贴到任意单元格，在一旁的下拉菜单选择“复制值”。 3. 复制该值。 | B2: =".st "&_xlfn.CONCAT(附表!E93:E162) -> .st 会计学10警觉20运动30行政10犯罪学10乔装10闪避30机动车驾驶20射击20急救10重型机械10历史10人源情报10近战武器30导航10神秘学10说服20精神治疗10骑术10搜寻20潜藏10生存10游泳20徒手搏斗40
A3: 生成6个属性的骰子指令
A4: .r6#4d6k3

Sheet 职业列表
A1: 职业名 | B1: 推荐属性 | C1: 重要关系数 | D1: 固定职业技能 | T1: 自由职业技能数 | U1: 自由职业技能选项 | AF1: 子模板 | AJ1: 建议额外技能 | AN1: 装备
A2: （创建新职业） | C2: ≤4 | D2: {=TRANSPOSE(附表!A37:A41)} -> 任选10个本职技能，分配350 | E2: 技能点，额外加在基础值上， | F2: 最高至60%。重要关系自4个开 | G2: 始每少一个（最少1个），增 | H2: 加50本职技能点。 | AO2: =ROW() -> 2
A3: （主持人自定义职业模板栏位） | AO3: =IF(LEFT(TRIM(A3&"$"),1)="（",65536,ROW()) -> 65536
A4: （这几栏可以自由编辑） | AO4: =IF(LEFT(TRIM(A4&"$"),1)="（",65536,ROW()) -> 65536
A5: （一般用于主持人提供的职业模板） | AO5: =IF(LEFT(TRIM(A5&"$"),1)="（",65536,ROW()) -> 65536
A6: （玩家自定义模板不建议放这里） | AO6: =IF(LEFT(TRIM(A6&"$"),1)="（",65536,ROW()) -> 65536
A7: （直接填写技能即可，毕竟模板只是参考） | AO7: =IF(LEFT(TRIM(A7&"$"),1)="（",65536,ROW()) -> 65536
A8: 人类学家或历史学家 | B8: 智力 | C8: 4 | D8: 人类学50%或考古学50% | E8: 行政40% | F8: 外语（任选）50% | G8: 外语（任选）40% | H8: 历史60% | I8: 神秘学40% | J8: 说服40% | T8: 2 | U8: 人类学40% | V8: 考古学40% | W8: 人源情报50% | X8: 导航50% | Y8: 骑术50% | Z8: 搜寻60% | AA8: 生存50% | AO8: =ROW() -> 8
A9: 计算机科学家或工程师 | B9: 智力 | C9: 3 | D9: 计算机科学60% | E9: 工艺（电工）30% | F9: 工艺（机械）30% | G9: 工艺（微电子）40% | H9: 科学（数学）40% | I9: 信号情报40% | T9: 4 | U9: 会计学50% | V9: 行政50% | W9: 工艺（任选）40% | X9: 外语（任选）40% | Y9: 重型机械50% | Z9: 法律40% | AA9: 科学（任选）40% | AO9: =ROW() -> 9
A10: 联邦探员 | B10: 体质，意志，魅力 | C10: 3 | D10: 警觉50% | E10: 行政40% | F10: 犯罪学50% | G10: 机动车驾驶50% | H10: 射击50% | I10: 法证学30% | J10: 人源情报60% | K10: 法律30% | L10: 说服50% | M10: 搜寻50% | N10: 徒手搏斗60% | T10: 1 | U10: 会计学60% | V10: 计算机科学50% | W10: 外语（任选）50% | X10: 重型武器50% | Y10: 药学50% | AO10: =ROW() -> 10
A11: 医生 | B11: 智力，意志，敏捷 | C11: 3 | D11: 行政50% | E11: 急救60% | F11: 医学60% | G11: 说服40% | H11: 药学50% | I11: 科学（生物学）60% | J11: 搜寻40% | T11: 2 | U11: 法证学50% | V11: 精神治疗60% | W11: 科学（任选）50% | X11: 手术50% | AO11: =ROW() -> 11
A12: 科学家 | B12: 智力 | C12: 4 | D12: 行政40% | E12: 计算机科学40% | F12: 科学（任选）60% | G12: 科学（任选）50% | H12: 科学（任选）50% | T12: 3 | U12: 会计学50% | V12: 工艺（任选）40% | W12: 外语（任选）40% | X12: 法证学40% | Y12: 法律40% | Z12: 药学40% | AO12: =ROW() -> 12
A13: 特种作战员 | B13: 力量，体质，意志 | C13: 2 | D13: 警觉60% | E13: 运动60% | F13: 爆破40% | G13: 射击60% | H13: 重型武器50% | I13: 近战武器50% | J13: 军事科学（陆军）60% | K13: 导航50% | L13: 潜藏50% | M13: 生存50% | N13: 游泳50% | O13: 徒手搏斗60% | AO13: =ROW() -> 13
A14: 【额外】罪犯 | B14: 力量，敏捷 | C14: 4 | D14: 警觉50% | E14: 运动50% | F14: 犯罪学60% | G14: 闪避40% | H14: 机动车驾驶50% | I14: 射击40% | J14: 法律20% | K14: 近战武器40% | L14: 说服50% | M14: 潜藏50% | N14: 徒手搏斗50% | T14: 2 | U14: 工艺（锁匠）40% | V14: 爆破40% | W14: 乔装50% | X14: 外语（任选）40% | Y14: 法证学40% | Z14: 人源情报50% | AA14: 导航50% | AB14: 神秘学50% | AC14: 药学40% | AO14: =ROW() -> 14
A15: 【额外】消防队员 | B15: 力量，敏捷，体质 | C15: 3 | D15: 警觉50% | E15: 运动60% | F15: 工艺（电工）40% | G15: 工艺（机械）40% | H15: 爆破50% | I15: 机动车驾驶50% | J15: 急救50% | K15: 法证学40% | L15: 重型机械50% | M15: 导航50% | N15: 搜寻40% | AO15: =ROW() -> 15
A16: 【额外】外事官员 | B16: 智力，魅力 | C16: 3 | D16: 会计学40% | E16: 人类学40% | F16: 行政60% | G16: 外语（任选）50% | H16: 外语（任选）50% | I16: 外语（任选）40% | J16: 历史40% | K16: 人源情报50% | L16: 法律40% | M16: 说服50% | AO16: =ROW() -> 16
A17: 【额外】情报分析员 | B17: 智力 | C17: 3 | D17: 人类学40% | E17: 行政50% | F17: 计算机科学40% | G17: 犯罪学40% | H17: 外语（任选）50% | I17: 外语（任选）50% | J17: 外语（任选）40% | K17: 历史40% | L17: 人源情报50% | M17: 信号情报40% | AO17: =ROW() -> 17
A18: 【额外】情报官员 | B18: 智力，意志，魅力 | C18: 2 | D18: 警觉50% | E18: 行政40% | F18: 犯罪学50% | G18: 乔装50% | H18: 机动车驾驶40% | I18: 射击40% | J18: 外语（任选）50% | K18: 外语（任选）40% | L18: 人源情报60% | M18: 说服60% | N18: 信号情报40% | O18: 潜藏50% | P18: 徒手搏斗50% | AO18: =ROW() -> 18
A19: 【额外】律师或商务主管 | B19: 智力，魅力 | C19: 4 | D19: 会计学50% | E19: 行政50% | F19: 人源情报40% | G19: 说服60% | T19: 4 | U19: 计算机科学50% | V19: 犯罪学60% | W19: 外语（任选）50% | X19: 法律50% | Y19: 药学50% | AO19: =ROW() -> 19
A20: 【额外】媒体专家 | B20: 智力，魅力 | C20: 4 | D20: 艺术（任选）60% | E20: 历史40% | F20: 人源情报40% | G20: 说服50% | T20: 5 | U20: 人类学40% | V20: 考古学40% | W20: 艺术（任选）40% | X20: 行政50% | Y20: 计算机科学40% | Z20: 犯罪学50% | AA20: 外语（任选）40% | AB20: 法律40% | AC20: 军事科学（任选）40% | AD20: 神秘学50% | AE20: 科学（任选）40% | AO20: =ROW() -> 20
A21: 【额外】护士或护理人员 | B21: 智力，意志，魅力 | C21: 4 | D21: 警觉40% | E21: 行政40% | F21: 急救60% | G21: 人源情报40% | H21: 医学40% | I21: 说服40% | J21: 药学40% | K21: 科学（生物学）40% | T21: 2 | U21: 机动车驾驶60% | V21: 法证学40% | W21: 导航50% | X21: 精神治疗50% | Y21: 搜寻60% | AO21: =ROW() -> 21
A22: 【额外】飞行员或水手 | B22: 敏捷，智力 | C22: 3 | D22: 警觉60% | E22: 行政30% | F22: 工艺（电工）40% | G22: 工艺（机械）40% | H22: 导航50% | I22: 特种载具（任选）60% | J22: 科学（气象学）40% | K22: 游泳40% | T22: 2 | U22: 外语（任选）50% | V22: 特种载具（任选）50% | W22: 重型武器50% | X22: 军事科学（任选）50% | AO22: =ROW() -> 22
A23: 【额外】警察 | B23: 力量，体质，意志 | C23: 3 | D23: 警觉60% | E23: 行政40% | F23: 犯罪学40% | G23: 机动车驾驶50% | H23: 射击40% | I23: 急救30% | J23: 人源情报50% | K23: 法律30% | L23: 近战武器50% | M23: 导航40% | N23: 说服40% | O23: 搜寻40% | P23: 徒手搏斗60% | T23: 1 | U23: 法证学50% | V23: 重型机械60% | W23: 重型武器50% | X23: 骑术60% | AO23: =ROW() -> 23
A24: 【额外】项目群经理 | B24: 智力，魅力 | C24: 4 | D24: 会计学60% | E24: 行政60% | F24: 计算机科学50% | G24: 犯罪学30% | H24: 外语（任选）50% | I24: 历史40% | J24: 法律40% | K24: 说服50% | T24: 1 | U24: 人类学30% | V24: 艺术（任选）30% | W24: 工艺（任选）30% | X24: 科学（任选）30% | AO24: =ROW() -> 24
A25: 【额外】士兵或海军陆战队员 | B25: 力量，体质 | C25: 4 | D25: 警觉50% | E25: 运动50% | F25: 行政30% | G25: 机动车驾驶40% | H25: 射击40% | I25: 急救40% | J25: 军事科学（陆军）40% | K25: 导航40% | L25: 说服30% | M25: 徒手搏斗50% | T25: 3 | U25: 炮术40% | V25: 计算机科学40% | W25: 工艺（任选）40% | X25: 爆破40% | Y25: 外语（任选）40% | Z25: 重型机械50% | AA25: 重型武器40% | AB25: 搜寻60% | AC25: 信号情报40% | AD25: 游泳60% | AO25: =ROW() -> 25
A26: FBI / 犯罪调查处（CID） | AF26: 联邦探员 | AJ26: 犯罪学 | AK26: 药学 | AL26: 科学（化学） | AM26: 搜寻 | AN26: =附表!$L$62&"。" -> 参见《特工手册》的“本职装备：联邦探员”。 | AO26: =ROW() -> 26
A27: FBI / 国家安保部（NSB） | AF27: 联邦探员 | AG27: 情报分析员 | AH27: 情报官员 | AJ27: 外语 | AK27: 人源情报 | AL27: 信号情报 | AM27: 计算机科学 | AN27: =附表!$L$62&"，此外还有一台强固式笔电，加载先进的数据分析软件，化学嗅探器/分析仪。" -> 参见《特工手册》的“本职装备：联邦探员”，此外还有一台强固式笔电，加载先进的数据分析软件，化学嗅探器/分析仪。 | AO27: =ROW() -> 27
A28: FBI / 调查与行动支援科（IOSS） | AF28: 计算机科学家 | AG28: 情报官员 | AH28: 医生 | AI28: 科学家 | AJ28: 计算机科学 | AK28: 人源情报 | AL28: 精神治疗 | AM28: 科学（任选） | AN28: 收藏广泛的专业图书馆，ViCAP的使用权限，且/或使用最先进的犯罪学软件。 | AO28: =ROW() -> 28
A29: FBI / 情报部 | AF29: 情报分析员 | AG29: 情报官员 | AJ29: 犯罪学 | AK29: 法证学 | AL29: 射击 | AM29: 法律 | AN29: 语言培训材料或电子监控设备。 | AO29: =ROW() -> 29
A30: FBI / 人质救援队（HRT）或特警队（SWAT） | C30: 1 | D30: 警觉60% | E30: 运动60% | F30: 爆破40% | G30: 闪避50% | H30: 射击60% | I30: 法证学30% | J30: 重型武器50% | K30: 近战武器50% | L30: 军事科学（陆军）60% | M30: 导航50% | N30: 潜藏50% | O30: 生存50% | P30: 游泳50% | Q30: 徒手搏斗60% | AJ30: 犯罪学 | AK30: 射击 | AL30: 近战武器 | AM30: 潜藏 | AN30: =附表!$L$63&"。HRT还能获得专业便携式电脑，可使用FBI的指纹自动识别系统（IAFIS）及DoD的自动生物识别系统（ABIS）。" -> 参见《特工手册》的“本职装备：特警部队”。HRT还能获得专业便携式电脑，可使用FBI的指纹自动识别系统（IAFIS）及DoD的自动生物识别系统（ABIS）。 | AO30: =ROW() -> 30
A31: DEA / 行动分处 | AF31: 联邦探员 | AG31: 警察 | AJ31: 犯罪学 | AK31: 药学 | AL31: 科学（化学） | AM31: 搜寻 | AN31: =附表!$L$62&"。" -> 参见《特工手册》的“本职装备：联邦探员”。 | AO31: =ROW() -> 31
A32: DEA / 行动支援分处 | AF32: 人类学家或历史学家 | AG32: 律师 | AH32: 项目群经理 | AI32: 科学家 | AJ32: 会计学 | AK32: 法证学 | AL32: 法律 | AM32: 药学 | AN32: 专业资料库和技术设备。 | AO32: =ROW() -> 32
A33: DEA / 特种作战科（SOD） | AF33: 计算机科学家 | AG33: 情报分析员 | AJ33: 计算机科学 | AK33: 犯罪学 | AL33: 法律 | AM33: 信号情报 | AN33: 窃听装置及电子监控设备。 | AO33: =ROW() -> 33
A34: DEA / 海外部署咨询与支援小组（FAST） | C34: 2 | D34: 警觉50% | E34: 行政40% | F34: 犯罪学50% | G34: 机动车驾驶40% | H34: 射击50% | I34: 外语（任选）30% | J34: 法证学30% | K34: 重型武器30% | L34: 人源情报30% | M34: 法律30% | N34: 军事科学（陆军）30% | O34: 说服40% | P34: 药学30% | Q34: 搜寻50% | R34: 生存30% | S34: 徒手搏斗60% | AJ34: 运动 | AK34: 射击 | AL34: 法证学 | AM34: 搜寻 | AN34: =附表!$L$64&"。" -> 参见《特工手册》的“本职装备：警局警员”。 | AO34: =ROW() -> 34
A35: ICE / 国土调查处（HSI） | AF35: 联邦探员 | AJ35: 行政 | AK35: 犯罪学 | AL35: 法证学 | AM35: 人源情报 | AN35: =附表!$L$62&"。" -> 参见《特工手册》的“本职装备：联邦探员”。 | AO35: =ROW() -> 35
A36: ICE / HIS，情报办公室 | AF36: 媒体专家 | AG36: 情报分析员 | AJ36: 行政 | AK36: 计算机科学 | AL36: 科学（任选） | AM36: 信号情报 | AN36: =附表!$L$62&"。" -> 参见《特工手册》的“本职装备：联邦探员”。 | AO36: =ROW() -> 36
A37: ICE / 特别应对小组（SRT） | C37: 2 | D37: 警觉50% | E37: 行政40% | F37: 犯罪学50% | G37: 闪避50% | H37: 机动车驾驶50% | I37: 射击50% | J37: 法证学30% | K37: 重型武器50% | L37: 人源情报60% | M37: 法律30% | N37: 说服50% | O37: 搜寻50% | P37: 潜藏40% | Q37: 徒手搏斗60% | AJ37: 闪避 | AK37: 射击 | AL37: 犯罪学 | AM37: 近战武器 | AN37: =附表!$L$63&"。" -> 参见《特工手册》的“本职装备：特警部队”。 | AO37: =ROW() -> 37
A38: ICE / 遣返行动执法处（ERO） | AF38: 联邦探员 | AJ38: 运动 | AK38: 人源情报 | AL38: 说服 | AM38: 徒手搏斗 | AN38: =附表!$L$62&"。" -> 参见《特工手册》的“本职装备：联邦探员”。 | AO38: =ROW() -> 38
A39: USMS / 调查行动处 | AF39: 联邦探员 | AJ39: 犯罪学 | AK39: 法证学 | AL39: 法律 | AM39: 搜寻 | AN39: =附表!$L$62&"。" -> 参见《特工手册》的“本职装备：联邦探员”。 | AO39: =ROW() -> 39
A40: USMS / 特种行动队（SOG） | C40: 2 | D40: 警觉50% | E40: 运动40% | F40: 行政40% | G40: 犯罪学50% | H40: 闪避40% | I40: 机动车驾驶50% | J40: 射击50% | K40: 法证学30% | L40: 重型武器50% | M40: 人源情报60% | N40: 法律30% | O40: 说服50% | P40: 搜寻50% | Q40: 潜藏40% | R40: 徒手搏斗60% | AJ40: 运动 | AK40: 闪避 | AL40: 射击 | AM40: 徒手搏斗 | AN40: =附表!$L$63&"。" -> 参见《特工手册》的“本职装备：特警部队”。 | AO40: =ROW() -> 40
...

Sheet 额外技能包
A1: 额外技能包名 | B1: 固定额外技能名 | J1: 自由额外技能技能数 | K1: 自由额外技能
A2: （自选） | B2: {=TRANSPOSE(附表!G37:G43)} -> 选择8个技能（除了非自 | C2: 然知识），为每一个加上 | D2: 20点。不能超过80%。可 | E2: 重复选择。 | F2: 0 | G2: 0 | H2: 0
A3: 艺术家，演员或音乐家 | B3: 警觉 | C3: 工艺（任选） | D3: 乔装 | E3: 说服 | F3: 艺术（任选） | G3: 艺术（任选） | H3: 艺术（任选） | I3: 人源情报
A4: 运动员 | B4: 警觉 | C4: 运动 | D4: 闪避 | E4: 急救 | F4: 人源情报 | G4: 说服 | H4: 游泳 | I4: 徒手搏斗
A5: 作家，编辑或新闻撰稿人 | B5: 艺术（任选） | C5: 人类学 | D5: 行政 | E5: 历史 | F5: 法律 | G5: 神秘学 | H5: 说服 | I5: 人源情报
A6: 潜入训练 | B6: 警觉 | C6: 运动 | D6: 工艺（电工） | E6: 工艺（锁匠） | F6: 犯罪学 | G6: 乔装 | H6: 搜寻 | I6: 潜藏
A7: 蓝领工人 | B7: 警觉 | C7: 工艺（任选） | D7: 工艺（任选） | E7: 机动车驾驶 | F7: 急救 | G7: 重型机械 | H7: 导航 | I7: 搜寻
A8: 政府官员 | B8: 会计学 | C8: 行政 | D8: 计算机科学 | E8: 犯罪学 | F8: 人源情报 | G8: 法律 | H8: 说服 | I8: 另一项个人特长
A9: 神职人员 | B9: 外语（任择三项） | C9: 历史 | D9: 人源情报 | E9: 神秘学 | F9: 说服 | G9: 精神治疗
A10: 老兵 | B10: 警觉 | C10: 闪避 | D10: 射击 | E10: 急救 | F10: 重型武器 | G10: 近战武器 | H10: 潜藏 | I10: 徒手搏斗
A11: 电脑狂热者或黑客 | B11: 计算机科学 | C11: 工艺（微电子） | D11: 科学（数学） | E11: 信号情报 | F11: 另四项个人特长
A12: 顾问 | B12: 行政 | C12: 急救 | D12: 外语（任选） | E12: 人源情报 | F12: 法律 | G12: 说服 | H12: 精神治疗 | I12: 搜寻
A13: 刑事专家 | B13: 会计学 | C13: 行政 | D13: 计算机科学 | E13: 犯罪学 | F13: 法证学 | G13: 法律 | H13: 药学 | I13: 搜寻
A14: 消防员 | B14: 警觉 | C14: 爆破 | D14: 机动车驾驶 | E14: 急救 | F14: 法证学 | G14: 重型机械 | H14: 导航 | I14: 搜寻
A15: 黑帮或卧底 | B15: 警觉 | C15: 犯罪学 | D15: 闪避 | E15: 机动车驾驶 | F15: 说服 | G15: 潜藏 | J15: 2 | K15: 运动 | L15: 外语（任选） | M15: 射击 | N15: 人源情报 | O15: 近战武器 | P15: 药学 | Q15: 徒手搏斗
A16: 审讯官 | B16: 犯罪学 | C16: 外语（任选） | D16: 外语（任选） | E16: 人源情报 | F16: 法律 | G16: 说服 | H16: 药学 | I16: 搜寻
A17: 人文学科学位 | B17: 人类学或考古学 | C17: 艺术（任选） | D17: 外语（任选） | E17: 历史 | F17: 说服 | G17: 另三项个人特长
A18: 军官 | B18: 行政 | C18: 射击 | D18: 历史 | E18: 军事科学（任选） | F18: 导航 | G18: 说服 | H18: 徒手搏斗 | J18: 1 | K18: 炮术 | L18: 重型机械 | M18: 重型武器 | N18: 人源情报 | O18: 特种载具（任选） | P18: 信号情报
A19: 工商管理硕士 | B19: 会计学 | C19: 行政 | D19: 人源情报 | E19: 法律 | F19: 说服 | G19: 另三项个人特长
A20: 护士，辅助医护人员或医学本科学位 | B20: 警觉 | C20: 急救 | D20: 医学 | E20: 说服 | F20: 药学 | G20: 精神治疗 | H20: 科学（生物学） | I20: 搜寻
A21: 神秘事件调查员或阴谋论家 | B21: 人类学 | C21: 考古学 | D21: 计算机科学 | E21: 犯罪学 | F21: 历史 | G21: 神秘学 | H21: 说服 | I21: 搜寻
A22: 野外探险家 | B22: 警觉 | C22: 运动 | D22: 射击 | E22: 导航 | F22: 骑术 | G22: 搜寻 | H22: 潜藏 | I22: 生存
A23: 摄影师 | B23: 警觉 | C23: 艺术（摄影） | D23: 计算机科学 | E23: 说服 | F23: 搜寻 | G23: 潜藏 | H23: 另两项个人特长
A24: 飞行员或水手 | B24: 警觉 | C24: 工艺（机械） | D24: 急救 | E24: 外语（任选） | F24: 导航 | G24: 特种载具（任选） | H24: 生存 | I24: 游泳
A25: 警官 | B25: 警觉 | C25: 犯罪学 | D25: 机动车驾驶 | E25: 射击 | F25: 人源情报 | G25: 法律 | H25: 近战武器 | I25: 徒手搏斗
A26: 理科研究生 | B26: 行政 | C26: 计算机科学 | D26: 工艺（任选） | E26: 外语（任选） | F26: 科学（任选） | G26: 科学（任选） | H26: 科学（任选） | J26: 1 | K26: 会计学 | L26: 法证学 | M26: 法律 | N26: 药学
A27: 社会工作者或刑事司法 | B27: 行政 | C27: 犯罪学 | D27: 法证学 | E27: 外语（任选） | F27: 人源情报 | G27: 法律 | H27: 说服 | I27: 搜寻
A28: 陆军或海军陆战队 | B28: 警觉 | C28: 炮术 | D28: 运动 | E28: 机动车驾驶 | F28: 射击 | G28: 重型武器 | H28: 军事科学（陆军） | I28: 徒手搏斗
A29: 翻译 | B29: 人类学 | C29: 外语（任选） | D29: 外语（任选） | E29: 外语（任选） | F29: 历史 | G29: 人源情报 | H29: 说服 | I29: 另一项个人特长
A30: 城市探险家 | B30: 警觉 | C30: 运动 | D30: 工艺（任选） | E30: 法律 | F30: 导航 | G30: 说服 | H30: 搜寻 | I30: 潜藏

Sheet 子技能
A1: 艺术 | C1: 工艺 | E1: 军事科学 | G1: 特种载具 | I1: 科学
A2: 演艺 | C2: 电工 | E2: 陆军 | G2: 飞机 | I2: 天文学
A3: 创意写作 | C3: 电子 | E3: 空军 | G3: 无人机 | I3: 生物学
A4: 造假 | C4: 机械 | E4: 海军 | G4: 直升机 | I4: 植物学
A5: 绘画 | C5: 锁匠 | G5: 小船 | I5: 化学
A6: 舞蹈 | C6: 枪匠 | G6: 大船 | I6: 工程学
A7: 唱歌 | C7: 木工 | G7: 航天飞机 | I7: 基因科学
A8: 雕塑 | C8: 建筑学 | G8: 宇航服 | I8: 地质学
A9: 小提琴 | C9: 微电子 | G9: 飞行器 | I9: 数学
A10: 摄像 | C10: 管道工 | I10: 气象学
A11: 摄影 | C11: 金属加工 | I11: 物理学
C12: 训犬 | I12: 行星科学
C13: 工程 | I13: 动物学
C14: 电子学 | I14: 微生物学
I15: 环境学
I16: 生态学
I17: 免疫学
I18: 海洋生物学
I19: 兽医学
I20: 逻辑学
I21: 地理学
I22: 核物理学
I23: 天体物理学
I24: 弹道学
I25: 系统论
I26: 量子理论
I27: 航空工程

Sheet 附表
A1: 计入暂降后的数值 | D1: 重要关系
A2: STR | B2: =IF(ISBLANK(人物卡!AN3),人物卡!AH3,人物卡!AN3) -> 0 | D2: =人物卡!ED24
A3: CON | B3: =IF(ISBLANK(人物卡!AN4),人物卡!AH4,人物卡!AN4) -> 0 | D3: =人物卡!ED27
A4: DEX | B4: =IF(ISBLANK(人物卡!AN5),人物卡!AH5,人物卡!AN5) -> 0 | D4: =人物卡!ED30
A5: INT | B5: =IF(ISBLANK(人物卡!AN6),人物卡!AH6,人物卡!AN6) -> 0 | D5: =人物卡!ED33
A6: POW | B6: =IF(ISBLANK(人物卡!AN7),人物卡!AH7,人物卡!AN7) -> 0 | D6: =人物卡!ED36
A7: CHA | B7: =IF(ISBLANK(人物卡!AN8),人物卡!AH8,人物卡!AN8) -> 0 | D7: =人物卡!ED39
A11: 职业选择 | C11: 实际模板 | D11: =IF(G11,INDEX(H63:H82,MATCH(IF(A63=1,B62,人物卡!H47),G63:G82,0)),A15) -> （创建新职业） | F11: 初步有子模板 | G11: =B62<>0 -> FALSE | H11: 最终有子模板 | I11: =AND(G11,A63>1) -> FALSE
A12: 总模板号 | B12: =MATCH(人物卡!$H$46,职业列表!A2:A505,0) -> 1 | C12: 实际模板号 | D12: =MATCH(D11,职业列表!A2:A505,0) -> 1 | H12: 正确模板 | I12: =IFERROR(AND(NOT(ISNA(D11)),OR(NOT(I11),COUNTIF(B62:B65,人物卡!H47)>0)),FALSE) -> TRUE
A15: {=INDEX(职业列表!A2:A505,$B$12)} -> （创建新职业） | B15: {=INDEX(职业列表!B2:B505,$B$12)} -> 0 | C15: {=INDEX(职业列表!C2:C505,$B$12)} -> ≤4 | D15: {=INDEX(职业列表!D2:D505,$B$12)} -> 任选10个本职技能，分配350 | E15: {=INDEX(职业列表!E2:E505,$B$12)} -> 技能点，额外加在基础值上， | F15: {=INDEX(职业列表!F2:F505,$B$12)} -> 最高至60%。重要关系自4个开 | G15: {=INDEX(职业列表!G2:G505,$B$12)} -> 始每少一个（最少1个），增 | H15: {=INDEX(职业列表!H2:H505,$B$12)} -> 加50本职技能点。 | ... AX15: {=INDEX(职业列表!AX2:AX505,$B$12)} -> 0
A16: {=INDEX(职业列表!A2:A505,$D$12)} -> （创建新职业） | B16: {=INDEX(职业列表!B2:B505,$D$12)} -> 0 | C16: {=INDEX(职业列表!C2:C505,$D$12)} -> ≤4 | D16: {=INDEX(职业列表!D2:D505,$D$12)} -> 任选10个本职技能，分配350 | E16: {=INDEX(职业列表!E2:E505,$D$12)} -> 技能点，额外加在基础值上， | F16: {=INDEX(职业列表!F2:F505,$D$12)} -> 最高至60%。重要关系自4个开 | G16: {=INDEX(职业列表!G2:G505,$D$12)} -> 始每少一个（最少1个），增 | H16: {=INDEX(职业列表!H2:H505,$D$12)} -> 加50本职技能点。 | ... AX16: {=INDEX(职业列表!AX2:AX505,$D$12)} -> 0
A19: 职业技能列 | C19: 自由： | D19: =T16 -> 0 | F19: 推荐： | I19: 特殊 | K19: =INDEX(K20:K26,MATCH(1,I20:I26,0)) -> （自定义职业请在掌局者同意后商议定制）
A20: {=TRANSPOSE(D16:S16)} -> 任选10个本职技能，分配350 | D20: {=TRANSPOSE(U16:AE16)} -> 0 | F20: {=TRANSPOSE(AJ15:AM15)} -> 0 | I20: =COUNTIF($A$16,J20&"*") -> 0 | J20: 【额外】 | K20: （额外职业并非典型的DG新人职业，一队中不应过多，请与掌局者商议后选择）
A21: 技能点，额外加在基础值上， | D21: 0 | F21: 0 | I21: =COUNTIF($A$16,J21&"*") -> 1 | J21: （创建新职业） | K21: （自定义职业请在掌局者同意后商议定制）
A22: 最高至60%。重要关系自4个开 | D22: 0 | F22: 0
A23: 始每少一个（最少1个），增 | D23: 0 | F23: 0
A24: 加50本职技能点。 | D24: 0
A25: 0 | D25: 0
A26: 0 | D26: 0 | I26: =COUNTIF(A23,J26&"*") -> 1 | K26: =""
A27: 0 | D27: 0 | K27: =""
A28: 0 | D28: 0
A29: 0 | D29: 0
A30: 0 | D30: 0
A31: 0
A32: 0
A33: 0
A34: 0
A35: 0
A36: 自定义职业描述： | G36: 自选额外技能描述
A37: 任选10个本职技能，分配350 | G37: 选择8个技能（除了非自
A38: 技能点，额外加在基础值上， | G38: 然知识），为每一个加上
A39: 最高至60%。重要关系自4个开 | G39: 20点。不能超过80%。可
A40: 始每少一个（最少1个），增 | G40: 重复选择。
A41: 加50本职技能点。
A45: 额外技能包选择 | C45: =MATCH(人物卡!$BW$46,额外技能包!A2:A30,0) -> 1
A46: {=INDEX(额外技能包!A$2:A$30,$C$45)} -> （自选） | B46: {=INDEX(额外技能包!B$2:B$30,$C$45)} -> 选择8个技能（除了非自 | C46: {=INDEX(额外技能包!C$2:C$30,$C$45)} -> 然知识），为每一个加上 | D46: {=INDEX(额外技能包!D$2:D$30,$C$45)} -> 20点。不能超过80%。可 | E46: {=INDEX(额外技能包!E$2:E$30,$C$45)} -> 重复选择。 | F46: {=INDEX(额外技能包!F$2:F$30,$C$45)} -> 0 | G46: {=INDEX(额外技能包!G$2:G$30,$C$45)} -> 0 | H46: {=INDEX(额外技能包!H$2:H$30,$C$45)} -> 0 | ... Y46: {=INDEX(额外技能包!Y$2:Y$30,$C$45)} -> 0
A48: 额外技能包列 | D48: =J46 -> 0
A49: {=TRANSPOSE(B46:I46)} -> 选择8个技能（除了非自 | D49: {=TRANSPOSE(K46:U46)} -> 0
A50: 然知识），为每一个加上 | D50: 0
A51: 20点。不能超过80%。可 | D51: 0
...

Sheet 更新记录
A1: 绿色三角洲人物卡｜更新记录 | B1: 绿色三角洲人物卡｜更新记录
A3: 原版作者 | B3: DKWings
A4: 联系方式 | B4: QQ：280848250 Email：dkwings@gmail.com
A5: 后续改版 | B5: v0.4之后：Lindrich King QQ：2113155803
A6: 项目仓库 | B6: https://github.com/Shylosia/DeltaGreen
A7: 当前版本 | B7: v1.10
A8: 返回人物卡 | B8: 绿箱生成器
A10: 版本 | B10: 更新内容
A11: v1.10 | B11: 主卡失败勾选、批量成长与职业装备（2026-09-22）
B12: 恢复主卡失败技能下拉勾选；幕间页自动列出已勾选技能和当前值，分别填写1D4即可生成整批成长记录，不再逐项录入失败事件。
B13: 复制生成记录的前九列，粘贴为值到归档区后统一计入主卡；同一模组同一技能只计一次。归档保留变更前后值，清空勾选不会删除已归档成长。
B14: 模组结算后可接续一至两次幕间：选择事项、目标、结果及骰点，自动生成技能、属性、理智和关系变化；归档后联动主卡。
B15: 将装备权衡中的五组装备加入物品栏下拉，默认随职业及子模板带入；保留可选、二选一和车载装备说明，亦可单独选择装备包。
B16: 保留当前角色的职业、属性、武器及其他已填资料；保留主卡和双页A4的行高、列宽，更新说明按新到旧排列。
B17: 成长骰点使用实际掷骰结果。归档后手动清空失败标记与骰点；下一模组更换编号并清空两组幕间输入，归档记录继续保留。
A19: v1.9 | B19: 幕间结算、成长记录与页面整理（2026-09-22）
B20: 新增“幕间与结算”工作表，提供九类幕间事项下拉；记录游戏内日期、事件、变更前值、实际增减和关系代价，确认后按属性与技能上限累计到人物卡。
B21: 初始属性移至“幕间与结算”填写，主卡显示计入背景与后续变化后的累计值。
B22: 技能失败结算手动录入结算前值和固定1D4结果，同一模组的同一技能只结算一次；保留成长前后值，失败标记和成长历史联动主卡。
B23: 重要关系名称使用下拉选择，移除“个人／群体”占位选项。
B24: 隐藏职业列表、额外技能包、子技能、附表和职业选项，规则数据继续隐藏；删除空展示页。
B25: A4打印版只保留首页深绿色主标题，背面不再重复标题；保留两页A4、页脚、行高和列宽。
A27: v1.8 | B27: 固定工艺技能匹配修正（2026-09-22）
B28: 固定工艺按主卡已有的专攻名称匹配，调整到其他工艺行后仍计入职业值；原位置优先，同名只计一次，无匹配时仍待填，不改写玩家输入。
B29: 核对计算机科学家或工程师的电工30%、机械30%、微电子40%及相关模板；工艺下拉补入“电子学”，四个工艺名称格均可选择，保留“电子”和“微电子”为独立选项。
B30: 保留人物卡版式、职业任选规则、技能包逐项替换与额外技能联动；同步角色版、公开空白母版和更新记录为v1.8。
A32: v1.7 | B32: 技能包单项替换与分配统计（2026-09-22）
B33: 技能包的模板固定项也可在右栏替换；例如将运动员的一项换成其他技能，清空手选后恢复该模板默认项。
B34: 保留八项各+20、同一技能可重复分配及创建上限80%；非自然知识不能通过技能包提升，原有任选与专攻范围保持不变。
B35: 将分配统计移到第八项技能之后，八项连续排列，便于逐项核对。
B36: 保留原人物卡行高、列宽及其余联动；同步角色版、公开空白母版和更新记录为v1.7。
A38: v1.6 | B38: 导航、模组备忘录与打印占位（2026-09-22）
B39: 规则速查由68个分类链接精简为12个主题导航；冻结前8行替代原25行，保留538条正文，并提示筛选后先清除筛选再跳转。
B40: 清理规则速查、精神疾病与参考选项中的出处栏目及备注末尾出处行，参考内容仍完整留在工作表中。
B41: 新增20条空白场次的模组经历备忘录，可记录日期、行动、掌局者、同行特工、结果、角色变化与下次备忘。
B42: 主卡底部和备忘录加入绿箱生成器、规则速查和版本记录入口；绿箱地址为 https://greenbox.thebackstop.app/。
B43: v0.4之后版本改编维护：Lindrich King，QQ：2113155803；保留原版作者DKWings及既有历史记录。
B44: 项目入口：https://github.com/Shylosia/DeltaGreen。仓库发布空白母版；已填写角色版保留在本地。
B45: 打印页135处数值或基础等级标签在空白时以0占位；姓名、专攻名称、背景叙述继续留白。未填力量时伤害加成显示0。
B46: 同步版本v1.6。保留原人物卡与A4表的行高列宽、原有联动及已填写角色内容；新增底部导航不移动原外框。
...

Sheet 职业选项
S1: 当前模板原始行 | T1: =IFERROR(MATCH(附表!$D$11,职业列表!$A$1:$A$106,0),2) -> 2
A2: =IF(INDEX($C$1:$C$1611,$T$2+0)="","",INDEX($C$1:$C$1611,$T$2+0)) | B2: =IF(INDEX($D$1:$D$1611,$T$2+0)="","",INDEX($D$1:$D$1611,$T$2+0)) -> fixed | C2: =IF(INDEX($E$1:$E$1611,$T$2+0)="","",INDEX($E$1:$E$1611,$T$2+0)) | D2: =INDEX($F$1:$F$1611,$T$2+0) -> 0 | E2: =IF(INDEX($G$1:$G$1611,$T$2+0)="","",INDEX($G$1:$G$1611,$T$2+0)) | F2: =IF(INDEX($H$1:$H$1611,$T$2+0)="","",INDEX($H$1:$H$1611,$T$2+0)) | G2: =IF(INDEX($I$1:$I$1611,$T$2+0)="","",INDEX($I$1:$I$1611,$T$2+0)) | H2: =IF(INDEX($J$1:$J$1611,$T$2+0)="","",INDEX($J$1:$J$1611,$T$2+0)) | I2: =IF(INDEX($K$1:$K$1611,$T$2+0)="","",INDEX($K$1:$K$1611,$T$2+0)) | J2: =IF(P2="","",IF(COUNTBLANK(INDIRECT("'人物卡'!"&P2))>0,"",TRIM(INDIRECT("'人物卡'!"&P2)))) | K2: =IF(P2="",G2,IF(E2="skill",IF(AND(J2<>"",ISNUMBER(FIND("|"&J2&"|","|"&H2&"|"))),J2,""),IF(E2="any",IF(AND(J2<>"",J2<>"0",ISERROR(FIND("任选",J2)),ISERROR(FIND("（",J2)),ISERROR(FIND("）",J2))),C2&"（"&J2&"）",""),IF(E2="limited",IF(AND(J2<>"",ISNUMBER(FIND("|"&J2&"|","|"&H2&"|"))),C2&"（"&J2&"）",""),IF(J2=F2,G2,""))))) | L2: =AND(A2<>"",TRUE) -> FALSE | M2: =AND(L2,K2<>"",COUNTIFS($K$2:$K$17,K2,$L$2:$L$17,TRUE)>1) -> FALSE | N2: =IF(A2="","",IF(NOT(L2),"未勾选",IF(E2="unknown","原文名称异常",IF(K2="","请在主卡填写／修正细项",IF(M2,"重复技能",IF(O2>0,"已计入","超选：暂不计入")))))) | O2: =IF(AND(附表!$I$12,L2,K2<>"",NOT(M2),TRUE),D2,0) -> 0 | P2: =IF(AND(C2="工艺",E2="",F2<>""),IF(AND(I2="工艺1",TRIM(人物卡!J25)=F2),"J25",IF(AND(I2="工艺2",TRIM(人物卡!J26)=F2),"J26",IF(AND(I2="工艺3",TRIM(人物卡!J27)=F2),"J27",IF(AND(I2="工艺4",TRIM(人物卡!J28)=F2),"J28",IF(TRIM(人物卡!J25)=F2,"J25",IF(TRIM(人物卡!J26)=F2,"J26",IF(TRIM(人物卡!J27)=F2,"J27",IF(TRIM(人物卡!J28)=F2,"J28",IF(INDEX($L$1:$L$1611,$T$2+0)="","",INDEX($L$1:$L$1611,$T$2+0)))))))))),IF(INDEX($L$1:$L$1611,$T$2+0)="","",INDEX($L$1:$L$1611,$T$2+0))) | Q2: =IF(INDEX($M$1:$M$1611,$T$2+0)="","",INDEX($M$1:$M$1611,$T$2+0)) -> D2 | R2: =INDEX($N$1:$N$1611,$T$2+0) -> FALSE | T2: =IFERROR(MATCH(T1,$A$100:$A$1611,0)+99,100) -> 100 | Z2: =AND(附表!$I$12,A18<>"",人物卡!P49="☑") -> FALSE | AA2: ☐
A3: =IF(INDEX($C$1:$C$1611,$T$2+1)="","",INDEX($C$1:$C$1611,$T$2+1)) | B3: =IF(INDEX($D$1:$D$1611,$T$2+1)="","",INDEX($D$1:$D$1611,$T$2+1)) -> fixed | C3: =IF(INDEX($E$1:$E$1611,$T$2+1)="","",INDEX($E$1:$E$1611,$T$2+1)) | D3: =INDEX($F$1:$F$1611,$T$2+1) -> 0 | E3: =IF(INDEX($G$1:$G$1611,$T$2+1)="","",INDEX($G$1:$G$1611,$T$2+1)) | F3: =IF(INDEX($H$1:$H$1611,$T$2+1)="","",INDEX($H$1:$H$1611,$T$2+1)) | G3: =IF(INDEX($I$1:$I$1611,$T$2+1)="","",INDEX($I$1:$I$1611,$T$2+1)) | H3: =IF(INDEX($J$1:$J$1611,$T$2+1)="","",INDEX($J$1:$J$1611,$T$2+1)) | I3: =IF(INDEX($K$1:$K$1611,$T$2+1)="","",INDEX($K$1:$K$1611,$T$2+1)) | J3: =IF(P3="","",IF(COUNTBLANK(INDIRECT("'人物卡'!"&P3))>0,"",TRIM(INDIRECT("'人物卡'!"&P3)))) | K3: =IF(P3="",G3,IF(E3="skill",IF(AND(J3<>"",ISNUMBER(FIND("|"&J3&"|","|"&H3&"|"))),J3,""),IF(E3="any",IF(AND(J3<>"",J3<>"0",ISERROR(FIND("任选",J3)),ISERROR(FIND("（",J3)),ISERROR(FIND("）",J3))),C3&"（"&J3&"）",""),IF(E3="limited",IF(AND(J3<>"",ISNUMBER(FIND("|"&J3&"|","|"&H3&"|"))),C3&"（"&J3&"）",""),IF(J3=F3,G3,""))))) | L3: =AND(A3<>"",TRUE) -> FALSE | M3: =AND(L3,K3<>"",COUNTIFS($K$2:$K$17,K3,$L$2:$L$17,TRUE)>1) -> FALSE | N3: =IF(A3="","",IF(NOT(L3),"未勾选",IF(E3="unknown","原文名称异常",IF(K3="","请在主卡填写／修正细项",IF(M3,"重复技能",IF(O3>0,"已计入","超选：暂不计入")))))) | O3: =IF(AND(附表!$I$12,L3,K3<>"",NOT(M3),TRUE),D3,0) -> 0 | P3: =IF(AND(C3="工艺",E3="",F3<>""),IF(AND(I3="工艺1",TRIM(人物卡!J25)=F3),"J25",IF(AND(I3="工艺2",TRIM(人物卡!J26)=F3),"J26",IF(AND(I3="工艺3",TRIM(人物卡!J27)=F3),"J27",IF(AND(I3="工艺4",TRIM(人物卡!J28)=F3),"J28",IF(TRIM(人物卡!J25)=F3,"J25",IF(TRIM(人物卡!J26)=F3,"J26",IF(TRIM(人物卡!J27)=F3,"J27",IF(TRIM(人物卡!J28)=F3,"J28",IF(INDEX($L$1:$L$1611,$T$2+1)="","",INDEX($L$1:$L$1611,$T$2+1)))))))))),IF(INDEX($L$1:$L$1611,$T$2+1)="","",INDEX($L$1:$L$1611,$T$2+1))) | Q3: =IF(INDEX($M$1:$M$1611,$T$2+1)="","",INDEX($M$1:$M$1611,$T$2+1)) -> E2 | R3: =INDEX($N$1:$N$1611,$T$2+1) -> FALSE | S3: 任选数量 | T3: =IFERROR(INDEX(职业列表!$T$1:$T$106,T1),0) -> 0 | Z3: =AND(附表!$I$12,A19<>"",人物卡!P50="☑") -> FALSE | AA3: ☑
A4: =IF(INDEX($C$1:$C$1611,$T$2+2)="","",INDEX($C$1:$C$1611,$T$2+2)) | B4: =IF(INDEX($D$1:$D$1611,$T$2+2)="","",INDEX($D$1:$D$1611,$T$2+2)) -> fixed | C4: =IF(INDEX($E$1:$E$1611,$T$2+2)="","",INDEX($E$1:$E$1611,$T$2+2)) | D4: =INDEX($F$1:$F$1611,$T$2+2) -> 0 | E4: =IF(INDEX($G$1:$G$1611,$T$2+2)="","",INDEX($G$1:$G$1611,$T$2+2)) | F4: =IF(INDEX($H$1:$H$1611,$T$2+2)="","",INDEX($H$1:$H$1611,$T$2+2)) | G4: =IF(INDEX($I$1:$I$1611,$T$2+2)="","",INDEX($I$1:$I$1611,$T$2+2)) | H4: =IF(INDEX($J$1:$J$1611,$T$2+2)="","",INDEX($J$1:$J$1611,$T$2+2)) | I4: =IF(INDEX($K$1:$K$1611,$T$2+2)="","",INDEX($K$1:$K$1611,$T$2+2)) | J4: =IF(P4="","",IF(COUNTBLANK(INDIRECT("'人物卡'!"&P4))>0,"",TRIM(INDIRECT("'人物卡'!"&P4)))) | K4: =IF(P4="",G4,IF(E4="skill",IF(AND(J4<>"",ISNUMBER(FIND("|"&J4&"|","|"&H4&"|"))),J4,""),IF(E4="any",IF(AND(J4<>"",J4<>"0",ISERROR(FIND("任选",J4)),ISERROR(FIND("（",J4)),ISERROR(FIND("）",J4))),C4&"（"&J4&"）",""),IF(E4="limited",IF(AND(J4<>"",ISNUMBER(FIND("|"&J4&"|","|"&H4&"|"))),C4&"（"&J4&"）",""),IF(J4=F4,G4,""))))) | L4: =AND(A4<>"",TRUE) -> FALSE | M4: =AND(L4,K4<>"",COUNTIFS($K$2:$K$17,K4,$L$2:$L$17,TRUE)>1) -> FALSE | N4: =IF(A4="","",IF(NOT(L4),"未勾选",IF(E4="unknown","原文名称异常",IF(K4="","请在主卡填写／修正细项",IF(M4,"重复技能",IF(O4>0,"已计入","超选：暂不计入")))))) | O4: =IF(AND(附表!$I$12,L4,K4<>"",NOT(M4),TRUE),D4,0) -> 0 | P4: =IF(AND(C4="工艺",E4="",F4<>""),IF(AND(I4="工艺1",TRIM(人物卡!J25)=F4),"J25",IF(AND(I4="工艺2",TRIM(人物卡!J26)=F4),"J26",IF(AND(I4="工艺3",TRIM(人物卡!J27)=F4),"J27",IF(AND(I4="工艺4",TRIM(人物卡!J28)=F4),"J28",IF(TRIM(人物卡!J25)=F4,"J25",IF(TRIM(人物卡!J26)=F4,"J26",IF(TRIM(人物卡!J27)=F4,"J27",IF(TRIM(人物卡!J28)=F4,"J28",IF(INDEX($L$1:$L$1611,$T$2+2)="","",INDEX($L$1:$L$1611,$T$2+2)))))))))),IF(INDEX($L$1:$L$1611,$T$2+2)="","",INDEX($L$1:$L$1611,$T$2+2))) | Q4: =IF(INDEX($M$1:$M$1611,$T$2+2)="","",INDEX($M$1:$M$1611,$T$2+2)) -> F2 | R4: =INDEX($N$1:$N$1611,$T$2+2) -> FALSE | S4: 已勾数量 | T4: =COUNTIFS($L$18:$L$28,TRUE,$A$18:$A$28,"<>") -> 0 | Z4: =AND(附表!$I$12,A20<>"",人物卡!P51="☑") -> FALSE
A5: =IF(INDEX($C$1:$C$1611,$T$2+3)="","",INDEX($C$1:$C$1611,$T$2+3)) | B5: =IF(INDEX($D$1:$D$1611,$T$2+3)="","",INDEX($D$1:$D$1611,$T$2+3)) -> fixed | C5: =IF(INDEX($E$1:$E$1611,$T$2+3)="","",INDEX($E$1:$E$1611,$T$2+3)) | D5: =INDEX($F$1:$F$1611,$T$2+3) -> 0 | E5: =IF(INDEX($G$1:$G$1611,$T$2+3)="","",INDEX($G$1:$G$1611,$T$2+3)) | F5: =IF(INDEX($H$1:$H$1611,$T$2+3)="","",INDEX($H$1:$H$1611,$T$2+3)) | G5: =IF(INDEX($I$1:$I$1611,$T$2+3)="","",INDEX($I$1:$I$1611,$T$2+3)) | H5: =IF(INDEX($J$1:$J$1611,$T$2+3)="","",INDEX($J$1:$J$1611,$T$2+3)) | I5: =IF(INDEX($K$1:$K$1611,$T$2+3)="","",INDEX($K$1:$K$1611,$T$2+3)) | J5: =IF(P5="","",IF(COUNTBLANK(INDIRECT("'人物卡'!"&P5))>0,"",TRIM(INDIRECT("'人物卡'!"&P5)))) | K5: =IF(P5="",G5,IF(E5="skill",IF(AND(J5<>"",ISNUMBER(FIND("|"&J5&"|","|"&H5&"|"))),J5,""),IF(E5="any",IF(AND(J5<>"",J5<>"0",ISERROR(FIND("任选",J5)),ISERROR(FIND("（",J5)),ISERROR(FIND("）",J5))),C5&"（"&J5&"）",""),IF(E5="limited",IF(AND(J5<>"",ISNUMBER(FIND("|"&J5&"|","|"&H5&"|"))),C5&"（"&J5&"）",""),IF(J5=F5,G5,""))))) | L5: =AND(A5<>"",TRUE) -> FALSE | M5: =AND(L5,K5<>"",COUNTIFS($K$2:$K$17,K5,$L$2:$L$17,TRUE)>1) -> FALSE | N5: =IF(A5="","",IF(NOT(L5),"未勾选",IF(E5="unknown","原文名称异常",IF(K5="","请在主卡填写／修正细项",IF(M5,"重复技能",IF(O5>0,"已计入","超选：暂不计入")))))) | O5: =IF(AND(附表!$I$12,L5,K5<>"",NOT(M5),TRUE),D5,0) -> 0 | P5: =IF(AND(C5="工艺",E5="",F5<>""),IF(AND(I5="工艺1",TRIM(人物卡!J25)=F5),"J25",IF(AND(I5="工艺2",TRIM(人物卡!J26)=F5),"J26",IF(AND(I5="工艺3",TRIM(人物卡!J27)=F5),"J27",IF(AND(I5="工艺4",TRIM(人物卡!J28)=F5),"J28",IF(TRIM(人物卡!J25)=F5,"J25",IF(TRIM(人物卡!J26)=F5,"J26",IF(TRIM(人物卡!J27)=F5,"J27",IF(TRIM(人物卡!J28)=F5,"J28",IF(INDEX($L$1:$L$1611,$T$2+3)="","",INDEX($L$1:$L$1611,$T$2+3)))))))))),IF(INDEX($L$1:$L$1611,$T$2+3)="","",INDEX($L$1:$L$1611,$T$2+3))) | Q5: =IF(INDEX($M$1:$M$1611,$T$2+3)="","",INDEX($M$1:$M$1611,$T$2+3)) -> G2 | R5: =INDEX($N$1:$N$1611,$T$2+3) -> FALSE | S5: 有效数量 | T5: =COUNTIF($O$18:$O$28,">0") -> 0 | Z5: =AND(附表!$I$12,A21<>"",人物卡!P52="☑") -> FALSE
