Workbook
Name EditableMiddle: 人物卡!$BX$3:$CX$11,人物卡!$BN$14,人物卡!$BN$17,人物卡!$BI$27
Name 主卡技能选项: OFFSET(规则数据!$Z$20,0,0,MAX(1,规则数据!$Z$19),1)
Name 额外第1项: OFFSET(规则数据!$AA$20,0,0,MAX(1,规则数据!$AA$19),1)
Name 额外第2项: OFFSET(规则数据!$AC$20,0,0,MAX(1,规则数据!$AC$19),1)
Name 额外第3项: OFFSET(规则数据!$AE$20,0,0,MAX(1,规则数据!$AE$19),1)
Name 额外第4项: OFFSET(规则数据!$AG$20,0,0,MAX(1,规则数据!$AG$19),1)
Name 额外第5项: OFFSET(规则数据!$AI$20,0,0,MAX(1,规则数据!$AI$19),1)
Name 额外第6项: OFFSET(规则数据!$AK$20,0,0,MAX(1,规则数据!$AK$19),1)
Name 额外第7项: OFFSET(规则数据!$AM$20,0,0,MAX(1,规则数据!$AM$19),1)
Name 额外第8项: OFFSET(规则数据!$AO$20,0,0,MAX(1,规则数据!$AO$19),1)
Name 非自然心理疾病: '精神疾病'!$B$9:$B$16
Name 武器下拉列表: 规则数据!$A$500:$A$553
Name 护甲下拉列表: 规则数据!$A$560:$A$565
Name 特训对应项: 规则数据!$A$580:$A$644
Name 任选勾选值: '职业选项'!$AA$2:$AA$3
Name 空白选项: '职业选项'!$AA$4
Name 特训范例: '参考选项'!$B$20:$B$33
Name 模组编号: '幕间计算'!$J$2:$J$21
Name 幕间事项: '幕间计算'!$L$2:$L$24
Name 变更目标: '幕间计算'!$X$2:INDEX('幕间计算'!$X$2:$X$79,MAX(1,COUNTIF('幕间计算'!$X$2:$X$79,"?*")))
Name 关系编号: '幕间计算'!$N$2:$N$8
Name 关系称谓: '幕间计算'!$M$2:$M$13
Name 成长候选00: '幕间计算'!$V$2:INDEX('幕间计算'!$V$2:$V$201,MAX(1,COUNTIF('幕间计算'!$V$2:$V$201,"?*")))
Name 成长候选01: '幕间计算'!$AA$2:INDEX('幕间计算'!$AA$2:$AA$201,MAX(1,COUNTIF('幕间计算'!$AA$2:$AA$201,"?*")))
Name 成长候选02: '幕间计算'!$AB$2:INDEX('幕间计算'!$AB$2:$AB$201,MAX(1,COUNTIF('幕间计算'!$AB$2:$AB$201,"?*")))
Name 成长候选03: '幕间计算'!$AC$2:INDEX('幕间计算'!$AC$2:$AC$201,MAX(1,COUNTIF('幕间计算'!$AC$2:$AC$201,"?*")))
Name 成长候选04: '幕间计算'!$AD$2:INDEX('幕间计算'!$AD$2:$AD$201,MAX(1,COUNTIF('幕间计算'!$AD$2:$AD$201,"?*")))
Name 成长候选05: '幕间计算'!$AE$2:INDEX('幕间计算'!$AE$2:$AE$201,MAX(1,COUNTIF('幕间计算'!$AE$2:$AE$201,"?*")))
Name 成长候选06: '幕间计算'!$AF$2:INDEX('幕间计算'!$AF$2:$AF$201,MAX(1,COUNTIF('幕间计算'!$AF$2:$AF$201,"?*")))
Name 成长候选07: '幕间计算'!$AG$2:INDEX('幕间计算'!$AG$2:$AG$201,MAX(1,COUNTIF('幕间计算'!$AG$2:$AG$201,"?*")))
Name 成长候选08: '幕间计算'!$AH$2:INDEX('幕间计算'!$AH$2:$AH$201,MAX(1,COUNTIF('幕间计算'!$AH$2:$AH$201,"?*")))
Name 成长候选09: '幕间计算'!$AI$2:INDEX('幕间计算'!$AI$2:$AI$201,MAX(1,COUNTIF('幕间计算'!$AI$2:$AI$201,"?*")))
Name 成长候选10: '幕间计算'!$AJ$2:INDEX('幕间计算'!$AJ$2:$AJ$201,MAX(1,COUNTIF('幕间计算'!$AJ$2:$AJ$201,"?*")))
Name 成长候选11: '幕间计算'!$AK$2:INDEX('幕间计算'!$AK$2:$AK$201,MAX(1,COUNTIF('幕间计算'!$AK$2:$AK$201,"?*")))
Name 成长候选12: '幕间计算'!$AL$2:INDEX('幕间计算'!$AL$2:$AL$201,MAX(1,COUNTIF('幕间计算'!$AL$2:$AL$201,"?*")))
Name 成长候选13: '幕间计算'!$AM$2:INDEX('幕间计算'!$AM$2:$AM$201,MAX(1,COUNTIF('幕间计算'!$AM$2:$AM$201,"?*")))
Name 成长候选14: '幕间计算'!$AN$2:INDEX('幕间计算'!$AN$2:$AN$201,MAX(1,COUNTIF('幕间计算'!$AN$2:$AN$201,"?*")))
Name 成长候选15: '幕间计算'!$AO$2:INDEX('幕间计算'!$AO$2:$AO$201,MAX(1,COUNTIF('幕间计算'!$AO$2:$AO$201,"?*")))
Name 成长候选16: '幕间计算'!$AP$2:INDEX('幕间计算'!$AP$2:$AP$201,MAX(1,COUNTIF('幕间计算'!$AP$2:$AP$201,"?*")))
Name 成长候选17: '幕间计算'!$AQ$2:INDEX('幕间计算'!$AQ$2:$AQ$201,MAX(1,COUNTIF('幕间计算'!$AQ$2:$AQ$201,"?*")))
Name 成长候选18: '幕间计算'!$AR$2:INDEX('幕间计算'!$AR$2:$AR$201,MAX(1,COUNTIF('幕间计算'!$AR$2:$AR$201,"?*")))
Name 成长候选19: '幕间计算'!$AS$2:INDEX('幕间计算'!$AS$2:$AS$201,MAX(1,COUNTIF('幕间计算'!$AS$2:$AS$201,"?*")))
Name 成长候选20: '幕间计算'!$AT$2:INDEX('幕间计算'!$AT$2:$AT$201,MAX(1,COUNTIF('幕间计算'!$AT$2:$AT$201,"?*")))

Sheet 人物卡
CZ1: 物品
B2: ※ 特工信息 v1.9 | AB2: ※ 属性 | AH2: 数值 | AK2: ×5 | AN2: 暂降 | AQ2: 突出值解释 | BI2: 头像 | BX2: ※ 特训 | CP2: 对应技能或属性 | CZ2: ※ 物品
B3: 玩家 | AB3: 力量 | AE3: STR | AH3: =MAX(0,MIN(18,'幕间计算'!S2+SUMIF('幕间与结算'!$E$9:$E$208,"力量",'幕间与结算'!$K$9:$K$208))) -> 0 | AK3: =附表!B2*5 -> 0
B4: 特工 | AB4: 体质 | AE4: CON | AH4: =MAX(0,MIN(18,'幕间计算'!S3+SUMIF('幕间与结算'!$E$9:$E$208,"体质",'幕间与结算'!$K$9:$K$208))) -> 0 | AK4: =附表!B3*5 -> 0
B5: 性别 | N5: 年龄 | AB5: 敏捷 | AE5: DEX | AH5: =MAX(0,MIN(18,'幕间计算'!S4+SUMIF('幕间与结算'!$E$9:$E$208,"敏捷",'幕间与结算'!$K$9:$K$208))) -> 0 | AK5: =附表!B4*5 -> 0
B6: 国籍 | N6: 年代 | AB6: 智力 | AE6: INT | AH6: =MAX(0,MIN(18,'幕间计算'!S5+SUMIF('幕间与结算'!$E$9:$E$208,"智力",'幕间与结算'!$K$9:$K$208))) -> 0 | AK6: =附表!B5*5 -> 0
B7: 雇主 | AB7: 意志 | AE7: POW | AH7: =MAX(0,MIN(18,'幕间计算'!S6+SUMIF('幕间与结算'!$E$9:$E$208,"意志",'幕间与结算'!$K$9:$K$208))) -> 0 | AK7: =附表!B6*5 -> 0
B8: 职位 | AB8: 魅力 | AE8: CHA | AH8: =MAX(0,MIN(18,'幕间计算'!S7+SUMIF('幕间与结算'!$E$9:$E$208,"魅力",'幕间与结算'!$K$9:$K$208))) -> 0 | AK8: =附表!B7*5 -> 0 | EI8: 护甲
R9: 原始合计： | X9: =SUM('幕间与结算'!A5:F5) -> 0 | AB9: 总本职技能点： | AI9: =SUM(V14:V43,AY14:AY43)-SUMIF(V14:V43,">0",S14:S43)-SUMIF(AY14:AY43,">0",AV14:AV43) -> 0 | AL9: （初始重要关系数： | AT9: =IFERROR(MAX(0,IF(AND(AI9>=350,AI9<=500,MOD(AI9,50)=0),(550-AI9)/50,"错误")-IF(DF46="艰苦经历",1,0)),"错误")&"）" -> 错误） | AW9: 总额外技能点： | BD9: =规则数据!S3 -> 0
B10: 体力 | H10: =MAX(0,MIN(K10,'幕间计算'!BA409)) -> 0 | K10: =CEILING((附表!B2+附表!B3)/2,1) -> 0 | N10: 毅力 | V10: =MAX(0,MIN(Y10,'幕间计算'!BB409)) -> 0 | Y10: =附表!B6 -> 0 | AB10: 理智 | AH10: =MAX(0,MIN(AK10,'幕间计算'!BC409)) -> 0 | AK10: =99-AS39 -> 99 | AN10: 崩溃点 | AU10: =MAX(0,MIN(99,'幕间计算'!BD409)) -> 0 | AX10: 适应暴力 | BD10: =IF(DF46="极端暴力","已适应","☐☐☐") -> ☐☐☐
B11: Hit Points | N11: Willpower Points | AB11: Sanity | AN11: Breaking Point | AX11: 适应无力 | BD11: =IF(DF46="关押或入狱","已适应","☐☐☐") -> ☐☐☐
B13: ※ 技能 | P13: 总计 | S13: 初始 | V13: 职业 | Y13: 额外 | AB13: 成长 | AS13: 总计 | AV13: 初始 | AY13: 职业 | BB13: 额外 | BE13: 成长 | BI13: ※ 背景故事 | CZ13: ※ 武器 | DM13: 技能% | DQ13: 伤害/致死% | DW13: 穿甲 | DZ13: 基础射程 | ED13: 半径 | EI13: 近战伤害加成 | EQ13: =IF(AH3="",0,FLOOR((附表!B2-9)/4,1)) -> -3
B14: =IF(AND('幕间计算'!A2<>"",COUNTIFS('幕间计算'!$A$210:$A$409,IFERROR(VALUE('幕间与结算'!$B$3),0),'幕间计算'!$B$210:$B$409,1,'幕间与结算'!$E$9:$E$208,'幕间计算'!A2)>0,COUNTIFS('幕间计算'!$A$500:$A$739,IFERROR(VALUE('幕间与结算'!$B$3),0),'幕间计算'!$C$500:$C$739,1,'幕间与结算'!$C$215:$C$454,'幕间计算'!A2)=0),"√","☐") -> ☐ | D14: 会计学 | P14: =MAX(0,MIN(99,IF(V14="",N(S14),N(V14))+N(Y14)+N(AB14))) -> 10 | S14: 10 | V14: =IF(职业选项!V40>0,职业选项!V40,"") | Y14: =规则数据!H20 | AB14: ='幕间计算'!B2+IF(AND('幕间计算'!A2<>"",COUNTIF('幕间计算'!$A$2:A2,'幕间计算'!A2)=1),SUMIF('幕间与结算'!$E$9:$E$208,'幕间计算'!A2,'幕间与结算'!$K$9:$K$208)+SUMIF('幕间与结算'!$C$215:$C$454,'幕间计算'!A2,'幕间与结算'!$G$215:$G$454),0) -> 0 | AE14: =IF(AND('幕间计算'!A32<>"",COUNTIFS('幕间计算'!$A$210:$A$409,IFERROR(VALUE('幕间与结算'!$B$3),0),'幕间计算'!$B$210:$B$409,1,'幕间与结算'!$E$9:$E$208,'幕间计算'!A32)>0,COUNTIFS('幕间计算'!$A$500:$A$739,IFERROR(VALUE('幕间与结算'!$B$3),0),'幕间计算'!$C$500:$C$739,1,'幕间与结算'!$C$215:$C$454,'幕间计算'!A32)=0),"√","☐") -> ☐ | AG14: 法律 | AS14: =MAX(0,MIN(99,IF(AY14="",N(AV14),N(AY14))+N(BB14)+N(BE14))) -> 0 | AV14: 0 | AY14: =IF(职业选项!V41>0,职业选项!V41,"") | BB14: =规则数据!H50 | BE14: ='幕间计算'!B32+IF(AND('幕间计算'!A32<>"",COUNTIF('幕间计算'!$A$2:A32,'幕间计算'!A32)=1),SUMIF('幕间与结算'!$E$9:$E$208,'幕间计算'!A32,'幕间与结算'!$K$9:$K$208)+SUMIF('幕间与结算'!$C$215:$C$454,'幕间计算'!A32,'幕间与结算'!$G$215:$G$454),0) -> 0 | BI14: 外貌描述 | DM14: =IFERROR(INDIRECT(INDEX(规则数据!$C$500:$C$553,MATCH(CZ14,规则数据!$A$500:$A$553,0))),"") | DQ14: =IFERROR(IF(INDEX(规则数据!$D$500:$D$553,MATCH(CZ14,规则数据!$A$500:$A$553,0))="","",INDEX(规则数据!$D$500:$D$553,MATCH(CZ14,规则数据!$A$500:$A$553,0))),"") | DW14: =IFERROR(IF(INDEX(规则数据!$E$500:$E$553,MATCH(CZ14,规则数据!$A$500:$A$553,0))="","",INDEX(规则数据!$E$500:$E$553,MATCH(CZ14,规则数据!$A$500:$A$553,0))),"") | DZ14: =IFERROR(IF(INDEX(规则数据!$F$500:$F$553,MATCH(CZ14,规则数据!$A$500:$A$553,0))="","",INDEX(规则数据!$F$500:$F$553,MATCH(CZ14,规则数据!$A$500:$A$553,0))),"") | ED14: =IFERROR(IF(INDEX(规则数据!$G$500:$G$553,MATCH(CZ14,规则数据!$A$500:$A$553,0))="","",INDEX(规则数据!$G$500:$G$553,MATCH(CZ14,规则数据!$A$500:$A$553,0))),"") | EI14: Damage Bonus
B15: =IF(AND('幕间计算'!A3<>"",COUNTIFS('幕间计算'!$A$210:$A$409,IFERROR(VALUE('幕间与结算'!$B$3),0),'幕间计算'!$B$210:$B$409,1,'幕间与结算'!$E$9:$E$208,'幕间计算'!A3)>0,COUNTIFS('幕间计算'!$A$500:$A$739,IFERROR(VALUE('幕间与结算'!$B$3),0),'幕间计算'!$C$500:$C$739,1,'幕间与结算'!$C$215:$C$454,'幕间计算'!A3)=0),"√","☐") -> ☐ | D15: 警觉 | P15: =MAX(0,MIN(99,IF(V15="",N(S15),N(V15))+N(Y15)+N(AB15))) -> 20 | S15: 20 | V15: =IF(职业选项!V42>0,职业选项!V42,"") | Y15: =规则数据!H21 | AB15: ='幕间计算'!B3+IF(AND('幕间计算'!A3<>"",COUNTIF('幕间计算'!$A$2:A3,'幕间计算'!A3)=1),SUMIF('幕间与结算'!$E$9:$E$208,'幕间计算'!A3,'幕间与结算'!$K$9:$K$208)+SUMIF('幕间与结算'!$C$215:$C$454,'幕间计算'!A3,'幕间与结算'!$G$215:$G$454),0) -> 0 | AE15: =IF(AND('幕间计算'!A33<>"",COUNTIFS('幕间计算'!$A$210:$A$409,IFERROR(VALUE('幕间与结算'!$B$3),0),'幕间计算'!$B$210:$B$409,1,'幕间与结算'!$E$9:$E$208,'幕间计算'!A33)>0,COUNTIFS('幕间计算'!$A$500:$A$739,IFERROR(VALUE('幕间与结算'!$B$3),0),'幕间计算'!$C$500:$C$739,1,'幕间与结算'!$C$215:$C$454,'幕间计算'!A33)=0),"√","☐") -> ☐ | AG15: 医学 | AS15: =MAX(0,MIN(99,IF(AY15="",N(AV15),N(AY15))+N(BB15)+N(BE15))) -> 0 | AV15: 0 | AY15: =IF(职业选项!V43>0,职业选项!V43,"") | BB15: =规则数据!H51 | BE15: ='幕间计算'!B33+IF(AND('幕间计算'!A33<>"",COUNTIF('幕间计算'!$A$2:A33,'幕间计算'!A33)=1),SUMIF('幕间与结算'!$E$9:$E$208,'幕间计算'!A33,'幕间与结算'!$K$9:$K$208)+SUMIF('幕间与结算'!$C$215:$C$454,'幕间计算'!A33,'幕间与结算'!$G$215:$G$454),0) -> 0 | DM15: =IFERROR(INDIRECT(INDEX(规则数据!$C$500:$C$553,MATCH(CZ15,规则数据!$A$500:$A$553,0))),"") | DQ15: =IFERROR(IF(INDEX(规则数据!$D$500:$D$553,MATCH(CZ15,规则数据!$A$500:$A$553,0))="","",INDEX(规则数据!$D$500:$D$553,MATCH(CZ15,规则数据!$A$500:$A$553,0))),"") | DW15: =IFERROR(IF(INDEX(规则数据!$E$500:$E$553,MATCH(CZ15,规则数据!$A$500:$A$553,0))="","",INDEX(规则数据!$E$500:$E$553,MATCH(CZ15,规则数据!$A$500:$A$553,0))),"") | DZ15: =IFERROR(IF(INDEX(规则数据!$F$500:$F$553,MATCH(CZ15,规则数据!$A$500:$A$553,0))="","",INDEX(规则数据!$F$500:$F$553,MATCH(CZ15,规则数据!$A$500:$A$553,0))),"") | ED15: =IFERROR(IF(INDEX(规则数据!$G$500:$G$553,MATCH(CZ15,规则数据!$A$500:$A$553,0))="","",INDEX(规则数据!$G$500:$G$553,MATCH(CZ15,规则数据!$A$500:$A$553,0))),"")
B16: =IF(AND('幕间计算'!A4<>"",COUNTIFS('幕间计算'!$A$210:$A$409,IFERROR(VALUE('幕间与结算'!$B$3),0),'幕间计算'!$B$210:$B$409,1,'幕间与结算'!$E$9:$E$208,'幕间计算'!A4)>0,COUNTIFS('幕间计算'!$A$500:$A$739,IFERROR(VALUE('幕间与结算'!$B$3),0),'幕间计算'!$C$500:$C$739,1,'幕间与结算'!$C$215:$C$454,'幕间计算'!A4)=0),"√","☐") -> ☐ | D16: 人类学 | P16: =MAX(0,MIN(99,IF(V16="",N(S16),N(V16))+N(Y16)+N(AB16))) -> 0 | S16: 0 | V16: =IF(职业选项!V44>0,职业选项!V44,"") | Y16: =规则数据!H22 | AB16: ='幕间计算'!B4+IF(AND('幕间计算'!A4<>"",COUNTIF('幕间计算'!$A$2:A4,'幕间计算'!A4)=1),SUMIF('幕间与结算'!$E$9:$E$208,'幕间计算'!A4,'幕间与结算'!$K$9:$K$208)+SUMIF('幕间与结算'!$C$215:$C$454,'幕间计算'!A4,'幕间与结算'!$G$215:$G$454),0) -> 0 | AE16: =IF(AND('幕间计算'!A34<>"",COUNTIFS('幕间计算'!$A$210:$A$409,IFERROR(VALUE('幕间与结算'!$B$3),0),'幕间计算'!$B$210:$B$409,1,'幕间与结算'!$E$9:$E$208,'幕间计算'!A34)>0,COUNTIFS('幕间计算'!$A$500:$A$739,IFERROR(VALUE('幕间与结算'!$B$3),0),'幕间计算'!$C$500:$C$739,1,'幕间与结算'!$C$215:$C$454,'幕间计算'!A34)=0),"√","☐") -> ☐ | AG16: 近战武器 | AS16: =MAX(0,MIN(99,IF(AY16="",N(AV16),N(AY16))+N(BB16)+N(BE16))) -> 30 | AV16: 30 | AY16: =IF(职业选项!V45>0,职业选项!V45,"") | BB16: =规则数据!H52 | BE16: ='幕间计算'!B34+IF(AND('幕间计算'!A34<>"",COUNTIF('幕间计算'!$A$2:A34,'幕间计算'!A34)=1),SUMIF('幕间与结算'!$E$9:$E$208,'幕间计算'!A34,'幕间与结算'!$K$9:$K$208)+SUMIF('幕间与结算'!$C$215:$C$454,'幕间计算'!A34,'幕间与结算'!$G$215:$G$454),0) -> 0 | DM16: =IFERROR(INDIRECT(INDEX(规则数据!$C$500:$C$553,MATCH(CZ16,规则数据!$A$500:$A$553,0))),"") | DQ16: =IFERROR(IF(INDEX(规则数据!$D$500:$D$553,MATCH(CZ16,规则数据!$A$500:$A$553,0))="","",INDEX(规则数据!$D$500:$D$553,MATCH(CZ16,规则数据!$A$500:$A$553,0))),"") | DW16: =IFERROR(IF(INDEX(规则数据!$E$500:$E$553,MATCH(CZ16,规则数据!$A$500:$A$553,0))="","",INDEX(规则数据!$E$500:$E$553,MATCH(CZ16,规则数据!$A$500:$A$553,0))),"") | DZ16: =IFERROR(IF(INDEX(规则数据!$F$500:$F$553,MATCH(CZ16,规则数据!$A$500:$A$553,0))="","",INDEX(规则数据!$F$500:$F$553,MATCH(CZ16,规则数据!$A$500:$A$553,0))),"") | ED16: =IFERROR(IF(INDEX(规则数据!$G$500:$G$553,MATCH(CZ16,规则数据!$A$500:$A$553,0))="","",INDEX(规则数据!$G$500:$G$553,MATCH(CZ16,规则数据!$A$500:$A$553,0))),"") | EI16: ※ 永久伤残、顽疾或成瘾症
B17: =IF(AND('幕间计算'!A5<>"",COUNTIFS('幕间计算'!$A$210:$A$409,IFERROR(VALUE('幕间与结算'!$B$3),0),'幕间计算'!$B$210:$B$409,1,'幕间与结算'!$E$9:$E$208,'幕间计算'!A5)>0,COUNTIFS('幕间计算'!$A$500:$A$739,IFERROR(VALUE('幕间与结算'!$B$3),0),'幕间计算'!$C$500:$C$739,1,'幕间与结算'!$C$215:$C$454,'幕间计算'!A5)=0),"√","☐") -> ☐ | D17: 考古学 | P17: =MAX(0,MIN(99,IF(V17="",N(S17),N(V17))+N(Y17)+N(AB17))) -> 0 | S17: 0 | V17: =IF(职业选项!V46>0,职业选项!V46,"") | Y17: =规则数据!H23 | AB17: ='幕间计算'!B5+IF(AND('幕间计算'!A5<>"",COUNTIF('幕间计算'!$A$2:A5,'幕间计算'!A5)=1),SUMIF('幕间与结算'!$E$9:$E$208,'幕间计算'!A5,'幕间与结算'!$K$9:$K$208)+SUMIF('幕间与结算'!$C$215:$C$454,'幕间计算'!A5,'幕间与结算'!$G$215:$G$454),0) -> 0 | AE17: =IF(AND('幕间计算'!A35<>"",COUNTIFS('幕间计算'!$A$210:$A$409,IFERROR(VALUE('幕间与结算'!$B$3),0),'幕间计算'!$B$210:$B$409,1,'幕间与结算'!$E$9:$E$208,'幕间计算'!A35)>0,COUNTIFS('幕间计算'!$A$500:$A$739,IFERROR(VALUE('幕间与结算'!$B$3),0),'幕间计算'!$C$500:$C$739,1,'幕间与结算'!$C$215:$C$454,'幕间计算'!A35)=0),"√","☐") -> ☐ | AG17: 军事科学： | AM17: =IF(COUNTIF(职业选项!$I$2:$I$28,"军事科学1")>0,IFERROR(INDEX(职业选项!$F$2:$F$28,MATCH("军事科学1",职业选项!$I$2:$I$28,0)),""),IFERROR(MID(IFERROR(INDEX(规则数据!$C$2:$C$9,SMALL(规则数据!$AU$2:$AU$9,1-COUNTIF(职业选项!$C$2:$C$28,"军事科学"))),""),LEN("军事科学")+2,LEN(IFERROR(INDEX(规则数据!$C$2:$C$9,SMALL(规则数据!$AU$2:$AU$9,1-COUNTIF(职业选项!$C$2:$C$28,"军事科学"))),""))-LEN("军事科学")-2),"")) | AS17: =MAX(0,MIN(99,IF(AY17="",N(AV17),N(AY17))+N(BB17)+N(BE17))) -> 0 | AV17: 0 | AY17: =IF(职业选项!V47>0,职业选项!V47,"") | BB17: =规则数据!H53 | BE17: ='幕间计算'!B35+IF(AND('幕间计算'!A35<>"",COUNTIF('幕间计算'!$A$2:A35,'幕间计算'!A35)=1),SUMIF('幕间与结算'!$E$9:$E$208,'幕间计算'!A35,'幕间与结算'!$K$9:$K$208)+SUMIF('幕间与结算'!$C$215:$C$454,'幕间计算'!A35,'幕间与结算'!$G$215:$G$454),0) -> 0 | BI17: 人生动力 及 精神疾病 | BN17: =规则数据!S10&IF(AND(DF46="人类不应知道之事",DR55<>""),IF(规则数据!S10<>"",CHAR(10),"")&"创伤心理疾病："&DR55,"") | DM17: =IFERROR(INDIRECT(INDEX(规则数据!$C$500:$C$553,MATCH(CZ17,规则数据!$A$500:$A$553,0))),"") | DQ17: =IFERROR(IF(INDEX(规则数据!$D$500:$D$553,MATCH(CZ17,规则数据!$A$500:$A$553,0))="","",INDEX(规则数据!$D$500:$D$553,MATCH(CZ17,规则数据!$A$500:$A$553,0))),"") | DW17: =IFERROR(IF(INDEX(规则数据!$E$500:$E$553,MATCH(CZ17,规则数据!$A$500:$A$553,0))="","",INDEX(规则数据!$E$500:$E$553,MATCH(CZ17,规则数据!$A$500:$A$553,0))),"") | DZ17: =IFERROR(IF(INDEX(规则数据!$F$500:$F$553,MATCH(CZ17,规则数据!$A$500:$A$553,0))="","",INDEX(规则数据!$F$500:$F$553,MATCH(CZ17,规则数据!$A$500:$A$553,0))),"") | ED17: =IFERROR(IF(INDEX(规则数据!$G$500:$G$553,MATCH(CZ17,规则数据!$A$500:$A$553,0))="","",INDEX(规则数据!$G$500:$G$553,MATCH(CZ17,规则数据!$A$500:$A$553,0))),"")
B18: =IF(AND('幕间计算'!A6<>"",COUNTIFS('幕间计算'!$A$210:$A$409,IFERROR(VALUE('幕间与结算'!$B$3),0),'幕间计算'!$B$210:$B$409,1,'幕间与结算'!$E$9:$E$208,'幕间计算'!A6)>0,COUNTIFS('幕间计算'!$A$500:$A$739,IFERROR(VALUE('幕间与结算'!$B$3),0),'幕间计算'!$C$500:$C$739,1,'幕间与结算'!$C$215:$C$454,'幕间计算'!A6)=0),"√","☐") -> ☐ | D18: 艺术： | J18: =IF(COUNTIF(职业选项!$I$2:$I$28,"艺术1")>0,IFERROR(INDEX(职业选项!$F$2:$F$28,MATCH("艺术1",职业选项!$I$2:$I$28,0)),""),IFERROR(MID(IFERROR(INDEX(规则数据!$C$2:$C$9,SMALL(规则数据!$AR$2:$AR$9,1-COUNTIF(职业选项!$C$2:$C$28,"艺术"))),""),LEN("艺术")+2,LEN(IFERROR(INDEX(规则数据!$C$2:$C$9,SMALL(规则数据!$AR$2:$AR$9,1-COUNTIF(职业选项!$C$2:$C$28,"艺术"))),""))-LEN("艺术")-2),"")) | P18: =MAX(0,MIN(99,IF(V18="",N(S18),N(V18))+N(Y18)+N(AB18))) -> 0 | S18: 0 | V18: =IF(职业选项!V48>0,职业选项!V48,"") | Y18: =规则数据!H24 | AB18: ='幕间计算'!B6+IF(AND('幕间计算'!A6<>"",COUNTIF('幕间计算'!$A$2:A6,'幕间计算'!A6)=1),SUMIF('幕间与结算'!$E$9:$E$208,'幕间计算'!A6,'幕间与结算'!$K$9:$K$208)+SUMIF('幕间与结算'!$C$215:$C$454,'幕间计算'!A6,'幕间与结算'!$G$215:$G$454),0) -> 0 | AE18: =IF(AND('幕间计算'!A36<>"",COUNTIFS('幕间计算'!$A$210:$A$409,IFERROR(VALUE('幕间与结算'!$B$3),0),'幕间计算'!$B$210:$B$409,1,'幕间与结算'!$E$9:$E$208,'幕间计算'!A36)>0,COUNTIFS('幕间计算'!$A$500:$A$739,IFERROR(VALUE('幕间与结算'!$B$3),0),'幕间计算'!$C$500:$C$739,1,'幕间与结算'!$C$215:$C$454,'幕间计算'!A36)=0),"√","☐") -> ☐ | AG18: 军事科学： | AM18: =IF(COUNTIF(职业选项!$I$2:$I$28,"军事科学2")>0,IFERROR(INDEX(职业选项!$F$2:$F$28,MATCH("军事科学2",职业选项!$I$2:$I$28,0)),""),IFERROR(MID(IFERROR(INDEX(规则数据!$C$2:$C$9,SMALL(规则数据!$AU$2:$AU$9,2-COUNTIF(职业选项!$C$2:$C$28,"军事科学"))),""),LEN("军事科学")+2,LEN(IFERROR(INDEX(规则数据!$C$2:$C$9,SMALL(规则数据!$AU$2:$AU$9,2-COUNTIF(职业选项!$C$2:$C$28,"军事科学"))),""))-LEN("军事科学")-2),"")) | AS18: =MAX(0,MIN(99,IF(AY18="",N(AV18),N(AY18))+N(BB18)+N(BE18))) -> 0 | AV18: 0 | AY18: =IF(职业选项!V49>0,职业选项!V49,"") | BB18: =规则数据!H54 | BE18: ='幕间计算'!B36+IF(AND('幕间计算'!A36<>"",COUNTIF('幕间计算'!$A$2:A36,'幕间计算'!A36)=1),SUMIF('幕间与结算'!$E$9:$E$208,'幕间计算'!A36,'幕间与结算'!$K$9:$K$208)+SUMIF('幕间与结算'!$C$215:$C$454,'幕间计算'!A36,'幕间与结算'!$G$215:$G$454),0) -> 0 | DM18: =IFERROR(INDIRECT(INDEX(规则数据!$C$500:$C$553,MATCH(CZ18,规则数据!$A$500:$A$553,0))),"") | DQ18: =IFERROR(IF(INDEX(规则数据!$D$500:$D$553,MATCH(CZ18,规则数据!$A$500:$A$553,0))="","",INDEX(规则数据!$D$500:$D$553,MATCH(CZ18,规则数据!$A$500:$A$553,0))),"") | DW18: =IFERROR(IF(INDEX(规则数据!$E$500:$E$553,MATCH(CZ18,规则数据!$A$500:$A$553,0))="","",INDEX(规则数据!$E$500:$E$553,MATCH(CZ18,规则数据!$A$500:$A$553,0))),"") | DZ18: =IFERROR(IF(INDEX(规则数据!$F$500:$F$553,MATCH(CZ18,规则数据!$A$500:$A$553,0))="","",INDEX(规则数据!$F$500:$F$553,MATCH(CZ18,规则数据!$A$500:$A$553,0))),"") | ED18: =IFERROR(IF(INDEX(规则数据!$G$500:$G$553,MATCH(CZ18,规则数据!$A$500:$A$553,0))="","",INDEX(规则数据!$G$500:$G$553,MATCH(CZ18,规则数据!$A$500:$A$553,0))),"")
B19: =IF(AND('幕间计算'!A7<>"",COUNTIFS('幕间计算'!$A$210:$A$409,IFERROR(VALUE('幕间与结算'!$B$3),0),'幕间计算'!$B$210:$B$409,1,'幕间与结算'!$E$9:$E$208,'幕间计算'!A7)>0,COUNTIFS('幕间计算'!$A$500:$A$739,IFERROR(VALUE('幕间与结算'!$B$3),0),'幕间计算'!$C$500:$C$739,1,'幕间与结算'!$C$215:$C$454,'幕间计算'!A7)=0),"√","☐") -> ☐ | D19: 艺术： | J19: =IF(COUNTIF(职业选项!$I$2:$I$28,"艺术2")>0,IFERROR(INDEX(职业选项!$F$2:$F$28,MATCH("艺术2",职业选项!$I$2:$I$28,0)),""),IFERROR(MID(IFERROR(INDEX(规则数据!$C$2:$C$9,SMALL(规则数据!$AR$2:$AR$9,2-COUNTIF(职业选项!$C$2:$C$28,"艺术"))),""),LEN("艺术")+2,LEN(IFERROR(INDEX(规则数据!$C$2:$C$9,SMALL(规则数据!$AR$2:$AR$9,2-COUNTIF(职业选项!$C$2:$C$28,"艺术"))),""))-LEN("艺术")-2),"")) | P19: =MAX(0,MIN(99,IF(V19="",N(S19),N(V19))+N(Y19)+N(AB19))) -> 0 | S19: 0 | V19: =IF(职业选项!V50>0,职业选项!V50,"") | Y19: =规则数据!H25 | AB19: ='幕间计算'!B7+IF(AND('幕间计算'!A7<>"",COUNTIF('幕间计算'!$A$2:A7,'幕间计算'!A7)=1),SUMIF('幕间与结算'!$E$9:$E$208,'幕间计算'!A7,'幕间与结算'!$K$9:$K$208)+SUMIF('幕间与结算'!$C$215:$C$454,'幕间计算'!A7,'幕间与结算'!$G$215:$G$454),0) -> 0 | AE19: =IF(AND('幕间计算'!A37<>"",COUNTIFS('幕间计算'!$A$210:$A$409,IFERROR(VALUE('幕间与结算'!$B$3),0),'幕间计算'!$B$210:$B$409,1,'幕间与结算'!$E$9:$E$208,'幕间计算'!A37)>0,COUNTIFS('幕间计算'!$A$500:$A$739,IFERROR(VALUE('幕间与结算'!$B$3),0),'幕间计算'!$C$500:$C$739,1,'幕间与结算'!$C$215:$C$454,'幕间计算'!A37)=0),"√","☐") -> ☐ | AG19: 军事科学： | AM19: =IF(COUNTIF(职业选项!$I$2:$I$28,"军事科学3")>0,IFERROR(INDEX(职业选项!$F$2:$F$28,MATCH("军事科学3",职业选项!$I$2:$I$28,0)),""),IFERROR(MID(IFERROR(INDEX(规则数据!$C$2:$C$9,SMALL(规则数据!$AU$2:$AU$9,3-COUNTIF(职业选项!$C$2:$C$28,"军事科学"))),""),LEN("军事科学")+2,LEN(IFERROR(INDEX(规则数据!$C$2:$C$9,SMALL(规则数据!$AU$2:$AU$9,3-COUNTIF(职业选项!$C$2:$C$28,"军事科学"))),""))-LEN("军事科学")-2),"")) | AS19: =MAX(0,MIN(99,IF(AY19="",N(AV19),N(AY19))+N(BB19)+N(BE19))) -> 0 | AV19: 0 | AY19: =IF(职业选项!V51>0,职业选项!V51,"") | BB19: =规则数据!H55 | BE19: ='幕间计算'!B37+IF(AND('幕间计算'!A37<>"",COUNTIF('幕间计算'!$A$2:A37,'幕间计算'!A37)=1),SUMIF('幕间与结算'!$E$9:$E$208,'幕间计算'!A37,'幕间与结算'!$K$9:$K$208)+SUMIF('幕间与结算'!$C$215:$C$454,'幕间计算'!A37,'幕间与结算'!$G$215:$G$454),0) -> 0 | DM19: =IFERROR(INDIRECT(INDEX(规则数据!$C$500:$C$553,MATCH(CZ19,规则数据!$A$500:$A$553,0))),"") | DQ19: =IFERROR(IF(INDEX(规则数据!$D$500:$D$553,MATCH(CZ19,规则数据!$A$500:$A$553,0))="","",INDEX(规则数据!$D$500:$D$553,MATCH(CZ19,规则数据!$A$500:$A$553,0))),"") | DW19: =IFERROR(IF(INDEX(规则数据!$E$500:$E$553,MATCH(CZ19,规则数据!$A$500:$A$553,0))="","",INDEX(规则数据!$E$500:$E$553,MATCH(CZ19,规则数据!$A$500:$A$553,0))),"") | DZ19: =IFERROR(IF(INDEX(规则数据!$F$500:$F$553,MATCH(CZ19,规则数据!$A$500:$A$553,0))="","",INDEX(规则数据!$F$500:$F$553,MATCH(CZ19,规则数据!$A$500:$A$553,0))),"") | ED19: =IFERROR(IF(INDEX(规则数据!$G$500:$G$553,MATCH(CZ19,规则数据!$A$500:$A$553,0))="","",INDEX(规则数据!$G$500:$G$553,MATCH(CZ19,规则数据!$A$500:$A$553,0))),"")
B20: =IF(AND('幕间计算'!A8<>"",COUNTIFS('幕间计算'!$A$210:$A$409,IFERROR(VALUE('幕间与结算'!$B$3),0),'幕间计算'!$B$210:$B$409,1,'幕间与结算'!$E$9:$E$208,'幕间计算'!A8)>0,COUNTIFS('幕间计算'!$A$500:$A$739,IFERROR(VALUE('幕间与结算'!$B$3),0),'幕间计算'!$C$500:$C$739,1,'幕间与结算'!$C$215:$C$454,'幕间计算'!A8)=0),"√","☐") -> ☐ | D20: 艺术： | J20: =IF(COUNTIF(职业选项!$I$2:$I$28,"艺术3")>0,IFERROR(INDEX(职业选项!$F$2:$F$28,MATCH("艺术3",职业选项!$I$2:$I$28,0)),""),IFERROR(MID(IFERROR(INDEX(规则数据!$C$2:$C$9,SMALL(规则数据!$AR$2:$AR$9,3-COUNTIF(职业选项!$C$2:$C$28,"艺术"))),""),LEN("艺术")+2,LEN(IFERROR(INDEX(规则数据!$C$2:$C$9,SMALL(规则数据!$AR$2:$AR$9,3-COUNTIF(职业选项!$C$2:$C$28,"艺术"))),""))-LEN("艺术")-2),"")) | P20: =MAX(0,MIN(99,IF(V20="",N(S20),N(V20))+N(Y20)+N(AB20))) -> 0 | S20: 0 | V20: =IF(职业选项!V52>0,职业选项!V52,"") | Y20: =规则数据!H26 | AB20: ='幕间计算'!B8+IF(AND('幕间计算'!A8<>"",COUNTIF('幕间计算'!$A$2:A8,'幕间计算'!A8)=1),SUMIF('幕间与结算'!$E$9:$E$208,'幕间计算'!A8,'幕间与结算'!$K$9:$K$208)+SUMIF('幕间与结算'!$C$215:$C$454,'幕间计算'!A8,'幕间与结算'!$G$215:$G$454),0) -> 0 | AE20: =IF(AND('幕间计算'!A38<>"",COUNTIFS('幕间计算'!$A$210:$A$409,IFERROR(VALUE('幕间与结算'!$B$3),0),'幕间计算'!$B$210:$B$409,1,'幕间与结算'!$E$9:$E$208,'幕间计算'!A38)>0,COUNTIFS('幕间计算'!$A$500:$A$739,IFERROR(VALUE('幕间与结算'!$B$3),0),'幕间计算'!$C$500:$C$739,1,'幕间与结算'!$C$215:$C$454,'幕间计算'!A38)=0),"√","☐") -> ☐ | AG20: 导航 | AS20: =MAX(0,MIN(99,IF(AY20="",N(AV20),N(AY20))+N(BB20)+N(BE20))) -> 10 | AV20: 10 | AY20: =IF(职业选项!V53>0,职业选项!V53,"") | BB20: =规则数据!H56 | BE20: ='幕间计算'!B38+IF(AND('幕间计算'!A38<>"",COUNTIF('幕间计算'!$A$2:A38,'幕间计算'!A38)=1),SUMIF('幕间与结算'!$E$9:$E$208,'幕间计算'!A38,'幕间与结算'!$K$9:$K$208)+SUMIF('幕间与结算'!$C$215:$C$454,'幕间计算'!A38,'幕间与结算'!$G$215:$G$454),0) -> 0 | DM20: =IFERROR(INDIRECT(INDEX(规则数据!$C$500:$C$553,MATCH(CZ20,规则数据!$A$500:$A$553,0))),"") | DQ20: =IFERROR(IF(INDEX(规则数据!$D$500:$D$553,MATCH(CZ20,规则数据!$A$500:$A$553,0))="","",INDEX(规则数据!$D$500:$D$553,MATCH(CZ20,规则数据!$A$500:$A$553,0))),"") | DW20: =IFERROR(IF(INDEX(规则数据!$E$500:$E$553,MATCH(CZ20,规则数据!$A$500:$A$553,0))="","",INDEX(规则数据!$E$500:$E$553,MATCH(CZ20,规则数据!$A$500:$A$553,0))),"") | DZ20: =IFERROR(IF(INDEX(规则数据!$F$500:$F$553,MATCH(CZ20,规则数据!$A$500:$A$553,0))="","",INDEX(规则数据!$F$500:$F$553,MATCH(CZ20,规则数据!$A$500:$A$553,0))),"") | ED20: =IFERROR(IF(INDEX(规则数据!$G$500:$G$553,MATCH(CZ20,规则数据!$A$500:$A$553,0))="","",INDEX(规则数据!$G$500:$G$553,MATCH(CZ20,规则数据!$A$500:$A$553,0))),"")
B21: =IF(AND('幕间计算'!A9<>"",COUNTIFS('幕间计算'!$A$210:$A$409,IFERROR(VALUE('幕间与结算'!$B$3),0),'幕间计算'!$B$210:$B$409,1,'幕间与结算'!$E$9:$E$208,'幕间计算'!A9)>0,COUNTIFS('幕间计算'!$A$500:$A$739,IFERROR(VALUE('幕间与结算'!$B$3),0),'幕间计算'!$C$500:$C$739,1,'幕间与结算'!$C$215:$C$454,'幕间计算'!A9)=0),"√","☐") -> ☐ | D21: 炮术 | P21: =MAX(0,MIN(99,IF(V21="",N(S21),N(V21))+N(Y21)+N(AB21))) -> 0 | S21: 0 | V21: =IF(职业选项!V54>0,职业选项!V54,"") | Y21: =规则数据!H27 | AB21: ='幕间计算'!B9+IF(AND('幕间计算'!A9<>"",COUNTIF('幕间计算'!$A$2:A9,'幕间计算'!A9)=1),SUMIF('幕间与结算'!$E$9:$E$208,'幕间计算'!A9,'幕间与结算'!$K$9:$K$208)+SUMIF('幕间与结算'!$C$215:$C$454,'幕间计算'!A9,'幕间与结算'!$G$215:$G$454),0) -> 0 | AE21: =IF(AND('幕间计算'!A39<>"",COUNTIFS('幕间计算'!$A$210:$A$409,IFERROR(VALUE('幕间与结算'!$B$3),0),'幕间计算'!$B$210:$B$409,1,'幕间与结算'!$E$9:$E$208,'幕间计算'!A39)>0,COUNTIFS('幕间计算'!$A$500:$A$739,IFERROR(VALUE('幕间与结算'!$B$3),0),'幕间计算'!$C$500:$C$739,1,'幕间与结算'!$C$215:$C$454,'幕间计算'!A39)=0),"√","☐") -> ☐ | AG21: 神秘学 | AS21: =MAX(0,MIN(99,IF(AY21="",N(AV21),N(AY21))+N(BB21)+N(BE21))) -> 10 | AV21: 10 | AY21: =IF(职业选项!V55>0,职业选项!V55,"") | BB21: =规则数据!H57 | BE21: ='幕间计算'!B39+IF(AND('幕间计算'!A39<>"",COUNTIF('幕间计算'!$A$2:A39,'幕间计算'!A39)=1),SUMIF('幕间与结算'!$E$9:$E$208,'幕间计算'!A39,'幕间与结算'!$K$9:$K$208)+SUMIF('幕间与结算'!$C$215:$C$454,'幕间计算'!A39,'幕间与结算'!$G$215:$G$454),0) -> 0
B22: =IF(AND('幕间计算'!A10<>"",COUNTIFS('幕间计算'!$A$210:$A$409,IFERROR(VALUE('幕间与结算'!$B$3),0),'幕间计算'!$B$210:$B$409,1,'幕间与结算'!$E$9:$E$208,'幕间计算'!A10)>0,COUNTIFS('幕间计算'!$A$500:$A$739,IFERROR(VALUE('幕间与结算'!$B$3),0),'幕间计算'!$C$500:$C$739,1,'幕间与结算'!$C$215:$C$454,'幕间计算'!A10)=0),"√","☐") -> ☐ | D22: 运动 | P22: =MAX(0,MIN(99,IF(V22="",N(S22),N(V22))+N(Y22)+N(AB22))) -> 30 | S22: 30 | V22: =IF(职业选项!V56>0,职业选项!V56,"") | Y22: =规则数据!H28 | AB22: ='幕间计算'!B10+IF(AND('幕间计算'!A10<>"",COUNTIF('幕间计算'!$A$2:A10,'幕间计算'!A10)=1),SUMIF('幕间与结算'!$E$9:$E$208,'幕间计算'!A10,'幕间与结算'!$K$9:$K$208)+SUMIF('幕间与结算'!$C$215:$C$454,'幕间计算'!A10,'幕间与结算'!$G$215:$G$454),0) -> 0 | AE22: =IF(AND('幕间计算'!A40<>"",COUNTIFS('幕间计算'!$A$210:$A$409,IFERROR(VALUE('幕间与结算'!$B$3),0),'幕间计算'!$B$210:$B$409,1,'幕间与结算'!$E$9:$E$208,'幕间计算'!A40)>0,COUNTIFS('幕间计算'!$A$500:$A$739,IFERROR(VALUE('幕间与结算'!$B$3),0),'幕间计算'!$C$500:$C$739,1,'幕间与结算'!$C$215:$C$454,'幕间计算'!A40)=0),"√","☐") -> ☐ | AG22: 说服 | AS22: =MAX(0,MIN(99,IF(AY22="",N(AV22),N(AY22))+N(BB22)+N(BE22))) -> 20 | AV22: 20 | AY22: =IF(职业选项!V57>0,职业选项!V57,"") | BB22: =规则数据!H58 | BE22: ='幕间计算'!B40+IF(AND('幕间计算'!A40<>"",COUNTIF('幕间计算'!$A$2:A40,'幕间计算'!A40)=1),SUMIF('幕间与结算'!$E$9:$E$208,'幕间计算'!A40,'幕间与结算'!$K$9:$K$208)+SUMIF('幕间与结算'!$C$215:$C$454,'幕间计算'!A40,'幕间与结算'!$G$215:$G$454),0) -> 0 | CZ22: ※ 重要关系 | DT22: 关系数： | DX22: =COUNTIF(ED24,">0")+COUNTIF(ED27,">0")+COUNTIF(ED30,">0")+COUNTIF(ED33,">0")+COUNTIF(ED36,">0")+COUNTIF(ED39,">0")+COUNTIF(ED42,">0") -> 0 | EC22: 魅力： | EF22: =附表!B7 -> 0 | EI22: ※ 其他笔记
B23: =IF(AND('幕间计算'!A11<>"",COUNTIFS('幕间计算'!$A$210:$A$409,IFERROR(VALUE('幕间与结算'!$B$3),0),'幕间计算'!$B$210:$B$409,1,'幕间与结算'!$E$9:$E$208,'幕间计算'!A11)>0,COUNTIFS('幕间计算'!$A$500:$A$739,IFERROR(VALUE('幕间与结算'!$B$3),0),'幕间计算'!$C$500:$C$739,1,'幕间与结算'!$C$215:$C$454,'幕间计算'!A11)=0),"√","☐") -> ☐ | D23: 行政 | P23: =MAX(0,MIN(99,IF(V23="",N(S23),N(V23))+N(Y23)+N(AB23))) -> 10 | S23: 10 | V23: =IF(职业选项!V58>0,职业选项!V58,"") | Y23: =规则数据!H29 | AB23: ='幕间计算'!B11+IF(AND('幕间计算'!A11<>"",COUNTIF('幕间计算'!$A$2:A11,'幕间计算'!A11)=1),SUMIF('幕间与结算'!$E$9:$E$208,'幕间计算'!A11,'幕间与结算'!$K$9:$K$208)+SUMIF('幕间与结算'!$C$215:$C$454,'幕间计算'!A11,'幕间与结算'!$G$215:$G$454),0) -> 0 | AE23: =IF(AND('幕间计算'!A41<>"",COUNTIFS('幕间计算'!$A$210:$A$409,IFERROR(VALUE('幕间与结算'!$B$3),0),'幕间计算'!$B$210:$B$409,1,'幕间与结算'!$E$9:$E$208,'幕间计算'!A41)>0,COUNTIFS('幕间计算'!$A$500:$A$739,IFERROR(VALUE('幕间与结算'!$B$3),0),'幕间计算'!$C$500:$C$739,1,'幕间与结算'!$C$215:$C$454,'幕间计算'!A41)=0),"√","☐") -> ☐ | AG23: 药学 | AS23: =MAX(0,MIN(99,IF(AY23="",N(AV23),N(AY23))+N(BB23)+N(BE23))) -> 0 | AV23: 0 | AY23: =IF(职业选项!V59>0,职业选项!V59,"") | BB23: =规则数据!H59 | BE23: ='幕间计算'!B41+IF(AND('幕间计算'!A41<>"",COUNTIF('幕间计算'!$A$2:A41,'幕间计算'!A41)=1),SUMIF('幕间与结算'!$E$9:$E$208,'幕间计算'!A41,'幕间与结算'!$K$9:$K$208)+SUMIF('幕间与结算'!$C$215:$C$454,'幕间计算'!A41,'幕间与结算'!$G$215:$G$454),0) -> 0 | ED23: 值 | EF23: DG
B24: =IF(AND('幕间计算'!A12<>"",COUNTIFS('幕间计算'!$A$210:$A$409,IFERROR(VALUE('幕间与结算'!$B$3),0),'幕间计算'!$B$210:$B$409,1,'幕间与结算'!$E$9:$E$208,'幕间计算'!A12)>0,COUNTIFS('幕间计算'!$A$500:$A$739,IFERROR(VALUE('幕间与结算'!$B$3),0),'幕间计算'!$C$500:$C$739,1,'幕间与结算'!$C$215:$C$454,'幕间计算'!A12)=0),"√","☐") -> ☐ | D24: 计算机科学 | P24: =MAX(0,MIN(99,IF(V24="",N(S24),N(V24))+N(Y24)+N(AB24))) -> 0 | S24: 0 | V24: =IF(职业选项!V60>0,职业选项!V60,"") | Y24: =规则数据!H30 | AB24: ='幕间计算'!B12+IF(AND('幕间计算'!A12<>"",COUNTIF('幕间计算'!$A$2:A12,'幕间计算'!A12)=1),SUMIF('幕间与结算'!$E$9:$E$208,'幕间计算'!A12,'幕间与结算'!$K$9:$K$208)+SUMIF('幕间与结算'!$C$215:$C$454,'幕间计算'!A12,'幕间与结算'!$G$215:$G$454),0) -> 0 | AE24: =IF(AND('幕间计算'!A42<>"",COUNTIFS('幕间计算'!$A$210:$A$409,IFERROR(VALUE('幕间与结算'!$B$3),0),'幕间计算'!$B$210:$B$409,1,'幕间与结算'!$E$9:$E$208,'幕间计算'!A42)>0,COUNTIFS('幕间计算'!$A$500:$A$739,IFERROR(VALUE('幕间与结算'!$B$3),0),'幕间计算'!$C$500:$C$739,1,'幕间与结算'!$C$215:$C$454,'幕间计算'!A42)=0),"√","☐") -> ☐ | AG24: 特种载具： | AM24: =IF(COUNTIF(职业选项!$I$2:$I$28,"特种载具1")>0,IFERROR(INDEX(职业选项!$F$2:$F$28,MATCH("特种载具1",职业选项!$I$2:$I$28,0)),""),IFERROR(MID(IFERROR(INDEX(规则数据!$C$2:$C$9,SMALL(规则数据!$AV$2:$AV$9,1-COUNTIF(职业选项!$C$2:$C$28,"特种载具"))),""),LEN("特种载具")+2,LEN(IFERROR(INDEX(规则数据!$C$2:$C$9,SMALL(规则数据!$AV$2:$AV$9,1-COUNTIF(职业选项!$C$2:$C$28,"特种载具"))),""))-LEN("特种载具")-2),"")) | AS24: =MAX(0,MIN(99,IF(AY24="",N(AV24),N(AY24))+N(BB24)+N(BE24))) -> 0 | AV24: 0 | AY24: =IF(职业选项!V61>0,职业选项!V61,"") | BB24: =规则数据!H60 | BE24: ='幕间计算'!B42+IF(AND('幕间计算'!A42<>"",COUNTIF('幕间计算'!$A$2:A42,'幕间计算'!A42)=1),SUMIF('幕间与结算'!$E$9:$E$208,'幕间计算'!A42,'幕间与结算'!$K$9:$K$208)+SUMIF('幕间与结算'!$C$215:$C$454,'幕间计算'!A42,'幕间与结算'!$G$215:$G$454),0) -> 0 | ED24: =IF(CZ23="","",MAX(0,MIN(EF$22,IF('幕间计算'!Q2>0,IFERROR(INDEX('幕间与结算'!$F$9:$F$208,'幕间计算'!Q2-8),0)+SUMIFS('幕间与结算'!$K$9:$K$208,'幕间与结算'!$E$9:$E$208,"重要关系1",'幕间计算'!$F$210:$F$409,">="&'幕间计算'!Q2)-SUMIFS('幕间计算'!$D$210:$D$409,'幕间与结算'!$L$9:$L$208,"重要关系1",'幕间计算'!$F$210:$F$409,">="&'幕间计算'!Q2)+SUMIFS('幕间与结算'!$K$9:$K$208,'幕间与结算'!$E$9:$E$208,"魅力",'幕间与结算'!$K$9:$K$208,"<0",'幕间计算'!$F$210:$F$409,">="&'幕间计算'!Q2),N('幕间计算'!P2)+SUMIF('幕间与结算'!$E$9:$E$208,"重要关系1",'幕间与结算'!$K$9:$K$208)-SUMIF('幕间与结算'!$L$9:$L$208,"重要关系1",'幕间计算'!$D$210:$D$409)+SUMIFS('幕间与结算'!$K$9:$K$208,'幕间与结算'!$E$9:$E$208,"魅力",'幕间与结算'!$K$9:$K$208,"<0"))))) | EF24: ×
B25: =IF(AND('幕间计算'!A13<>"",COUNTIFS('幕间计算'!$A$210:$A$409,IFERROR(VALUE('幕间与结算'!$B$3),0),'幕间计算'!$B$210:$B$409,1,'幕间与结算'!$E$9:$E$208,'幕间计算'!A13)>0,COUNTIFS('幕间计算'!$A$500:$A$739,IFERROR(VALUE('幕间与结算'!$B$3),0),'幕间计算'!$C$500:$C$739,1,'幕间与结算'!$C$215:$C$454,'幕间计算'!A13)=0),"√","☐") -> ☐ | D25: 工艺： | J25: =IF(COUNTIF(职业选项!$I$2:$I$28,"工艺1")>0,IFERROR(INDEX(职业选项!$F$2:$F$28,MATCH("工艺1",职业选项!$I$2:$I$28,0)),""),IFERROR(MID(IFERROR(INDEX(规则数据!$C$2:$C$9,SMALL(规则数据!$AS$2:$AS$9,1-COUNTIF(职业选项!$C$2:$C$28,"工艺"))),""),LEN("工艺")+2,LEN(IFERROR(INDEX(规则数据!$C$2:$C$9,SMALL(规则数据!$AS$2:$AS$9,1-COUNTIF(职业选项!$C$2:$C$28,"工艺"))),""))-LEN("工艺")-2),"")) | P25: =MAX(0,MIN(99,IF(V25="",N(S25),N(V25))+N(Y25)+N(AB25))) -> 0 | S25: 0 | V25: =IF(职业选项!V62>0,职业选项!V62,"") | Y25: =规则数据!H31 | AB25: ='幕间计算'!B13+IF(AND('幕间计算'!A13<>"",COUNTIF('幕间计算'!$A$2:A13,'幕间计算'!A13)=1),SUMIF('幕间与结算'!$E$9:$E$208,'幕间计算'!A13,'幕间与结算'!$K$9:$K$208)+SUMIF('幕间与结算'!$C$215:$C$454,'幕间计算'!A13,'幕间与结算'!$G$215:$G$454),0) -> 0 | AE25: =IF(AND('幕间计算'!A43<>"",COUNTIFS('幕间计算'!$A$210:$A$409,IFERROR(VALUE('幕间与结算'!$B$3),0),'幕间计算'!$B$210:$B$409,1,'幕间与结算'!$E$9:$E$208,'幕间计算'!A43)>0,COUNTIFS('幕间计算'!$A$500:$A$739,IFERROR(VALUE('幕间与结算'!$B$3),0),'幕间计算'!$C$500:$C$739,1,'幕间与结算'!$C$215:$C$454,'幕间计算'!A43)=0),"√","☐") -> ☐ | AG25: 特种载具： | AM25: =IF(COUNTIF(职业选项!$I$2:$I$28,"特种载具2")>0,IFERROR(INDEX(职业选项!$F$2:$F$28,MATCH("特种载具2",职业选项!$I$2:$I$28,0)),""),IFERROR(MID(IFERROR(INDEX(规则数据!$C$2:$C$9,SMALL(规则数据!$AV$2:$AV$9,2-COUNTIF(职业选项!$C$2:$C$28,"特种载具"))),""),LEN("特种载具")+2,LEN(IFERROR(INDEX(规则数据!$C$2:$C$9,SMALL(规则数据!$AV$2:$AV$9,2-COUNTIF(职业选项!$C$2:$C$28,"特种载具"))),""))-LEN("特种载具")-2),"")) | AS25: =MAX(0,MIN(99,IF(AY25="",N(AV25),N(AY25))+N(BB25)+N(BE25))) -> 0 | AV25: 0 | AY25: =IF(职业选项!V63>0,职业选项!V63,"") | BB25: =规则数据!H61 | BE25: ='幕间计算'!B43+IF(AND('幕间计算'!A43<>"",COUNTIF('幕间计算'!$A$2:A43,'幕间计算'!A43)=1),SUMIF('幕间与结算'!$E$9:$E$208,'幕间计算'!A43,'幕间与结算'!$K$9:$K$208)+SUMIF('幕间与结算'!$C$215:$C$454,'幕间计算'!A43,'幕间与结算'!$G$215:$G$454),0) -> 0
B26: =IF(AND('幕间计算'!A14<>"",COUNTIFS('幕间计算'!$A$210:$A$409,IFERROR(VALUE('幕间与结算'!$B$3),0),'幕间计算'!$B$210:$B$409,1,'幕间与结算'!$E$9:$E$208,'幕间计算'!A14)>0,COUNTIFS('幕间计算'!$A$500:$A$739,IFERROR(VALUE('幕间与结算'!$B$3),0),'幕间计算'!$C$500:$C$739,1,'幕间与结算'!$C$215:$C$454,'幕间计算'!A14)=0),"√","☐") -> ☐ | D26: 工艺： | J26: =IF(COUNTIF(职业选项!$I$2:$I$28,"工艺2")>0,IFERROR(INDEX(职业选项!$F$2:$F$28,MATCH("工艺2",职业选项!$I$2:$I$28,0)),""),IFERROR(MID(IFERROR(INDEX(规则数据!$C$2:$C$9,SMALL(规则数据!$AS$2:$AS$9,2-COUNTIF(职业选项!$C$2:$C$28,"工艺"))),""),LEN("工艺")+2,LEN(IFERROR(INDEX(规则数据!$C$2:$C$9,SMALL(规则数据!$AS$2:$AS$9,2-COUNTIF(职业选项!$C$2:$C$28,"工艺"))),""))-LEN("工艺")-2),"")) | P26: =MAX(0,MIN(99,IF(V26="",N(S26),N(V26))+N(Y26)+N(AB26))) -> 0 | S26: 0 | V26: =IF(职业选项!V64>0,职业选项!V64,"") | Y26: =规则数据!H32 | AB26: ='幕间计算'!B14+IF(AND('幕间计算'!A14<>"",COUNTIF('幕间计算'!$A$2:A14,'幕间计算'!A14)=1),SUMIF('幕间与结算'!$E$9:$E$208,'幕间计算'!A14,'幕间与结算'!$K$9:$K$208)+SUMIF('幕间与结算'!$C$215:$C$454,'幕间计算'!A14,'幕间与结算'!$G$215:$G$454),0) -> 0 | AE26: =IF(AND('幕间计算'!A44<>"",COUNTIFS('幕间计算'!$A$210:$A$409,IFERROR(VALUE('幕间与结算'!$B$3),0),'幕间计算'!$B$210:$B$409,1,'幕间与结算'!$E$9:$E$208,'幕间计算'!A44)>0,COUNTIFS('幕间计算'!$A$500:$A$739,IFERROR(VALUE('幕间与结算'!$B$3),0),'幕间计算'!$C$500:$C$739,1,'幕间与结算'!$C$215:$C$454,'幕间计算'!A44)=0),"√","☐") -> ☐ | AG26: 特种载具： | AM26: =IF(COUNTIF(职业选项!$I$2:$I$28,"特种载具3")>0,IFERROR(INDEX(职业选项!$F$2:$F$28,MATCH("特种载具3",职业选项!$I$2:$I$28,0)),""),IFERROR(MID(IFERROR(INDEX(规则数据!$C$2:$C$9,SMALL(规则数据!$AV$2:$AV$9,3-COUNTIF(职业选项!$C$2:$C$28,"特种载具"))),""),LEN("特种载具")+2,LEN(IFERROR(INDEX(规则数据!$C$2:$C$9,SMALL(规则数据!$AV$2:$AV$9,3-COUNTIF(职业选项!$C$2:$C$28,"特种载具"))),""))-LEN("特种载具")-2),"")) | AS26: =MAX(0,MIN(99,IF(AY26="",N(AV26),N(AY26))+N(BB26)+N(BE26))) -> 0 | AV26: 0 | AY26: =IF(职业选项!V65>0,职业选项!V65,"") | BB26: =规则数据!H62 | BE26: ='幕间计算'!B44+IF(AND('幕间计算'!A44<>"",COUNTIF('幕间计算'!$A$2:A44,'幕间计算'!A44)=1),SUMIF('幕间与结算'!$E$9:$E$208,'幕间计算'!A44,'幕间与结算'!$K$9:$K$208)+SUMIF('幕间与结算'!$C$215:$C$454,'幕间计算'!A44,'幕间与结算'!$G$215:$G$454),0) -> 0 | ED26: 值 | EF26: DG
B27: =IF(AND('幕间计算'!A15<>"",COUNTIFS('幕间计算'!$A$210:$A$409,IFERROR(VALUE('幕间与结算'!$B$3),0),'幕间计算'!$B$210:$B$409,1,'幕间与结算'!$E$9:$E$208,'幕间计算'!A15)>0,COUNTIFS('幕间计算'!$A$500:$A$739,IFERROR(VALUE('幕间与结算'!$B$3),0),'幕间计算'!$C$500:$C$739,1,'幕间与结算'!$C$215:$C$454,'幕间计算'!A15)=0),"√","☐") -> ☐ | D27: 工艺： | J27: =IF(COUNTIF(职业选项!$I$2:$I$28,"工艺3")>0,IFERROR(INDEX(职业选项!$F$2:$F$28,MATCH("工艺3",职业选项!$I$2:$I$28,0)),""),IFERROR(MID(IFERROR(INDEX(规则数据!$C$2:$C$9,SMALL(规则数据!$AS$2:$AS$9,3-COUNTIF(职业选项!$C$2:$C$28,"工艺"))),""),LEN("工艺")+2,LEN(IFERROR(INDEX(规则数据!$C$2:$C$9,SMALL(规则数据!$AS$2:$AS$9,3-COUNTIF(职业选项!$C$2:$C$28,"工艺"))),""))-LEN("工艺")-2),"")) | P27: =MAX(0,MIN(99,IF(V27="",N(S27),N(V27))+N(Y27)+N(AB27))) -> 0 | S27: 0 | V27: =IF(职业选项!V66>0,职业选项!V66,"") | Y27: =规则数据!H33 | AB27: ='幕间计算'!B15+IF(AND('幕间计算'!A15<>"",COUNTIF('幕间计算'!$A$2:A15,'幕间计算'!A15)=1),SUMIF('幕间与结算'!$E$9:$E$208,'幕间计算'!A15,'幕间与结算'!$K$9:$K$208)+SUMIF('幕间与结算'!$C$215:$C$454,'幕间计算'!A15,'幕间与结算'!$G$215:$G$454),0) -> 0 | AE27: =IF(AND('幕间计算'!A45<>"",COUNTIFS('幕间计算'!$A$210:$A$409,IFERROR(VALUE('幕间与结算'!$B$3),0),'幕间计算'!$B$210:$B$409,1,'幕间与结算'!$E$9:$E$208,'幕间计算'!A45)>0,COUNTIFS('幕间计算'!$A$500:$A$739,IFERROR(VALUE('幕间与结算'!$B$3),0),'幕间计算'!$C$500:$C$739,1,'幕间与结算'!$C$215:$C$454,'幕间计算'!A45)=0),"√","☐") -> ☐ | AG27: 精神治疗 | AS27: =MAX(0,MIN(99,IF(AY27="",N(AV27),N(AY27))+N(BB27)+N(BE27))) -> 10 | AV27: 10 | AY27: =IF(职业选项!V67>0,职业选项!V67,"") | BB27: =规则数据!H63 | BE27: ='幕间计算'!B45+IF(AND('幕间计算'!A45<>"",COUNTIF('幕间计算'!$A$2:A45,'幕间计算'!A45)=1),SUMIF('幕间与结算'!$E$9:$E$208,'幕间计算'!A45,'幕间与结算'!$K$9:$K$208)+SUMIF('幕间与结算'!$C$215:$C$454,'幕间计算'!A45,'幕间与结算'!$G$215:$G$454),0) -> 0 | ED27: =IF(CZ26="","",MAX(0,MIN(EF$22,IF('幕间计算'!Q3>0,IFERROR(INDEX('幕间与结算'!$F$9:$F$208,'幕间计算'!Q3-8),0)+SUMIFS('幕间与结算'!$K$9:$K$208,'幕间与结算'!$E$9:$E$208,"重要关系2",'幕间计算'!$F$210:$F$409,">="&'幕间计算'!Q3)-SUMIFS('幕间计算'!$D$210:$D$409,'幕间与结算'!$L$9:$L$208,"重要关系2",'幕间计算'!$F$210:$F$409,">="&'幕间计算'!Q3)+SUMIFS('幕间与结算'!$K$9:$K$208,'幕间与结算'!$E$9:$E$208,"魅力",'幕间与结算'!$K$9:$K$208,"<0",'幕间计算'!$F$210:$F$409,">="&'幕间计算'!Q3),N('幕间计算'!P3)+SUMIF('幕间与结算'!$E$9:$E$208,"重要关系2",'幕间与结算'!$K$9:$K$208)-SUMIF('幕间与结算'!$L$9:$L$208,"重要关系2",'幕间计算'!$D$210:$D$409)+SUMIFS('幕间与结算'!$K$9:$K$208,'幕间与结算'!$E$9:$E$208,"魅力",'幕间与结算'!$K$9:$K$208,"<0"))))) | EF27: ×
B28: =IF(AND('幕间计算'!A16<>"",COUNTIFS('幕间计算'!$A$210:$A$409,IFERROR(VALUE('幕间与结算'!$B$3),0),'幕间计算'!$B$210:$B$409,1,'幕间与结算'!$E$9:$E$208,'幕间计算'!A16)>0,COUNTIFS('幕间计算'!$A$500:$A$739,IFERROR(VALUE('幕间与结算'!$B$3),0),'幕间计算'!$C$500:$C$739,1,'幕间与结算'!$C$215:$C$454,'幕间计算'!A16)=0),"√","☐") -> ☐ | D28: 工艺： | J28: =IF(COUNTIF(职业选项!$I$2:$I$28,"工艺4")>0,IFERROR(INDEX(职业选项!$F$2:$F$28,MATCH("工艺4",职业选项!$I$2:$I$28,0)),""),IFERROR(MID(IFERROR(INDEX(规则数据!$C$2:$C$9,SMALL(规则数据!$AS$2:$AS$9,4-COUNTIF(职业选项!$C$2:$C$28,"工艺"))),""),LEN("工艺")+2,LEN(IFERROR(INDEX(规则数据!$C$2:$C$9,SMALL(规则数据!$AS$2:$AS$9,4-COUNTIF(职业选项!$C$2:$C$28,"工艺"))),""))-LEN("工艺")-2),"")) | P28: =MAX(0,MIN(99,IF(V28="",N(S28),N(V28))+N(Y28)+N(AB28))) -> 0 | S28: 0 | V28: =IF(职业选项!V68>0,职业选项!V68,"") | Y28: =规则数据!H34 | AB28: ='幕间计算'!B16+IF(AND('幕间计算'!A16<>"",COUNTIF('幕间计算'!$A$2:A16,'幕间计算'!A16)=1),SUMIF('幕间与结算'!$E$9:$E$208,'幕间计算'!A16,'幕间与结算'!$K$9:$K$208)+SUMIF('幕间与结算'!$C$215:$C$454,'幕间计算'!A16,'幕间与结算'!$G$215:$G$454),0) -> 0 | AE28: =IF(AND('幕间计算'!A46<>"",COUNTIFS('幕间计算'!$A$210:$A$409,IFERROR(VALUE('幕间与结算'!$B$3),0),'幕间计算'!$B$210:$B$409,1,'幕间与结算'!$E$9:$E$208,'幕间计算'!A46)>0,COUNTIFS('幕间计算'!$A$500:$A$739,IFERROR(VALUE('幕间与结算'!$B$3),0),'幕间计算'!$C$500:$C$739,1,'幕间与结算'!$C$215:$C$454,'幕间计算'!A46)=0),"√","☐") -> ☐ | AG28: 骑术 | AS28: =MAX(0,MIN(99,IF(AY28="",N(AV28),N(AY28))+N(BB28)+N(BE28))) -> 10 | AV28: 10 | AY28: =IF(职业选项!V69>0,职业选项!V69,"") | BB28: =规则数据!H64 | BE28: ='幕间计算'!B46+IF(AND('幕间计算'!A46<>"",COUNTIF('幕间计算'!$A$2:A46,'幕间计算'!A46)=1),SUMIF('幕间与结算'!$E$9:$E$208,'幕间计算'!A46,'幕间与结算'!$K$9:$K$208)+SUMIF('幕间与结算'!$C$215:$C$454,'幕间计算'!A46,'幕间与结算'!$G$215:$G$454),0) -> 0
B29: =IF(AND('幕间计算'!A17<>"",COUNTIFS('幕间计算'!$A$210:$A$409,IFERROR(VALUE('幕间与结算'!$B$3),0),'幕间计算'!$B$210:$B$409,1,'幕间与结算'!$E$9:$E$208,'幕间计算'!A17)>0,COUNTIFS('幕间计算'!$A$500:$A$739,IFERROR(VALUE('幕间与结算'!$B$3),0),'幕间计算'!$C$500:$C$739,1,'幕间与结算'!$C$215:$C$454,'幕间计算'!A17)=0),"√","☐") -> ☐ | D29: 犯罪学 | P29: =MAX(0,MIN(99,IF(V29="",N(S29),N(V29))+N(Y29)+N(AB29))) -> 10 | S29: 10 | V29: =IF(职业选项!V70>0,职业选项!V70,"") | Y29: =规则数据!H35 | AB29: ='幕间计算'!B17+IF(AND('幕间计算'!A17<>"",COUNTIF('幕间计算'!$A$2:A17,'幕间计算'!A17)=1),SUMIF('幕间与结算'!$E$9:$E$208,'幕间计算'!A17,'幕间与结算'!$K$9:$K$208)+SUMIF('幕间与结算'!$C$215:$C$454,'幕间计算'!A17,'幕间与结算'!$G$215:$G$454),0) -> 0 | AE29: =IF(AND('幕间计算'!A47<>"",COUNTIFS('幕间计算'!$A$210:$A$409,IFERROR(VALUE('幕间与结算'!$B$3),0),'幕间计算'!$B$210:$B$409,1,'幕间与结算'!$E$9:$E$208,'幕间计算'!A47)>0,COUNTIFS('幕间计算'!$A$500:$A$739,IFERROR(VALUE('幕间与结算'!$B$3),0),'幕间计算'!$C$500:$C$739,1,'幕间与结算'!$C$215:$C$454,'幕间计算'!A47)=0),"√","☐") -> ☐ | AG29: 科学： | AM29: =IF(COUNTIF(职业选项!$I$2:$I$28,"科学1")>0,IFERROR(INDEX(职业选项!$F$2:$F$28,MATCH("科学1",职业选项!$I$2:$I$28,0)),""),IFERROR(MID(IFERROR(INDEX(规则数据!$C$2:$C$9,SMALL(规则数据!$AW$2:$AW$9,1-COUNTIF(职业选项!$C$2:$C$28,"科学"))),""),LEN("科学")+2,LEN(IFERROR(INDEX(规则数据!$C$2:$C$9,SMALL(规则数据!$AW$2:$AW$9,1-COUNTIF(职业选项!$C$2:$C$28,"科学"))),""))-LEN("科学")-2),"")) | AS29: =MAX(0,MIN(99,IF(AY29="",N(AV29),N(AY29))+N(BB29)+N(BE29))) -> 0 | AV29: 0 | AY29: =IF(职业选项!V71>0,职业选项!V71,"") | BB29: =规则数据!H65 | BE29: ='幕间计算'!B47+IF(AND('幕间计算'!A47<>"",COUNTIF('幕间计算'!$A$2:A47,'幕间计算'!A47)=1),SUMIF('幕间与结算'!$E$9:$E$208,'幕间计算'!A47,'幕间与结算'!$K$9:$K$208)+SUMIF('幕间与结算'!$C$215:$C$454,'幕间计算'!A47,'幕间与结算'!$G$215:$G$454),0) -> 0 | ED29: 值 | EF29: DG
B30: =IF(AND('幕间计算'!A18<>"",COUNTIFS('幕间计算'!$A$210:$A$409,IFERROR(VALUE('幕间与结算'!$B$3),0),'幕间计算'!$B$210:$B$409,1,'幕间与结算'!$E$9:$E$208,'幕间计算'!A18)>0,COUNTIFS('幕间计算'!$A$500:$A$739,IFERROR(VALUE('幕间与结算'!$B$3),0),'幕间计算'!$C$500:$C$739,1,'幕间与结算'!$C$215:$C$454,'幕间计算'!A18)=0),"√","☐") -> ☐ | D30: 爆破 | P30: =MAX(0,MIN(99,IF(V30="",N(S30),N(V30))+N(Y30)+N(AB30))) -> 0 | S30: 0 | V30: =IF(职业选项!V72>0,职业选项!V72,"") | Y30: =规则数据!H36 | AB30: ='幕间计算'!B18+IF(AND('幕间计算'!A18<>"",COUNTIF('幕间计算'!$A$2:A18,'幕间计算'!A18)=1),SUMIF('幕间与结算'!$E$9:$E$208,'幕间计算'!A18,'幕间与结算'!$K$9:$K$208)+SUMIF('幕间与结算'!$C$215:$C$454,'幕间计算'!A18,'幕间与结算'!$G$215:$G$454),0) -> 0 | AE30: =IF(AND('幕间计算'!A48<>"",COUNTIFS('幕间计算'!$A$210:$A$409,IFERROR(VALUE('幕间与结算'!$B$3),0),'幕间计算'!$B$210:$B$409,1,'幕间与结算'!$E$9:$E$208,'幕间计算'!A48)>0,COUNTIFS('幕间计算'!$A$500:$A$739,IFERROR(VALUE('幕间与结算'!$B$3),0),'幕间计算'!$C$500:$C$739,1,'幕间与结算'!$C$215:$C$454,'幕间计算'!A48)=0),"√","☐") -> ☐ | AG30: 科学： | AM30: =IF(COUNTIF(职业选项!$I$2:$I$28,"科学2")>0,IFERROR(INDEX(职业选项!$F$2:$F$28,MATCH("科学2",职业选项!$I$2:$I$28,0)),""),IFERROR(MID(IFERROR(INDEX(规则数据!$C$2:$C$9,SMALL(规则数据!$AW$2:$AW$9,2-COUNTIF(职业选项!$C$2:$C$28,"科学"))),""),LEN("科学")+2,LEN(IFERROR(INDEX(规则数据!$C$2:$C$9,SMALL(规则数据!$AW$2:$AW$9,2-COUNTIF(职业选项!$C$2:$C$28,"科学"))),""))-LEN("科学")-2),"")) | AS30: =MAX(0,MIN(99,IF(AY30="",N(AV30),N(AY30))+N(BB30)+N(BE30))) -> 0 | AV30: 0 | AY30: =IF(职业选项!V73>0,职业选项!V73,"") | BB30: =规则数据!H66 | BE30: ='幕间计算'!B48+IF(AND('幕间计算'!A48<>"",COUNTIF('幕间计算'!$A$2:A48,'幕间计算'!A48)=1),SUMIF('幕间与结算'!$E$9:$E$208,'幕间计算'!A48,'幕间与结算'!$K$9:$K$208)+SUMIF('幕间与结算'!$C$215:$C$454,'幕间计算'!A48,'幕间与结算'!$G$215:$G$454),0) -> 0 | ED30: =IF(CZ29="","",MAX(0,MIN(EF$22,IF('幕间计算'!Q4>0,IFERROR(INDEX('幕间与结算'!$F$9:$F$208,'幕间计算'!Q4-8),0)+SUMIFS('幕间与结算'!$K$9:$K$208,'幕间与结算'!$E$9:$E$208,"重要关系3",'幕间计算'!$F$210:$F$409,">="&'幕间计算'!Q4)-SUMIFS('幕间计算'!$D$210:$D$409,'幕间与结算'!$L$9:$L$208,"重要关系3",'幕间计算'!$F$210:$F$409,">="&'幕间计算'!Q4)+SUMIFS('幕间与结算'!$K$9:$K$208,'幕间与结算'!$E$9:$E$208,"魅力",'幕间与结算'!$K$9:$K$208,"<0",'幕间计算'!$F$210:$F$409,">="&'幕间计算'!Q4),N('幕间计算'!P4)+SUMIF('幕间与结算'!$E$9:$E$208,"重要关系3",'幕间与结算'!$K$9:$K$208)-SUMIF('幕间与结算'!$L$9:$L$208,"重要关系3",'幕间计算'!$D$210:$D$409)+SUMIFS('幕间与结算'!$K$9:$K$208,'幕间与结算'!$E$9:$E$208,"魅力",'幕间与结算'!$K$9:$K$208,"<0"))))) | EF30: ×
B31: =IF(AND('幕间计算'!A19<>"",COUNTIFS('幕间计算'!$A$210:$A$409,IFERROR(VALUE('幕间与结算'!$B$3),0),'幕间计算'!$B$210:$B$409,1,'幕间与结算'!$E$9:$E$208,'幕间计算'!A19)>0,COUNTIFS('幕间计算'!$A$500:$A$739,IFERROR(VALUE('幕间与结算'!$B$3),0),'幕间计算'!$C$500:$C$739,1,'幕间与结算'!$C$215:$C$454,'幕间计算'!A19)=0),"√","☐") -> ☐ | D31: 乔装 | P31: =MAX(0,MIN(99,IF(V31="",N(S31),N(V31))+N(Y31)+N(AB31))) -> 10 | S31: 10 | V31: =IF(职业选项!V74>0,职业选项!V74,"") | Y31: =规则数据!H37 | AB31: ='幕间计算'!B19+IF(AND('幕间计算'!A19<>"",COUNTIF('幕间计算'!$A$2:A19,'幕间计算'!A19)=1),SUMIF('幕间与结算'!$E$9:$E$208,'幕间计算'!A19,'幕间与结算'!$K$9:$K$208)+SUMIF('幕间与结算'!$C$215:$C$454,'幕间计算'!A19,'幕间与结算'!$G$215:$G$454),0) -> 0 | AE31: =IF(AND('幕间计算'!A49<>"",COUNTIFS('幕间计算'!$A$210:$A$409,IFERROR(VALUE('幕间与结算'!$B$3),0),'幕间计算'!$B$210:$B$409,1,'幕间与结算'!$E$9:$E$208,'幕间计算'!A49)>0,COUNTIFS('幕间计算'!$A$500:$A$739,IFERROR(VALUE('幕间与结算'!$B$3),0),'幕间计算'!$C$500:$C$739,1,'幕间与结算'!$C$215:$C$454,'幕间计算'!A49)=0),"√","☐") -> ☐ | AG31: 科学： | AM31: =IF(COUNTIF(职业选项!$I$2:$I$28,"科学3")>0,IFERROR(INDEX(职业选项!$F$2:$F$28,MATCH("科学3",职业选项!$I$2:$I$28,0)),""),IFERROR(MID(IFERROR(INDEX(规则数据!$C$2:$C$9,SMALL(规则数据!$AW$2:$AW$9,3-COUNTIF(职业选项!$C$2:$C$28,"科学"))),""),LEN("科学")+2,LEN(IFERROR(INDEX(规则数据!$C$2:$C$9,SMALL(规则数据!$AW$2:$AW$9,3-COUNTIF(职业选项!$C$2:$C$28,"科学"))),""))-LEN("科学")-2),"")) | AS31: =MAX(0,MIN(99,IF(AY31="",N(AV31),N(AY31))+N(BB31)+N(BE31))) -> 0 | AV31: 0 | AY31: =IF(职业选项!V75>0,职业选项!V75,"") | BB31: =规则数据!H67 | BE31: ='幕间计算'!B49+IF(AND('幕间计算'!A49<>"",COUNTIF('幕间计算'!$A$2:A49,'幕间计算'!A49)=1),SUMIF('幕间与结算'!$E$9:$E$208,'幕间计算'!A49,'幕间与结算'!$K$9:$K$208)+SUMIF('幕间与结算'!$C$215:$C$454,'幕间计算'!A49,'幕间与结算'!$G$215:$G$454),0) -> 0
B32: =IF(AND('幕间计算'!A20<>"",COUNTIFS('幕间计算'!$A$210:$A$409,IFERROR(VALUE('幕间与结算'!$B$3),0),'幕间计算'!$B$210:$B$409,1,'幕间与结算'!$E$9:$E$208,'幕间计算'!A20)>0,COUNTIFS('幕间计算'!$A$500:$A$739,IFERROR(VALUE('幕间与结算'!$B$3),0),'幕间计算'!$C$500:$C$739,1,'幕间与结算'!$C$215:$C$454,'幕间计算'!A20)=0),"√","☐") -> ☐ | D32: 闪避 | P32: =MAX(0,MIN(99,IF(V32="",N(S32),N(V32))+N(Y32)+N(AB32))) -> 30 | S32: 30 | V32: =IF(职业选项!V76>0,职业选项!V76,"") | Y32: =规则数据!H38 | AB32: ='幕间计算'!B20+IF(AND('幕间计算'!A20<>"",COUNTIF('幕间计算'!$A$2:A20,'幕间计算'!A20)=1),SUMIF('幕间与结算'!$E$9:$E$208,'幕间计算'!A20,'幕间与结算'!$K$9:$K$208)+SUMIF('幕间与结算'!$C$215:$C$454,'幕间计算'!A20,'幕间与结算'!$G$215:$G$454),0) -> 0 | AE32: =IF(AND('幕间计算'!A50<>"",COUNTIFS('幕间计算'!$A$210:$A$409,IFERROR(VALUE('幕间与结算'!$B$3),0),'幕间计算'!$B$210:$B$409,1,'幕间与结算'!$E$9:$E$208,'幕间计算'!A50)>0,COUNTIFS('幕间计算'!$A$500:$A$739,IFERROR(VALUE('幕间与结算'!$B$3),0),'幕间计算'!$C$500:$C$739,1,'幕间与结算'!$C$215:$C$454,'幕间计算'!A50)=0),"√","☐") -> ☐ | AG32: 搜寻 | AS32: =MAX(0,MIN(99,IF(AY32="",N(AV32),N(AY32))+N(BB32)+N(BE32))) -> 20 | AV32: 20 | AY32: =IF(职业选项!V77>0,职业选项!V77,"") | BB32: =规则数据!H68 | BE32: ='幕间计算'!B50+IF(AND('幕间计算'!A50<>"",COUNTIF('幕间计算'!$A$2:A50,'幕间计算'!A50)=1),SUMIF('幕间与结算'!$E$9:$E$208,'幕间计算'!A50,'幕间与结算'!$K$9:$K$208)+SUMIF('幕间与结算'!$C$215:$C$454,'幕间计算'!A50,'幕间与结算'!$G$215:$G$454),0) -> 0 | ED32: 值 | EF32: DG
B33: =IF(AND('幕间计算'!A21<>"",COUNTIFS('幕间计算'!$A$210:$A$409,IFERROR(VALUE('幕间与结算'!$B$3),0),'幕间计算'!$B$210:$B$409,1,'幕间与结算'!$E$9:$E$208,'幕间计算'!A21)>0,COUNTIFS('幕间计算'!$A$500:$A$739,IFERROR(VALUE('幕间与结算'!$B$3),0),'幕间计算'!$C$500:$C$739,1,'幕间与结算'!$C$215:$C$454,'幕间计算'!A21)=0),"√","☐") -> ☐ | D33: 机动车驾驶 | P33: =MAX(0,MIN(99,IF(V33="",N(S33),N(V33))+N(Y33)+N(AB33))) -> 20 | S33: 20 | V33: =IF(职业选项!V78>0,职业选项!V78,"") | Y33: =规则数据!H39 | AB33: ='幕间计算'!B21+IF(AND('幕间计算'!A21<>"",COUNTIF('幕间计算'!$A$2:A21,'幕间计算'!A21)=1),SUMIF('幕间与结算'!$E$9:$E$208,'幕间计算'!A21,'幕间与结算'!$K$9:$K$208)+SUMIF('幕间与结算'!$C$215:$C$454,'幕间计算'!A21,'幕间与结算'!$G$215:$G$454),0) -> 0 | AE33: =IF(AND('幕间计算'!A51<>"",COUNTIFS('幕间计算'!$A$210:$A$409,IFERROR(VALUE('幕间与结算'!$B$3),0),'幕间计算'!$B$210:$B$409,1,'幕间与结算'!$E$9:$E$208,'幕间计算'!A51)>0,COUNTIFS('幕间计算'!$A$500:$A$739,IFERROR(VALUE('幕间与结算'!$B$3),0),'幕间计算'!$C$500:$C$739,1,'幕间与结算'!$C$215:$C$454,'幕间计算'!A51)=0),"√","☐") -> ☐ | AG33: 信号情报 | AS33: =MAX(0,MIN(99,IF(AY33="",N(AV33),N(AY33))+N(BB33)+N(BE33))) -> 0 | AV33: 0 | AY33: =IF(职业选项!V79>0,职业选项!V79,"") | BB33: =规则数据!H69 | BE33: ='幕间计算'!B51+IF(AND('幕间计算'!A51<>"",COUNTIF('幕间计算'!$A$2:A51,'幕间计算'!A51)=1),SUMIF('幕间与结算'!$E$9:$E$208,'幕间计算'!A51,'幕间与结算'!$K$9:$K$208)+SUMIF('幕间与结算'!$C$215:$C$454,'幕间计算'!A51,'幕间与结算'!$G$215:$G$454),0) -> 0 | ED33: =IF(CZ32="","",MAX(0,MIN(EF$22,IF('幕间计算'!Q5>0,IFERROR(INDEX('幕间与结算'!$F$9:$F$208,'幕间计算'!Q5-8),0)+SUMIFS('幕间与结算'!$K$9:$K$208,'幕间与结算'!$E$9:$E$208,"重要关系4",'幕间计算'!$F$210:$F$409,">="&'幕间计算'!Q5)-SUMIFS('幕间计算'!$D$210:$D$409,'幕间与结算'!$L$9:$L$208,"重要关系4",'幕间计算'!$F$210:$F$409,">="&'幕间计算'!Q5)+SUMIFS('幕间与结算'!$K$9:$K$208,'幕间与结算'!$E$9:$E$208,"魅力",'幕间与结算'!$K$9:$K$208,"<0",'幕间计算'!$F$210:$F$409,">="&'幕间计算'!Q5),N('幕间计算'!P5)+SUMIF('幕间与结算'!$E$9:$E$208,"重要关系4",'幕间与结算'!$K$9:$K$208)-SUMIF('幕间与结算'!$L$9:$L$208,"重要关系4",'幕间计算'!$D$210:$D$409)+SUMIFS('幕间与结算'!$K$9:$K$208,'幕间与结算'!$E$9:$E$208,"魅力",'幕间与结算'!$K$9:$K$208,"<0"))))) | EF33: ×
B34: =IF(AND('幕间计算'!A22<>"",COUNTIFS('幕间计算'!$A$210:$A$409,IFERROR(VALUE('幕间与结算'!$B$3),0),'幕间计算'!$B$210:$B$409,1,'幕间与结算'!$E$9:$E$208,'幕间计算'!A22)>0,COUNTIFS('幕间计算'!$A$500:$A$739,IFERROR(VALUE('幕间与结算'!$B$3),0),'幕间计算'!$C$500:$C$739,1,'幕间与结算'!$C$215:$C$454,'幕间计算'!A22)=0),"√","☐") -> ☐ | D34: 射击 | P34: =MAX(0,MIN(99,IF(V34="",N(S34),N(V34))+N(Y34)+N(AB34))) -> 20 | S34: 20 | V34: =IF(职业选项!V80>0,职业选项!V80,"") | Y34: =规则数据!H40 | AB34: ='幕间计算'!B22+IF(AND('幕间计算'!A22<>"",COUNTIF('幕间计算'!$A$2:A22,'幕间计算'!A22)=1),SUMIF('幕间与结算'!$E$9:$E$208,'幕间计算'!A22,'幕间与结算'!$K$9:$K$208)+SUMIF('幕间与结算'!$C$215:$C$454,'幕间计算'!A22,'幕间与结算'!$G$215:$G$454),0) -> 0 | AE34: =IF(AND('幕间计算'!A52<>"",COUNTIFS('幕间计算'!$A$210:$A$409,IFERROR(VALUE('幕间与结算'!$B$3),0),'幕间计算'!$B$210:$B$409,1,'幕间与结算'!$E$9:$E$208,'幕间计算'!A52)>0,COUNTIFS('幕间计算'!$A$500:$A$739,IFERROR(VALUE('幕间与结算'!$B$3),0),'幕间计算'!$C$500:$C$739,1,'幕间与结算'!$C$215:$C$454,'幕间计算'!A52)=0),"√","☐") -> ☐ | AG34: 潜藏 | AS34: =MAX(0,MIN(99,IF(AY34="",N(AV34),N(AY34))+N(BB34)+N(BE34))) -> 10 | AV34: 10 | AY34: =IF(职业选项!V81>0,职业选项!V81,"") | BB34: =规则数据!H70 | BE34: ='幕间计算'!B52+IF(AND('幕间计算'!A52<>"",COUNTIF('幕间计算'!$A$2:A52,'幕间计算'!A52)=1),SUMIF('幕间与结算'!$E$9:$E$208,'幕间计算'!A52,'幕间与结算'!$K$9:$K$208)+SUMIF('幕间与结算'!$C$215:$C$454,'幕间计算'!A52,'幕间与结算'!$G$215:$G$454),0) -> 0
B35: =IF(AND('幕间计算'!A23<>"",COUNTIFS('幕间计算'!$A$210:$A$409,IFERROR(VALUE('幕间与结算'!$B$3),0),'幕间计算'!$B$210:$B$409,1,'幕间与结算'!$E$9:$E$208,'幕间计算'!A23)>0,COUNTIFS('幕间计算'!$A$500:$A$739,IFERROR(VALUE('幕间与结算'!$B$3),0),'幕间计算'!$C$500:$C$739,1,'幕间与结算'!$C$215:$C$454,'幕间计算'!A23)=0),"√","☐") -> ☐ | D35: 急救 | P35: =MAX(0,MIN(99,IF(V35="",N(S35),N(V35))+N(Y35)+N(AB35))) -> 10 | S35: 10 | V35: =IF(职业选项!V82>0,职业选项!V82,"") | Y35: =规则数据!H41 | AB35: ='幕间计算'!B23+IF(AND('幕间计算'!A23<>"",COUNTIF('幕间计算'!$A$2:A23,'幕间计算'!A23)=1),SUMIF('幕间与结算'!$E$9:$E$208,'幕间计算'!A23,'幕间与结算'!$K$9:$K$208)+SUMIF('幕间与结算'!$C$215:$C$454,'幕间计算'!A23,'幕间与结算'!$G$215:$G$454),0) -> 0 | AE35: =IF(AND('幕间计算'!A53<>"",COUNTIFS('幕间计算'!$A$210:$A$409,IFERROR(VALUE('幕间与结算'!$B$3),0),'幕间计算'!$B$210:$B$409,1,'幕间与结算'!$E$9:$E$208,'幕间计算'!A53)>0,COUNTIFS('幕间计算'!$A$500:$A$739,IFERROR(VALUE('幕间与结算'!$B$3),0),'幕间计算'!$C$500:$C$739,1,'幕间与结算'!$C$215:$C$454,'幕间计算'!A53)=0),"√","☐") -> ☐ | AG35: 手术 | AS35: =MAX(0,MIN(99,IF(AY35="",N(AV35),N(AY35))+N(BB35)+N(BE35))) -> 0 | AV35: 0 | AY35: =IF(职业选项!V83>0,职业选项!V83,"") | BB35: =规则数据!H71 | BE35: ='幕间计算'!B53+IF(AND('幕间计算'!A53<>"",COUNTIF('幕间计算'!$A$2:A53,'幕间计算'!A53)=1),SUMIF('幕间与结算'!$E$9:$E$208,'幕间计算'!A53,'幕间与结算'!$K$9:$K$208)+SUMIF('幕间与结算'!$C$215:$C$454,'幕间计算'!A53,'幕间与结算'!$G$215:$G$454),0) -> 0 | ED35: 值 | EF35: DG
B36: =IF(AND('幕间计算'!A24<>"",COUNTIFS('幕间计算'!$A$210:$A$409,IFERROR(VALUE('幕间与结算'!$B$3),0),'幕间计算'!$B$210:$B$409,1,'幕间与结算'!$E$9:$E$208,'幕间计算'!A24)>0,COUNTIFS('幕间计算'!$A$500:$A$739,IFERROR(VALUE('幕间与结算'!$B$3),0),'幕间计算'!$C$500:$C$739,1,'幕间与结算'!$C$215:$C$454,'幕间计算'!A24)=0),"√","☐") -> ☐ | D36: 外语： | J36: =IF(COUNTIF(职业选项!$I$2:$I$28,"外语1")>0,IFERROR(INDEX(职业选项!$F$2:$F$28,MATCH("外语1",职业选项!$I$2:$I$28,0)),""),IFERROR(MID(IFERROR(INDEX(规则数据!$C$2:$C$9,SMALL(规则数据!$AT$2:$AT$9,1-COUNTIF(职业选项!$C$2:$C$28,"外语"))),""),LEN("外语")+2,LEN(IFERROR(INDEX(规则数据!$C$2:$C$9,SMALL(规则数据!$AT$2:$AT$9,1-COUNTIF(职业选项!$C$2:$C$28,"外语"))),""))-LEN("外语")-2),"")) | P36: =MAX(0,MIN(99,IF(V36="",N(S36),N(V36))+N(Y36)+N(AB36))) -> 0 | S36: 0 | V36: =IF(职业选项!V84>0,职业选项!V84,"") | Y36: =规则数据!H42 | AB36: ='幕间计算'!B24+IF(AND('幕间计算'!A24<>"",COUNTIF('幕间计算'!$A$2:A24,'幕间计算'!A24)=1),SUMIF('幕间与结算'!$E$9:$E$208,'幕间计算'!A24,'幕间与结算'!$K$9:$K$208)+SUMIF('幕间与结算'!$C$215:$C$454,'幕间计算'!A24,'幕间与结算'!$G$215:$G$454),0) -> 0 | AE36: =IF(AND('幕间计算'!A54<>"",COUNTIFS('幕间计算'!$A$210:$A$409,IFERROR(VALUE('幕间与结算'!$B$3),0),'幕间计算'!$B$210:$B$409,1,'幕间与结算'!$E$9:$E$208,'幕间计算'!A54)>0,COUNTIFS('幕间计算'!$A$500:$A$739,IFERROR(VALUE('幕间与结算'!$B$3),0),'幕间计算'!$C$500:$C$739,1,'幕间与结算'!$C$215:$C$454,'幕间计算'!A54)=0),"√","☐") -> ☐ | AG36: 生存 | AS36: =MAX(0,MIN(99,IF(AY36="",N(AV36),N(AY36))+N(BB36)+N(BE36))) -> 10 | AV36: 10 | AY36: =IF(职业选项!V85>0,职业选项!V85,"") | BB36: =规则数据!H72 | BE36: ='幕间计算'!B54+IF(AND('幕间计算'!A54<>"",COUNTIF('幕间计算'!$A$2:A54,'幕间计算'!A54)=1),SUMIF('幕间与结算'!$E$9:$E$208,'幕间计算'!A54,'幕间与结算'!$K$9:$K$208)+SUMIF('幕间与结算'!$C$215:$C$454,'幕间计算'!A54,'幕间与结算'!$G$215:$G$454),0) -> 0 | ED36: =IF(CZ35="","",MAX(0,MIN(EF$22,IF('幕间计算'!Q6>0,IFERROR(INDEX('幕间与结算'!$F$9:$F$208,'幕间计算'!Q6-8),0)+SUMIFS('幕间与结算'!$K$9:$K$208,'幕间与结算'!$E$9:$E$208,"重要关系5",'幕间计算'!$F$210:$F$409,">="&'幕间计算'!Q6)-SUMIFS('幕间计算'!$D$210:$D$409,'幕间与结算'!$L$9:$L$208,"重要关系5",'幕间计算'!$F$210:$F$409,">="&'幕间计算'!Q6)+SUMIFS('幕间与结算'!$K$9:$K$208,'幕间与结算'!$E$9:$E$208,"魅力",'幕间与结算'!$K$9:$K$208,"<0",'幕间计算'!$F$210:$F$409,">="&'幕间计算'!Q6),N('幕间计算'!P6)+SUMIF('幕间与结算'!$E$9:$E$208,"重要关系5",'幕间与结算'!$K$9:$K$208)-SUMIF('幕间与结算'!$L$9:$L$208,"重要关系5",'幕间计算'!$D$210:$D$409)+SUMIFS('幕间与结算'!$K$9:$K$208,'幕间与结算'!$E$9:$E$208,"魅力",'幕间与结算'!$K$9:$K$208,"<0"))))) | EF36: ×
B37: =IF(AND('幕间计算'!A25<>"",COUNTIFS('幕间计算'!$A$210:$A$409,IFERROR(VALUE('幕间与结算'!$B$3),0),'幕间计算'!$B$210:$B$409,1,'幕间与结算'!$E$9:$E$208,'幕间计算'!A25)>0,COUNTIFS('幕间计算'!$A$500:$A$739,IFERROR(VALUE('幕间与结算'!$B$3),0),'幕间计算'!$C$500:$C$739,1,'幕间与结算'!$C$215:$C$454,'幕间计算'!A25)=0),"√","☐") -> ☐ | D37: 外语： | J37: =IF(COUNTIF(职业选项!$I$2:$I$28,"外语2")>0,IFERROR(INDEX(职业选项!$F$2:$F$28,MATCH("外语2",职业选项!$I$2:$I$28,0)),""),IFERROR(MID(IFERROR(INDEX(规则数据!$C$2:$C$9,SMALL(规则数据!$AT$2:$AT$9,2-COUNTIF(职业选项!$C$2:$C$28,"外语"))),""),LEN("外语")+2,LEN(IFERROR(INDEX(规则数据!$C$2:$C$9,SMALL(规则数据!$AT$2:$AT$9,2-COUNTIF(职业选项!$C$2:$C$28,"外语"))),""))-LEN("外语")-2),"")) | P37: =MAX(0,MIN(99,IF(V37="",N(S37),N(V37))+N(Y37)+N(AB37))) -> 0 | S37: 0 | V37: =IF(职业选项!V86>0,职业选项!V86,"") | Y37: =规则数据!H43 | AB37: ='幕间计算'!B25+IF(AND('幕间计算'!A25<>"",COUNTIF('幕间计算'!$A$2:A25,'幕间计算'!A25)=1),SUMIF('幕间与结算'!$E$9:$E$208,'幕间计算'!A25,'幕间与结算'!$K$9:$K$208)+SUMIF('幕间与结算'!$C$215:$C$454,'幕间计算'!A25,'幕间与结算'!$G$215:$G$454),0) -> 0 | AE37: =IF(AND('幕间计算'!A55<>"",COUNTIFS('幕间计算'!$A$210:$A$409,IFERROR(VALUE('幕间与结算'!$B$3),0),'幕间计算'!$B$210:$B$409,1,'幕间与结算'!$E$9:$E$208,'幕间计算'!A55)>0,COUNTIFS('幕间计算'!$A$500:$A$739,IFERROR(VALUE('幕间与结算'!$B$3),0),'幕间计算'!$C$500:$C$739,1,'幕间与结算'!$C$215:$C$454,'幕间计算'!A55)=0),"√","☐") -> ☐ | AG37: 游泳 | AS37: =MAX(0,MIN(99,IF(AY37="",N(AV37),N(AY37))+N(BB37)+N(BE37))) -> 20 | AV37: 20 | AY37: =IF(职业选项!V87>0,职业选项!V87,"") | BB37: =规则数据!H73 | BE37: ='幕间计算'!B55+IF(AND('幕间计算'!A55<>"",COUNTIF('幕间计算'!$A$2:A55,'幕间计算'!A55)=1),SUMIF('幕间与结算'!$E$9:$E$208,'幕间计算'!A55,'幕间与结算'!$K$9:$K$208)+SUMIF('幕间与结算'!$C$215:$C$454,'幕间计算'!A55,'幕间与结算'!$G$215:$G$454),0) -> 0
B38: =IF(AND('幕间计算'!A26<>"",COUNTIFS('幕间计算'!$A$210:$A$409,IFERROR(VALUE('幕间与结算'!$B$3),0),'幕间计算'!$B$210:$B$409,1,'幕间与结算'!$E$9:$E$208,'幕间计算'!A26)>0,COUNTIFS('幕间计算'!$A$500:$A$739,IFERROR(VALUE('幕间与结算'!$B$3),0),'幕间计算'!$C$500:$C$739,1,'幕间与结算'!$C$215:$C$454,'幕间计算'!A26)=0),"√","☐") -> ☐ | D38: 外语： | J38: =IF(COUNTIF(职业选项!$I$2:$I$28,"外语3")>0,IFERROR(INDEX(职业选项!$F$2:$F$28,MATCH("外语3",职业选项!$I$2:$I$28,0)),""),IFERROR(MID(IFERROR(INDEX(规则数据!$C$2:$C$9,SMALL(规则数据!$AT$2:$AT$9,3-COUNTIF(职业选项!$C$2:$C$28,"外语"))),""),LEN("外语")+2,LEN(IFERROR(INDEX(规则数据!$C$2:$C$9,SMALL(规则数据!$AT$2:$AT$9,3-COUNTIF(职业选项!$C$2:$C$28,"外语"))),""))-LEN("外语")-2),"")) | P38: =MAX(0,MIN(99,IF(V38="",N(S38),N(V38))+N(Y38)+N(AB38))) -> 0 | S38: 0 | V38: =IF(职业选项!V88>0,职业选项!V88,"") | Y38: =规则数据!H44 | AB38: ='幕间计算'!B26+IF(AND('幕间计算'!A26<>"",COUNTIF('幕间计算'!$A$2:A26,'幕间计算'!A26)=1),SUMIF('幕间与结算'!$E$9:$E$208,'幕间计算'!A26,'幕间与结算'!$K$9:$K$208)+SUMIF('幕间与结算'!$C$215:$C$454,'幕间计算'!A26,'幕间与结算'!$G$215:$G$454),0) -> 0 | AE38: =IF(AND('幕间计算'!A56<>"",COUNTIFS('幕间计算'!$A$210:$A$409,IFERROR(VALUE('幕间与结算'!$B$3),0),'幕间计算'!$B$210:$B$409,1,'幕间与结算'!$E$9:$E$208,'幕间计算'!A56)>0,COUNTIFS('幕间计算'!$A$500:$A$739,IFERROR(VALUE('幕间与结算'!$B$3),0),'幕间计算'!$C$500:$C$739,1,'幕间与结算'!$C$215:$C$454,'幕间计算'!A56)=0),"√","☐") -> ☐ | AG38: 徒手搏斗 | AS38: =MAX(0,MIN(99,IF(AY38="",N(AV38),N(AY38))+N(BB38)+N(BE38))) -> 40 | AV38: 40 | AY38: =IF(职业选项!V89>0,职业选项!V89,"") | BB38: =规则数据!H74 | BE38: ='幕间计算'!B56+IF(AND('幕间计算'!A56<>"",COUNTIF('幕间计算'!$A$2:A56,'幕间计算'!A56)=1),SUMIF('幕间与结算'!$E$9:$E$208,'幕间计算'!A56,'幕间与结算'!$K$9:$K$208)+SUMIF('幕间与结算'!$C$215:$C$454,'幕间计算'!A56,'幕间与结算'!$G$215:$G$454),0) -> 0 | ED38: 值 | EF38: DG
B39: =IF(AND('幕间计算'!A27<>"",COUNTIFS('幕间计算'!$A$210:$A$409,IFERROR(VALUE('幕间与结算'!$B$3),0),'幕间计算'!$B$210:$B$409,1,'幕间与结算'!$E$9:$E$208,'幕间计算'!A27)>0,COUNTIFS('幕间计算'!$A$500:$A$739,IFERROR(VALUE('幕间与结算'!$B$3),0),'幕间计算'!$C$500:$C$739,1,'幕间与结算'!$C$215:$C$454,'幕间计算'!A27)=0),"√","☐") -> ☐ | D39: 法证学 | P39: =MAX(0,MIN(99,IF(V39="",N(S39),N(V39))+N(Y39)+N(AB39))) -> 0 | S39: 0 | V39: =IF(职业选项!V90>0,职业选项!V90,"") | Y39: =规则数据!H45 | AB39: ='幕间计算'!B27+IF(AND('幕间计算'!A27<>"",COUNTIF('幕间计算'!$A$2:A27,'幕间计算'!A27)=1),SUMIF('幕间与结算'!$E$9:$E$208,'幕间计算'!A27,'幕间与结算'!$K$9:$K$208)+SUMIF('幕间与结算'!$C$215:$C$454,'幕间计算'!A27,'幕间与结算'!$G$215:$G$454),0) -> 0 | AE39: =IF(AND('幕间计算'!A57<>"",COUNTIFS('幕间计算'!$A$210:$A$409,IFERROR(VALUE('幕间与结算'!$B$3),0),'幕间计算'!$B$210:$B$409,1,'幕间与结算'!$E$9:$E$208,'幕间计算'!A57)>0,COUNTIFS('幕间计算'!$A$500:$A$739,IFERROR(VALUE('幕间与结算'!$B$3),0),'幕间计算'!$C$500:$C$739,1,'幕间与结算'!$C$215:$C$454,'幕间计算'!A57)=0),"√","☐") -> ☐ | AG39: 非自然知识 | AS39: =MAX(0,MIN(99,N(BB39)+N(BE39))) -> 0 | AV39: 0 | AY39: — | BB39: =IF(DF46="人类不应知道之事",10,0) -> 0 | BE39: ='幕间计算'!B57+IF(AND('幕间计算'!A57<>"",COUNTIF('幕间计算'!$A$2:A57,'幕间计算'!A57)=1),SUMIF('幕间与结算'!$E$9:$E$208,'幕间计算'!A57,'幕间与结算'!$K$9:$K$208)+SUMIF('幕间与结算'!$C$215:$C$454,'幕间计算'!A57,'幕间与结算'!$G$215:$G$454),0) -> 0 | ED39: =IF(CZ38="","",MAX(0,MIN(EF$22,IF('幕间计算'!Q7>0,IFERROR(INDEX('幕间与结算'!$F$9:$F$208,'幕间计算'!Q7-8),0)+SUMIFS('幕间与结算'!$K$9:$K$208,'幕间与结算'!$E$9:$E$208,"重要关系6",'幕间计算'!$F$210:$F$409,">="&'幕间计算'!Q7)-SUMIFS('幕间计算'!$D$210:$D$409,'幕间与结算'!$L$9:$L$208,"重要关系6",'幕间计算'!$F$210:$F$409,">="&'幕间计算'!Q7)+SUMIFS('幕间与结算'!$K$9:$K$208,'幕间与结算'!$E$9:$E$208,"魅力",'幕间与结算'!$K$9:$K$208,"<0",'幕间计算'!$F$210:$F$409,">="&'幕间计算'!Q7),N('幕间计算'!P7)+SUMIF('幕间与结算'!$E$9:$E$208,"重要关系6",'幕间与结算'!$K$9:$K$208)-SUMIF('幕间与结算'!$L$9:$L$208,"重要关系6",'幕间计算'!$D$210:$D$409)+SUMIFS('幕间与结算'!$K$9:$K$208,'幕间与结算'!$E$9:$E$208,"魅力",'幕间与结算'!$K$9:$K$208,"<0"))))) | EF39: ×
B40: =IF(AND('幕间计算'!A28<>"",COUNTIFS('幕间计算'!$A$210:$A$409,IFERROR(VALUE('幕间与结算'!$B$3),0),'幕间计算'!$B$210:$B$409,1,'幕间与结算'!$E$9:$E$208,'幕间计算'!A28)>0,COUNTIFS('幕间计算'!$A$500:$A$739,IFERROR(VALUE('幕间与结算'!$B$3),0),'幕间计算'!$C$500:$C$739,1,'幕间与结算'!$C$215:$C$454,'幕间计算'!A28)=0),"√","☐") -> ☐ | D40: 重型机械 | P40: =MAX(0,MIN(99,IF(V40="",N(S40),N(V40))+N(Y40)+N(AB40))) -> 10 | S40: 10 | V40: =IF(职业选项!V91>0,职业选项!V91,"") | Y40: =规则数据!H46 | AB40: ='幕间计算'!B28+IF(AND('幕间计算'!A28<>"",COUNTIF('幕间计算'!$A$2:A28,'幕间计算'!A28)=1),SUMIF('幕间与结算'!$E$9:$E$208,'幕间计算'!A28,'幕间与结算'!$K$9:$K$208)+SUMIF('幕间与结算'!$C$215:$C$454,'幕间计算'!A28,'幕间与结算'!$G$215:$G$454),0) -> 0 | AE40: =IF(AND('幕间计算'!A58<>"",COUNTIFS('幕间计算'!$A$210:$A$409,IFERROR(VALUE('幕间与结算'!$B$3),0),'幕间计算'!$B$210:$B$409,1,'幕间与结算'!$E$9:$E$208,'幕间计算'!A58)>0,COUNTIFS('幕间计算'!$A$500:$A$739,IFERROR(VALUE('幕间与结算'!$B$3),0),'幕间计算'!$C$500:$C$739,1,'幕间与结算'!$C$215:$C$454,'幕间计算'!A58)=0),"√","☐") -> ☐ | AG40: =IFERROR(INDEX(规则数据!$C$2:$C$9,SMALL(规则数据!$AX$2:$AX$9,1)),"") | AS40: =MAX(0,MIN(99,IF(AY40="",N(AV40),N(AY40))+N(BB40)+N(BE40))) -> 0 | BB40: =规则数据!H75 | BE40: ='幕间计算'!B58+IF(AND('幕间计算'!A58<>"",COUNTIF('幕间计算'!$A$2:A58,'幕间计算'!A58)=1),SUMIF('幕间与结算'!$E$9:$E$208,'幕间计算'!A58,'幕间与结算'!$K$9:$K$208)+SUMIF('幕间与结算'!$C$215:$C$454,'幕间计算'!A58,'幕间与结算'!$G$215:$G$454),0) -> 0
B41: =IF(AND('幕间计算'!A29<>"",COUNTIFS('幕间计算'!$A$210:$A$409,IFERROR(VALUE('幕间与结算'!$B$3),0),'幕间计算'!$B$210:$B$409,1,'幕间与结算'!$E$9:$E$208,'幕间计算'!A29)>0,COUNTIFS('幕间计算'!$A$500:$A$739,IFERROR(VALUE('幕间与结算'!$B$3),0),'幕间计算'!$C$500:$C$739,1,'幕间与结算'!$C$215:$C$454,'幕间计算'!A29)=0),"√","☐") -> ☐ | D41: 重型武器 | P41: =MAX(0,MIN(99,IF(V41="",N(S41),N(V41))+N(Y41)+N(AB41))) -> 0 | S41: 0 | V41: =IF(职业选项!V92>0,职业选项!V92,"") | Y41: =规则数据!H47 | AB41: ='幕间计算'!B29+IF(AND('幕间计算'!A29<>"",COUNTIF('幕间计算'!$A$2:A29,'幕间计算'!A29)=1),SUMIF('幕间与结算'!$E$9:$E$208,'幕间计算'!A29,'幕间与结算'!$K$9:$K$208)+SUMIF('幕间与结算'!$C$215:$C$454,'幕间计算'!A29,'幕间与结算'!$G$215:$G$454),0) -> 0 | AE41: =IF(AND('幕间计算'!A59<>"",COUNTIFS('幕间计算'!$A$210:$A$409,IFERROR(VALUE('幕间与结算'!$B$3),0),'幕间计算'!$B$210:$B$409,1,'幕间与结算'!$E$9:$E$208,'幕间计算'!A59)>0,COUNTIFS('幕间计算'!$A$500:$A$739,IFERROR(VALUE('幕间与结算'!$B$3),0),'幕间计算'!$C$500:$C$739,1,'幕间与结算'!$C$215:$C$454,'幕间计算'!A59)=0),"√","☐") -> ☐ | AG41: =IFERROR(INDEX(规则数据!$C$2:$C$9,SMALL(规则数据!$AX$2:$AX$9,2)),"") | AS41: =MAX(0,MIN(99,IF(AY41="",N(AV41),N(AY41))+N(BB41)+N(BE41))) -> 0 | BB41: =规则数据!H76 | BE41: ='幕间计算'!B59+IF(AND('幕间计算'!A59<>"",COUNTIF('幕间计算'!$A$2:A59,'幕间计算'!A59)=1),SUMIF('幕间与结算'!$E$9:$E$208,'幕间计算'!A59,'幕间与结算'!$K$9:$K$208)+SUMIF('幕间与结算'!$C$215:$C$454,'幕间计算'!A59,'幕间与结算'!$G$215:$G$454),0) -> 0 | ED41: 值 | EF41: DG
...

Sheet 骰子指令
A1: 骰子属性设置指令
A2: 复制方法：（需要Excel 2019或更新版本） 1. 选择右方单元格，复制。 2. 粘贴到任意单元格，在一旁的下拉菜单选择“复制值”。 3. 复制该值。 | B2: =".st "&_xlfn.CONCAT(附表!E93:E162) -> .st 会计学10警觉20运动30行政10犯罪学10乔装10闪避30机动车驾驶20射击20急救10重型机械10历史10人源情报10近战武器30导航10神秘学10说服20精神治疗10骑术10搜寻20潜藏10生存10游泳20徒手搏斗40
A3: 生成6个属性的骰子指令
A4: .r6#4d6k3

Sheet 职业列表
A1: 职业名 | B1: 推荐属性 | C1: 重要关系数 | D1: 固定职业技能 | T1: 自由职业技能数 | U1: 自由职业技能选项 | AF1: 子模板 | AJ1: 建议额外技能 | AN1: 装备
A2: （创建新职业） | C2: ≤4 | D2: {=TRANSPOSE(附表!A37:A41)} -> 任选10个本职技能，分配350 | E2: 技能点，额外加在基础值上， | F2: 最高至60%。重要关系自4个开 | G2: 始每少一个（最少1个），增 | H2: 加50本职技能点。 | AO2: =ROW() -> 2
A3: （主持人自定义职业模板栏位） | AO3: =IF(LEFT(TRIM(A3&"$"),1)="（",65536,ROW()) -> 65536
A4: （这几栏可以自由编辑） | AO4: =IF(LEFT(TRIM(A4&"$"),1)="（",65536,ROW()) -> 65536
A5: （一般用于主持人提供的职业模板） | AO5: =IF(LEFT(TRIM(A5&"$"),1)="（",65536,ROW()) -> 65536
A6: （玩家自定义模板不建议放这里） | AO6: =IF(LEFT(TRIM(A6&"$"),1)="（",65536,ROW()) -> 65536
A7: （直接填写技能即可，毕竟模板只是参考） | AO7: =IF(LEFT(TRIM(A7&"$"),1)="（",65536,ROW()) -> 65536
A8: 人类学家或历史学家 | B8: 智力 | C8: 4 | D8: 人类学50%或考古学50% | E8: 行政40% | F8: 外语（任选）50% | G8: 外语（任选）40% | H8: 历史60% | I8: 神秘学40% | J8: 说服40% | T8: 2 | U8: 人类学40% | V8: 考古学40% | W8: 人源情报50% | X8: 导航50% | Y8: 骑术50% | Z8: 搜寻60% | AA8: 生存50% | AO8: =ROW() -> 8
A9: 计算机科学家或工程师 | B9: 智力 | C9: 3 | D9: 计算机科学60% | E9: 工艺（电工）30% | F9: 工艺（机械）30% | G9: 工艺（微电子）40% | H9: 科学（数学）40% | I9: 信号情报40% | T9: 4 | U9: 会计学50% | V9: 行政50% | W9: 工艺（任选）40% | X9: 外语（任选）40% | Y9: 重型机械50% | Z9: 法律40% | AA9: 科学（任选）40% | AO9: =ROW() -> 9
A10: 联邦探员 | B10: 体质，意志，魅力 | C10: 3 | D10: 警觉50% | E10: 行政40% | F10: 犯罪学50% | G10: 机动车驾驶50% | H10: 射击50% | I10: 法证学30% | J10: 人源情报60% | K10: 法律30% | L10: 说服50% | M10: 搜寻50% | N10: 徒手搏斗60% | T10: 1 | U10: 会计学60% | V10: 计算机科学50% | W10: 外语（任选）50% | X10: 重型武器50% | Y10: 药学50% | AO10: =ROW() -> 10
A11: 医生 | B11: 智力，意志，敏捷 | C11: 3 | D11: 行政50% | E11: 急救60% | F11: 医学60% | G11: 说服40% | H11: 药学50% | I11: 科学（生物学）60% | J11: 搜寻40% | T11: 2 | U11: 法证学50% | V11: 精神治疗60% | W11: 科学（任选）50% | X11: 手术50% | AO11: =ROW() -> 11
A12: 科学家 | B12: 智力 | C12: 4 | D12: 行政40% | E12: 计算机科学40% | F12: 科学（任选）60% | G12: 科学（任选）50% | H12: 科学（任选）50% | T12: 3 | U12: 会计学50% | V12: 工艺（任选）40% | W12: 外语（任选）40% | X12: 法证学40% | Y12: 法律40% | Z12: 药学40% | AO12: =ROW() -> 12
A13: 特种作战员 | B13: 力量，体质，意志 | C13: 2 | D13: 警觉60% | E13: 运动60% | F13: 爆破40% | G13: 射击60% | H13: 重型武器50% | I13: 近战武器50% | J13: 军事科学（陆军）60% | K13: 导航50% | L13: 潜藏50% | M13: 生存50% | N13: 游泳50% | O13: 徒手搏斗60% | AO13: =ROW() -> 13
A14: 【额外】罪犯 | B14: 力量，敏捷 | C14: 4 | D14: 警觉50% | E14: 运动50% | F14: 犯罪学60% | G14: 闪避40% | H14: 机动车驾驶50% | I14: 射击40% | J14: 法律20% | K14: 近战武器40% | L14: 说服50% | M14: 潜藏50% | N14: 徒手搏斗50% | T14: 2 | U14: 工艺（锁匠）40% | V14: 爆破40% | W14: 乔装50% | X14: 外语（任选）40% | Y14: 法证学40% | Z14: 人源情报50% | AA14: 导航50% | AB14: 神秘学50% | AC14: 药学40% | AO14: =ROW() -> 14
A15: 【额外】消防队员 | B15: 力量，敏捷，体质 | C15: 3 | D15: 警觉50% | E15: 运动60% | F15: 工艺（电工）40% | G15: 工艺（机械）40% | H15: 爆破50% | I15: 机动车驾驶50% | J15: 急救50% | K15: 法证学40% | L15: 重型机械50% | M15: 导航50% | N15: 搜寻40% | AO15: =ROW() -> 15
A16: 【额外】外事官员 | B16: 智力，魅力 | C16: 3 | D16: 会计学40% | E16: 人类学40% | F16: 行政60% | G16: 外语（任选）50% | H16: 外语（任选）50% | I16: 外语（任选）40% | J16: 历史40% | K16: 人源情报50% | L16: 法律40% | M16: 说服50% | AO16: =ROW() -> 16
A17: 【额外】情报分析员 | B17: 智力 | C17: 3 | D17: 人类学40% | E17: 行政50% | F17: 计算机科学40% | G17: 犯罪学40% | H17: 外语（任选）50% | I17: 外语（任选）50% | J17: 外语（任选）40% | K17: 历史40% | L17: 人源情报50% | M17: 信号情报40% | AO17: =ROW() -> 17
A18: 【额外】情报官员 | B18: 智力，意志，魅力 | C18: 2 | D18: 警觉50% | E18: 行政40% | F18: 犯罪学50% | G18: 乔装50% | H18: 机动车驾驶40% | I18: 射击40% | J18: 外语（任选）50% | K18: 外语（任选）40% | L18: 人源情报60% | M18: 说服60% | N18: 信号情报40% | O18: 潜藏50% | P18: 徒手搏斗50% | AO18: =ROW() -> 18
